Workbook
Name Ambar: 'Справочник подстановки'!$S$3:$S$4
Name Autonomy: 'Справочник подстановки'!$A$3:$A$4
Name ColumnCount: 'Справочник подстановки'!$C$3:$C$8
Name CountPilotBore: 'Справочник подстановки'!$E$3:$E$7
Name DrillRig: 'Справочник подстановки'!$N$3:$N$4
Name Grp: 'Справочник подстановки'!$H$3:$H$4
Name GrpCount: 'Справочник подстановки'!$I$3:$I$17
Name GrpType: 'Справочник подстановки'!$J$3:$J$4
Name MnogoZab: 'Справочник подстановки'!$F$3
Name MudPumpType: 'Справочник подстановки'!$O$3:$O$4
Name MudType: 'Справочник подстановки'!$P$3:$P$8
Name Nnb: 'Справочник подстановки'!$Q$3:$Q$11
Name Npv: 'Справочник подстановки'!$L$3:$L$6
Name Perforation: 'Справочник подстановки'!$R$3:$R$11
Name PilotBore: 'Справочник подстановки'!$D$3:$D$5
Name ProductBoresCount: 'Справочник подстановки'!$G$3:$G$8
Name WellFunc: 'Справочник подстановки'!$K$3:$K$7
Name WellType: 'Справочник подстановки'!$B$3:$B$12
Name Виновник: 'Справочник подстановки'!$M$3:$M$4

Sheet Уделки ЗБС 9 типов
A1: ="Отчет по стоимости скважин с учетом НЗС прошлых лет на отчетную дату по ЭБ и ЗБС по "&'Текущий год'!A2 -> Отчет по стоимости скважин с учетом НЗС прошлых лет на отчетную дату по ЭБ и ЗБС по
A4: № п/п | B4: Месторождение | C4: № куста | D4: № скважины | E4: Автономия | G4: Тип скважины | H4: Назначение скважины | I4: Кол-во обсадных колонн | J4: Наличие пилотного/ ликвидированного по геологическим причинам ствола | K4: Кол-во пилотных стволов (ликвидированных по геологич.причинам) | L4: МСС (многоствольная/ многозабойная скважина) | M4: Кол-во стволов | N4: ГРП/ МГРП | O4: Количество стадий ГРП/ МГРП | P4: Тип ГРП | Q4: Проходка выполненный объем | R4: Проходка по законченным бурением скважинам (Заполняется после окончания бурения) | X4: Длина ликвидированного ствола по ТЕХНИЧЕСКИМ причинам (не включается в основную проходку) | Y4: Глубина скважины до фактического забоя | AA4: ЗБС (включая углубления) | AC4: Отход от вертикали | AD4: Измеренная по стволу глубина спуска обсадных колонн | AK4: Диаметр обсадных колонн | AQ4: Отбор керна | AR4: Сроки строительства | AT4: Сроки бурения | AX4: Календарное время бурения по скважине (Выполнение прошлый год + текущий), сут ПОСЛЕ ОКОНЧАНИЯ БУРЕНИЯ КАЛЕНДАРНОЕ ВРЕМЯ ДОЛЖНО РАВНЯТЬСЯ ВРЕМЕНИ ПО ЗАКОНЧЕННЫМ БУРЕНИЕМ | BA4: Календарное время бурения по скв.зак.бурением, сут (заполняется только по скв.зак.бур. За весь период бурения скважины) | BD4: Сроки освоения | BF4: Продолжительность освоения, сут (заполняется после окончания освоения) | BL4: Дата сдачи скважины в эксплуатацию,или на ВНР | BM4: Продолжительность ВНР | BN4: Амбарное / Без амбарное бурение | BO4: Характеристика бурового станка | BX4: Характеристика бурового раствора | CE4: Характеристика ННБ | CK4: ВМР на скважине (виды ВМР на скважине в шт. и м/км должны соответствовать суммам по ВМР, включенным в стоимость строительства данной скважины) | CR4: Продолжительность ВМР | CX4: Перечень работ по вывозу и интенсификацции притока | DB4: Пусковой дебит | DC4: Полная стоимость строительства скважины (без НДС) тыс. руб. (не включается строительство и обустройство кустовой площадки, ФА, НКТ, ГНО) | YF4: Комментарии
E5: По электроэнергии (отсутствие ВЛ) | F5: По доступности (отсутствие дорог) | G5: ННС ГС ННС Юра ГС Юра ННС Палеозой ГС Палеозой ННС Бажен ГС Бажен БННС БГС | H5: Добывающая Нагнетательная Водозаборная Газовая | I5: 2-6 | J5: пилот/ перебур/ пилот + перебур | K5: 1-5 | L5: МСС | M5: 1-5 | N5: Проведение ГРП/ МГРП | O5: 1-15 | P5: Проппантный/ Кислотный | Q5: Всего | R5: Всего | S5: В том числе: Длина пилотного ствола или сумма стволов | T5: Длина ликвидированного ствола по геологическим причинам (перебур) | U5: Длина горизонтального участка 1 | V5: Длина горизонтального участка 2 | W5: Длина горизонтального участка 3 | Y5: по вертикали | Z5: по стволу | AA5: Длина бокового ствола | AB5: Измеренная по стволу глубина зарезки "окна" / башмака | AT5: Дата начала бурения | AV5: Дата окончания бурения | AX5: Всего, в том числе: | AY5: Производительное время | AZ5: Непроизводительное время | BA5: Всего, в том числе: | BB5: Производительное время | BC5: Непроизводительное время | BD5: Дата начала освоения | BE5: Дата окончания освоения | BF5: Время работы бригады КРС | BI5: ГРП | BJ5: ГНКТ | BK5: Прочие | CE5: Подрядчик по ННБ | CF5: Кондуктор | CG5: Технич. колонна 1 | CH5: Технич. колонна 2 | CI5: Экспл. колонна | CJ5: Хвостовик | CK5: Мобилизация / демобилизация БУ, указывается расстояние | CL5: Переезд (перевозка) БУ между кустами (местами дислокации), указывается расстояние | CM5: Передвижка БУ, указывается длина передвижки | CN5: Монтаж БУ | CO5: Стаскивание БУ | CP5: Демонтаж БУ | CQ5: Наличие Водных преград | CX5: Перфорация | CZ5: ГРП | DB5: Всего | DC5: ИТОГО руб. | DD5: При ЗБС | DF5: ВМР (виды ВМР на скважине в шт. и м/км должны соответствовать суммам по ВМР, включенным в стоимость строительства данной скважины) | DN5: Бурение | QW5: Освоение | XK5: Оборудование | XQ5: Подготовка площвдки
AD6: Направление | AE6: Кондуктор | AF6: Технич. колонна 1 | AG6: Технич. колонна 2 | AH6: Экспл. колонна | AI6: Хвостовик | AK6: Направление | AL6: Кондуктор | AM6: Технич. колонна 1 | AN6: Технич. колонна 2 | AO6: Экспл. колонна | AP6: Хвостовик | AR6: Начала стр-ва | AS6: Ввода скважины в эксплуатацию по фонду | BO6: Наименование БУ | BP6: Наличие СВП | BQ6: Номинальная грузоподъемность БУ | BR6: Буровые Насосы | BT6: Система очистки | BX6: Подрядчик по растворам | BY6: Система раствора | DD6: Подрядчик по подгот. работам | DE6: Подготовка скважины к реконструкции бригадой КРС | DF6: Подрядчик по ВМР | DG6: Всего, в т.ч. | DH6: Мобилизация / Демобилизация | DI6: Переезд (перевозка) БУ между кустами (местами дислокации) | DJ6: Передвижка | DK6: Монтаж | DL6: Демонтаж | DM6: Прочие работы | DN6: Всего, в т.ч. | DO6: Бурение (полные затраты на бурового подрядчика за исключением ВМР, перевозки и переработки бурового шлама) | EO6: в том числе: Услуги АвИЭС | EP6: Услуги АвИЭС (при условии, что услуги оказывает отдельный подрядчик) | FK6: Вырезка окна | GF6: Услуги направленного бурения и телеметрии (включая ГЗД) | HA6: Услуги ГИС при бурении | HV6: Услуги ГТИ | IQ6: Цементирование | JL6: Сопровождение буровых растворов | KG6: Долотное сопровождение | LB6: Керноотбор | LW6: Оборудование МГРП/ подвеска хвостовика | MR6: Затраты на перевозку, хранение, утилизацию (переработку) шлама и бурового раствора, а так же на рекультивацию | NM6: Супервайзинг при бурении | OH6: МТО (материалы, предоставляемые подрядчику на давальческой основе при бурении) | PC6: Авиа перевозки за счет Заказчика | PD6: Водные перевозки за счет Заказчика | PE6: Консультационные услуги, в том числе услуги НТЦ | PZ6: Экологические платежи в бюджет | QA6: Разработка проектной документации | QV6: Прочие затраты при бурении | QW6: Всего, в т.ч. | QX6: Стоимость услуг бригад освоения, ТКРС | RS6: Освоение скважин струйными насосами | SN6: Услуги по глушению, приготовлению раствора глушения (в т.ч. раствор), промывке, ОПЗ | TI6: Стоимость ГИС при освоении, включая перфорацию | UD6: Затраты на проведение ГРП | UY6: Затраты на ГНКТ | VT6: МТО (материалы, предоставляемые подрядчику на давальческой основе при освоении) кроме проппанта | WO6: Супервайзинг при освоении (этап освоение + ГРП + ГНКТ) | XJ6: Прочие затраты в освоении | XK6: ОНВСС | XQ6: Подготовка площадки
AI7: Глубина "Голова" подвески (по стволу) м | AJ7: Глубина спуска (по стволу) м | AT7: Число | AU7: Время | AV7: Число | AW7: Время | BF7: Всего | BG7: ПВ | BH7: НПВ | BR7: Количество | BS7: Тип | BT7: Марка вибросит | BU7: Количество | BV7: Марка центрифуг | BW7: Количество | BY7: Направление | BZ7: Кондуктор | CA7: Технич. колонна 1 | CB7: Технич. колонна 2 | CC7: Экспл. колонна | CD7: Хвостовик | CR7: Мобилизация / Демобилизация | CS7: Переезд (перевозка) БУ между кустами | CT7: Передвижка БУ | CU7: Монтаж | CV7: Стаскивание | CW7: Демонтаж | CX7: Сумма длин участков перфорации | CY7: Тип перфорации | CZ7: Объем проппанта | DA7: Объем проппанта на 1 стадию | DO7: Подрядчик по ЭБ и ЗБС 1 | DP7: Подрядчик по ЭБ и ЗБС 2 | DQ7: Подрядчик по ЭБ и ЗБС 3 | DR7: Подрядчик по ЭБ и ЗБС 4 | DS7: Подрядчик по ЭБ и ЗБС 5 | DT7: Подрядчик по ЭБ и ЗБС 6 | DU7: Подрядчик по ЭБ и ЗБС 7 | DV7: Подрядчик по ЭБ и ЗБС 8 | DW7: Подрядчик по ЭБ и ЗБС 9 | DX7: Подрядчик по ЭБ и ЗБС 10 | DY7: Подрядчик по ЭБ и ЗБС 11 | DZ7: Подрядчик по ЭБ и ЗБС 12 | EA7: Подрядчик по ЭБ и ЗБС 13 | EB7: Подрядчик по ЭБ и ЗБС 14 | EC7: Подрядчик по ЭБ и ЗБС 15 | ED7: Подрядчик по ЭБ и ЗБС 16 | EE7: Подрядчик по ЭБ и ЗБС 17 | EF7: Подрядчик по ЭБ и ЗБС 18 | EG7: Подрядчик по ЭБ и ЗБС 19 | EH7: Подрядчик по ЭБ и ЗБС 20 | EI7: Подрядчик по ЭБ и ЗБС 21 | EJ7: Подрядчик по ЭБ и ЗБС 22 | EK7: Подрядчик по ЭБ и ЗБС 23 | EL7: Подрядчик по ЭБ и ЗБС 24 | EM7: Подрядчик по ЭБ и ЗБС 25 | EN7: Всего | EO7: Всего | EP7: Подрядчик по АвИЭС 1 | EQ7: Подрядчик по АвИЭС 2 | ER7: Подрядчик по АвИЭС 3 | ES7: Подрядчик по АвИЭС 4 | ET7: Подрядчик по АвИЭС 5 | EU7: Подрядчик по АвИЭС 6 | EV7: Подрядчик по АвИЭС 7 | EW7: Подрядчик по АвИЭС 8 | EX7: Подрядчик по АвИЭС 9 | EY7: Подрядчик по АвИЭС 10 | EZ7: Подрядчик по АвИЭС 11 | FA7: Подрядчик по АвИЭС 12 | FB7: Подрядчик по АвИЭС 13 | FC7: Подрядчик по АвИЭС 14 | FD7: Подрядчик по АвИЭС 15 | FE7: Подрядчик по АвИЭС 16 | FF7: Подрядчик по АвИЭС 17 | FG7: Подрядчик по АвИЭС 18 | FH7: Подрядчик по АвИЭС 19 | FI7: Подрядчик по АвИЭС 20 | FJ7: Всего | FK7: Подрядчик по вырезке 1 | FL7: Подрядчик по вырезке 2 | FM7: Подрядчик по вырезке 3 | FN7: Подрядчик по вырезке 4 | FO7: Подрядчик по вырезке 5 | FP7: Подрядчик по вырезке 6 | FQ7: Подрядчик по вырезке 7 | FR7: Подрядчик по вырезке 8 | FS7: Подрядчик по вырезке 9 | FT7: Подрядчик по вырезке 10 | FU7: Подрядчик по вырезке 11 | FV7: Подрядчик по вырезке 12 | FW7: Подрядчик по вырезке 13 | FX7: Подрядчик по вырезке 14 | FY7: Подрядчик по вырезке 15 | FZ7: Подрядчик по вырезке 16 | GA7: Подрядчик по вырезке 17 | GB7: Подрядчик по вырезке 18 | GC7: Подрядчик по вырезке 19 | GD7: Подрядчик по вырезке 20 | GE7: Всего | GF7: Подрядчик по ННБ 1 | GG7: Подрядчик по ННБ 2 | GH7: Подрядчик по ННБ 3 | GI7: Подрядчик по ННБ 4 | GJ7: Подрядчик по ННБ 5 | GK7: Подрядчик по ННБ 6 | GL7: Подрядчик по ННБ 7 | GM7: Подрядчик по ННБ 8 | GN7: Подрядчик по ННБ 9 | GO7: Подрядчик по ННБ 10 | GP7: Подрядчик по ННБ 11 | GQ7: Подрядчик по ННБ 12 | GR7: Подрядчик по ННБ 13 | GS7: Подрядчик по ННБ 14 | GT7: Подрядчик по ННБ 15 | GU7: Подрядчик по ННБ 16 | GV7: Подрядчик по ННБ 17 | GW7: Подрядчик по ННБ 18 | GX7: Подрядчик по ННБ 19 | GY7: Подрядчик по ННБ 20 | GZ7: Всего | HA7: Подрядчик по ГИС 1 | HB7: Подрядчик по ГИС 2 | HC7: Подрядчик по ГИС 3 | HD7: Подрядчик по ГИС 4 | HE7: Подрядчик по ГИС 5 | HF7: Подрядчик по ГИС 6 | HG7: Подрядчик по ГИС 7 | HH7: Подрядчик по ГИС 8 | HI7: Подрядчик по ГИС 9 | HJ7: Подрядчик по ГИС 10 | HK7: Подрядчик по ГИС 11 | HL7: Подрядчик по ГИС 12 | HM7: Подрядчик по ГИС 13 | HN7: Подрядчик по ГИС 14 | HO7: Подрядчик по ГИС 15 | HP7: Подрядчик по ГИС 16 | HQ7: Подрядчик по ГИС 17 | HR7: Подрядчик по ГИС 18 | HS7: Подрядчик по ГИС 19 | HT7: Подрядчик по ГИС 20 | HU7: Всего | HV7: Подрядчик по ГТИ 1 | HW7: Подрядчик по ГТИ 2 | HX7: Подрядчик по ГТИ 3 | HY7: Подрядчик по ГТИ 4 | HZ7: Подрядчик по ГТИ 5 | IA7: Подрядчик по ГТИ 6 | IB7: Подрядчик по ГТИ 7 | IC7: Подрядчик по ГТИ 8 | ID7: Подрядчик по ГТИ 9 | IE7: Подрядчик по ГТИ 10 | IF7: Подрядчик по ГТИ 11 | IG7: Подрядчик по ГТИ 12 | IH7: Подрядчик по ГТИ 13 | II7: Подрядчик по ГТИ 14 | IJ7: Подрядчик по ГТИ 15 | IK7: Подрядчик по ГТИ 16 | IL7: Подрядчик по ГТИ 17 | IM7: Подрядчик по ГТИ 18 | IN7: Подрядчик по ГТИ 19 | IO7: Подрядчик по ГТИ 20 | IP7: Всего | IQ7: Подрядчик по Цементированию 1 | IR7: Подрядчик по Цементированию 2 | IS7: Подрядчик по Цементированию 3 | IT7: Подрядчик по Цементированию 4 | IU7: Подрядчик по Цементированию 5 | IV7: Подрядчик по Цементированию 6 | IW7: Подрядчик по Цементированию 7 | IX7: Подрядчик по Цементированию 8 | IY7: Подрядчик по Цементированию 9 | IZ7: Подрядчик по Цементированию 10 | JA7: Подрядчик по Цементированию 11 | JB7: Подрядчик по Цементированию 12 | JC7: Подрядчик по Цементированию 13 | JD7: Подрядчик по Цементированию 14 | JE7: Подрядчик по Цементированию 15 | JF7: Подрядчик по Цементированию 16 | JG7: Подрядчик по Цементированию 17 | JH7: Подрядчик по Цементированию 18 | JI7: Подрядчик по Цементированию 19 | JJ7: Подрядчик по Цементированию 20 | JK7: Всего | JL7: Подрядчик по растворам 1 | JM7: Подрядчик по растворам 2 | JN7: Подрядчик по растворам 3 | JO7: Подрядчик по растворам 4 | JP7: Подрядчик по растворам 5 | JQ7: Подрядчик по растворам 6 | JR7: Подрядчик по растворам 7 | JS7: Подрядчик по растворам 8 | JT7: Подрядчик по растворам 9 | JU7: Подрядчик по растворам 10 | JV7: Подрядчик по растворам 11 | JW7: Подрядчик по растворам 12 | JX7: Подрядчик по растворам 13 | JY7: Подрядчик по растворам 14 | JZ7: Подрядчик по растворам 15 | KA7: Подрядчик по растворам 16 | KB7: Подрядчик по растворам 17 | KC7: Подрядчик по растворам 18 | KD7: Подрядчик по растворам 19 | KE7: Подрядчик по растворам 20 | KF7: Всего | KG7: Подрядчик по Долотному сервису 1 | KH7: Подрядчик по Долотному сервису 2 | KI7: Подрядчик по Долотному сервису 3 | KJ7: Подрядчик по Долотному сервису 4 | KK7: Подрядчик по Долотному сервису 5 | KL7: Подрядчик по Долотному сервису 6 | KM7: Подрядчик по Долотному сервису 7 | KN7: Подрядчик по Долотному сервису 8 | KO7: Подрядчик по Долотному сервису 9 | KP7: Подрядчик по Долотному сервису 10 | KQ7: Подрядчик по Долотному сервису 11 | KR7: Подрядчик по Долотному сервису 12 | KS7: Подрядчик по Долотному сервису 13 | KT7: Подрядчик по Долотному сервису 14 | KU7: Подрядчик по Долотному сервису 15 | KV7: Подрядчик по Долотному сервису 16 | KW7: Подрядчик по Долотному сервису 17 | KX7: Подрядчик по Долотному сервису 18 | KY7: Подрядчик по Долотному сервису 19 | KZ7: Подрядчик по Долотному сервису 20 | LA7: Всего | LB7: Подрядчик по Отбору керна 1 | LC7: Подрядчик по Отбору керна 2 | LD7: Подрядчик по Отбору керна 3 | LE7: Подрядчик по Отбору керна 4 | LF7: Подрядчик по Отбору керна 5 | LG7: Подрядчик по Отбору керна 6 | LH7: Подрядчик по Отбору керна 7 | LI7: Подрядчик по Отбору керна 8 | LJ7: Подрядчик по Отбору керна 9 | LK7: Подрядчик по Отбору керна 10 | LL7: Подрядчик по Отбору керна 11 | LM7: Подрядчик по Отбору керна 12 | LN7: Подрядчик по Отбору керна 13 | LO7: Подрядчик по Отбору керна 14 | LP7: Подрядчик по Отбору керна 15 | LQ7: Подрядчик по Отбору керна 16 | LR7: Подрядчик по Отбору керна 17 | LS7: Подрядчик по Отбору керна 18 | LT7: Подрядчик по Отбору керна 19 | LU7: Подрядчик по Отбору керна 20 | LV7: Всего | LW7: Подрядчик по Хвостовикам 1 | LX7: Подрядчик по Хвостовикам 2 | LY7: Подрядчик по Хвостовикам 3 | LZ7: Подрядчик по Хвостовикам 4 | MA7: Подрядчик по Хвостовикам 5 | MB7: Подрядчик по Хвостовикам 6 | MC7: Подрядчик по Хвостовикам 7 | MD7: Подрядчик по Хвостовикам 8 | ME7: Подрядчик по Хвостовикам 9 | MF7: Подрядчик по Хвостовикам 10 | MG7: Подрядчик по Хвостовикам 11 | MH7: Подрядчик по Хвостовикам 12 | MI7: Подрядчик по Хвостовикам 13 | MJ7: Подрядчик по Хвостовикам 14 | MK7: Подрядчик по Хвостовикам 15 | ML7: Подрядчик по Хвостовикам 16 | MM7: Подрядчик по Хвостовикам 17 | MN7: Подрядчик по Хвостовикам 18 | MO7: Подрядчик по Хвостовикам 19 | MP7: Подрядчик по Хвостовикам 20 | MQ7: Всего | MR7: Подрядчик по Шламу 1 | MS7: Подрядчик по Шламу 2 | MT7: Подрядчик по Шламу 3 | MU7: Подрядчик по Шламу 4 | MV7: Подрядчик по Шламу 5 | MW7: Подрядчик по Шламу 6 | MX7: Подрядчик по Шламу 7 | MY7: Подрядчик по Шламу 8 | MZ7: Подрядчик по Шламу 9 | NA7: Подрядчик по Шламу 10 | NB7: Подрядчик по Шламу 11 | NC7: Подрядчик по Шламу 12 | ND7: Подрядчик по Шламу 13 | NE7: Подрядчик по Шламу 14 | NF7: Подрядчик по Шламу 15 | NG7: Подрядчик по Шламу 16 | NH7: Подрядчик по Шламу 17 | NI7: Подрядчик по Шламу 18 | NJ7: Подрядчик по Шламу 19 | NK7: Подрядчик по Шламу 20 | NL7: Всего | NM7: Подрядчик по Супервайзингу 1 | NN7: Подрядчик по Супервайзингу 2 | NO7: Подрядчик по Супервайзингу 3 | NP7: Подрядчик по Супервайзингу 4 | NQ7: Подрядчик по Супервайзингу 5 | NR7: Подрядчик по Супервайзингу 6 | NS7: Подрядчик по Супервайзингу 7 | NT7: Подрядчик по Супервайзингу 8 | NU7: Подрядчик по Супервайзингу 9 | NV7: Подрядчик по Супервайзингу 10 | NW7: Подрядчик по Супервайзингу 11 | NX7: Подрядчик по Супервайзингу 12 | NY7: Подрядчик по Супервайзингу 13 | NZ7: Подрядчик по Супервайзингу 14 | OA7: Подрядчик по Супервайзингу 15 | OB7: Подрядчик по Супервайзингу 16 | OC7: Подрядчик по Супервайзингу 17 | OD7: Подрядчик по Супервайзингу 18 | OE7: Подрядчик по Супервайзингу 19 | OF7: Подрядчик по Супервайзингу 20 | OG7: Всего | OH7: Обсадные колонны (в т.ч. оснастка) | OI7: Услуги УМТС (ТЗР на обсадные колонны) | OJ7: Дизтопливо | OK7: Услуги УМТС (ТЗР на дизтопливо) | OL7: Цемент | OM7: Услуги УМТС (ТЗР цемент) | ON7: Протектор (ГПН-Восток) | OO7: Услуги УМТС (ТЗР на протектор) | OP7: Галит (Хантос) | OQ7: Услуги УМТС (ТЗР на галит) | OR7: Нефть на техничекие нужны | OS7: прочее | OT7: прочее | OU7: прочее | OV7: прочее | OW7: прочее | OX7: прочее | OY7: прочее | OZ7: прочее | PA7: прочее | PB7: Всего | PE7: Подрядчик по Консультационным услугам 1 | PF7: Подрядчик по Консультационным услугам 2 | PG7: Подрядчик по Консультационным услугам 3 | PH7: Подрядчик по Консультационным услугам 4 | PI7: Подрядчик по Консультационным услугам 5 | PJ7: Подрядчик по Консультационным услугам 6 | PK7: Подрядчик по Консультационным услугам 7 | PL7: Подрядчик по Консультационным услугам 8 | PM7: Подрядчик по Консультационным услугам 9 | PN7: Подрядчик по Консультационным услугам 10 | PO7: Подрядчик по Консультационным услугам 11 | PP7: Подрядчик по Консультационным услугам 12 | PQ7: Подрядчик по Консультационным услугам 13 | PR7: Подрядчик по Консультационным услугам 14 | PS7: Подрядчик по Консультационным услугам 15 | PT7: Подрядчик по Консультационным услугам 16 | PU7: Подрядчик по Консультационным услугам 17 | PV7: Подрядчик по Консультационным услугам 18 | PW7: Подрядчик по Консультационным услугам 19 | PX7: Подрядчик по Консультационным услугам 20 | PY7: Всего | QA7: Подрядчик по Проектной док-ии 1 | QB7: Подрядчик по Проектной док-ии 2 | QC7: Подрядчик по Проектной док-ии 3 | QD7: Подрядчик по Проектной док-ии 4 | QE7: Подрядчик по Проектной док-ии 5 | QF7: Подрядчик по Проектной док-ии 6 | QG7: Подрядчик по Проектной док-ии 7 | QH7: Подрядчик по Проектной док-ии 8 | QI7: Подрядчик по Проектной док-ии 9 | QJ7: Подрядчик по Проектной док-ии 10 | QK7: Подрядчик по Проектной док-ии 11 | QL7: Подрядчик по Проектной док-ии 12 | QM7: Подрядчик по Проектной док-ии 13 | QN7: Подрядчик по Проектной док-ии 14 | QO7: Подрядчик по Проектной док-ии 15 | QP7: Подрядчик по Проектной док-ии 16 | QQ7: Подрядчик по Проектной док-ии 17 | QR7: Подрядчик по Проектной док-ии 18 | QS7: Подрядчик по Проектной док-ии 19 | QT7: Подрядчик по Проектной док-ии 20 | QU7: Всего | QX7: Подрядчик по Освоению 1 | QY7: Подрядчик по Освоению 2 | QZ7: Подрядчик по Освоению 3 | RA7: Подрядчик по Освоению 4 | RB7: Подрядчик по Освоению 5 | RC7: Подрядчик по Освоению 6 | RD7: Подрядчик по Освоению 7 | RE7: Подрядчик по Освоению 8 | RF7: Подрядчик по Освоению 9 | RG7: Подрядчик по Освоению 10 | RH7: Подрядчик по Освоению 11 | RI7: Подрядчик по Освоению 12 | RJ7: Подрядчик по Освоению 13 | RK7: Подрядчик по Освоению 14 | RL7: Подрядчик по Освоению 15 | RM7: Подрядчик по Освоению 16 | RN7: Подрядчик по Освоению 17 | RO7: Подрядчик по Освоению 18 | RP7: Подрядчик по Освоению 19 | RQ7: Подрядчик по Освоению 20 | RR7: Всего | RS7: Подрядчик по Освоению стр.насосами 1 | RT7: Подрядчик по Освоению стр.насосами 2 | RU7: Подрядчик по Освоению стр.насосами 3 | RV7: Подрядчик по Освоению стр.насосами 4 | RW7: Подрядчик по Освоению стр.насосами 5 | RX7: Подрядчик по Освоению стр.насосами 6 | RY7: Подрядчик по Освоению стр.насосами 7 | RZ7: Подрядчик по Освоению стр.насосами 8 | SA7: Подрядчик по Освоению стр.насосами 9 | SB7: Подрядчик по Освоению стр.насосами 10 | SC7: Подрядчик по Освоению стр.насосами 11 | SD7: Подрядчик по Освоению стр.насосами 12 | SE7: Подрядчик по Освоению стр.насосами 13 | SF7: Подрядчик по Освоению стр.насосами 14 | SG7: Подрядчик по Освоению стр.насосами 15 | SH7: Подрядчик по Освоению стр.насосами 16 | SI7: Подрядчик по Освоению стр.насосами 17 | SJ7: Подрядчик по Освоению стр.насосами 18 | SK7: Подрядчик по Освоению стр.насосами 19 | SL7: Подрядчик по Освоению стр.насосами 20 | SM7: Всего | SN7: Подрядчик по Глушению, ОПЗ и проч 1 | SO7: Подрядчик по Глушению, ОПЗ и проч 2 | SP7: Подрядчик по Глушению, ОПЗ и проч 3 | SQ7: Подрядчик по Глушению, ОПЗ и проч 4 | SR7: Подрядчик по Глушению, ОПЗ и проч 5 | SS7: Подрядчик по Глушению, ОПЗ и проч 6 | ST7: Подрядчик по Глушению, ОПЗ и проч 7 | SU7: Подрядчик по Глушению, ОПЗ и проч 8 | SV7: Подрядчик по Глушению, ОПЗ и проч 9 | SW7: Подрядчик по Глушению, ОПЗ и проч 10 | SX7: Подрядчик по Глушению, ОПЗ и проч 11 | SY7: Подрядчик по Глушению, ОПЗ и проч 12 | SZ7: Подрядчик по Глушению, ОПЗ и проч 13 | TA7: Подрядчик по Глушению, ОПЗ и проч 14 | TB7: Подрядчик по Глушению, ОПЗ и проч 15 | TC7: Подрядчик по Глушению, ОПЗ и проч 16 | TD7: Подрядчик по Глушению, ОПЗ и проч 17 | TE7: Подрядчик по Глушению, ОПЗ и проч 18 | TF7: Подрядчик по Глушению, ОПЗ и проч 19 | TG7: Подрядчик по Глушению, ОПЗ и проч 20 | TH7: Всего | TI7: Подрядчик по ГИС при освоении 1 | TJ7: Подрядчик по ГИС при освоении 2 | TK7: Подрядчик по ГИС при освоении 3 | TL7: Подрядчик по ГИС при освоении 4 | TM7: Подрядчик по ГИС при освоении 5 | TN7: Подрядчик по ГИС при освоении 6 | TO7: Подрядчик по ГИС при освоении 7 | TP7: Подрядчик по ГИС при освоении 8 | TQ7: Подрядчик по ГИС при освоении 9 | TR7: Подрядчик по ГИС при освоении 10 | TS7: Подрядчик по ГИС при освоении 11 | TT7: Подрядчик по ГИС при освоении 12 | TU7: Подрядчик по ГИС при освоении 13 | TV7: Подрядчик по ГИС при освоении 14 | TW7: Подрядчик по ГИС при освоении 15 | TX7: Подрядчик по ГИС при освоении 16 | TY7: Подрядчик по ГИС при освоении 17 | TZ7: Подрядчик по ГИС при освоении 18 | UA7: Подрядчик по ГИС при освоении 19 | UB7: Подрядчик по ГИС при освоении 20 | UC7: Всего | UD7: Подрядчик по ГРП 1 | UE7: Подрядчик по ГРП 2 | UF7: Подрядчик по ГРП 3 | UG7: Подрядчик по ГРП 4 | UH7: Подрядчик по ГРП 5 | UI7: Подрядчик по ГРП 6 | UJ7: Подрядчик по ГРП 7 | UK7: Подрядчик по ГРП 8 | UL7: Подрядчик по ГРП 9 | UM7: Подрядчик по ГРП 10 | UN7: Подрядчик по ГРП 11 | UO7: Подрядчик по ГРП 12 | UP7: Подрядчик по ГРП 13 | UQ7: Подрядчик по ГРП 14 | UR7: Подрядчик по ГРП 15 | US7: Подрядчик по ГРП 16 | UT7: Подрядчик по ГРП 17 | UU7: Подрядчик по ГРП 18 | UV7: Подрядчик по ГРП 19 | UW7: Подрядчик по ГРП 20 | UX7: Всего | UY7: Подрядчик по ГНКТ 1 | UZ7: Подрядчик по ГНКТ 2 | VA7: Подрядчик по ГНКТ 3 | VB7: Подрядчик по ГНКТ 4 | VC7: Подрядчик по ГНКТ 5 | VD7: Подрядчик по ГНКТ 6 | VE7: Подрядчик по ГНКТ 7 | VF7: Подрядчик по ГНКТ 8 | VG7: Подрядчик по ГНКТ 9 | VH7: Подрядчик по ГНКТ 10 | VI7: Подрядчик по ГНКТ 11 | VJ7: Подрядчик по ГНКТ 12 | VK7: Подрядчик по ГНКТ 13 | VL7: Подрядчик по ГНКТ 14 | VM7: Подрядчик по ГНКТ 15 | VN7: Подрядчик по ГНКТ 16 | VO7: Подрядчик по ГНКТ 17 | VP7: Подрядчик по ГНКТ 18 | VQ7: Подрядчик по ГНКТ 19 | VR7: Подрядчик по ГНКТ 20 | VS7: Всего | VT7: Техн.жидкость глушения | VU7: Услуги УМТС (ТЗР на жидкость глушения) | VV7: Хим. реагенты | VW7: Услуги УМТС (ТЗР хим. реагенты) | VX7: Кварцевый песок | VY7: Услуги УМТС (ТЗР на кварцевый песок) | VZ7: Проппант | WA7: Услуги УМТС (ТЗР на проппант) | WB7: Кислота | WC7: Услуги УМТС (ТЗР на кислоту) | WD7: Пакер (ГПН-Восток) | WE7: Услуги УМТС (ТЗР на пакер) | WF7: прочее | WG7: прочее | WH7: прочее | WI7: прочее | WJ7: прочее | WK7: прочее | WL7: прочее | WM7: прочее | WN7: Всего | WO7: Подрядчик по Супервайзингу при освоении 1 | WP7: Подрядчик по Супервайзингу при освоении 2 | WQ7: Подрядчик по Супервайзингу при освоении 3 | WR7: Подрядчик по Супервайзингу при освоении 4 | WS7: Подрядчик по Супервайзингу при освоении 5 | WT7: Подрядчик по Супервайзингу при освоении 6 | WU7: Подрядчик по Супервайзингу при освоении 7 | WV7: Подрядчик по Супервайзингу при освоении 8 | WW7: Подрядчик по Супервайзингу при освоении 9 | WX7: Подрядчик по Супервайзингу при освоении 10 | WY7: Подрядчик по Супервайзингу при освоении 11 | WZ7: Подрядчик по Супервайзингу при освоении 12 | XA7: Подрядчик по Супервайзингу при освоении 13 | XB7: Подрядчик по Супервайзингу при освоении 14 | XC7: Подрядчик по Супервайзингу при освоении 15 | XD7: Подрядчик по Супервайзингу при освоении 16 | XE7: Подрядчик по Супервайзингу при освоении 17 | XF7: Подрядчик по Супервайзингу при освоении 18 | XG7: Подрядчик по Супервайзингу при освоении 19 | XH7: Подрядчик по Супервайзингу при освоении 20 | XI7: Всего | XK7: ФА | XL7: НКТ | XM7: Прочее | XN7: Прочее | XO7: Прочее | XP7: Всего | XQ7: Подрядчик по подготовке площадки 1 | XR7: Подрядчик по подготовке площадки 2 | XS7: Подрядчик по подготовке площадки 3 | XT7: Подрядчик по подготовке площадки 4 | XU7: Подрядчик по подготовке площадки 5 | XV7: Подрядчик по подготовке площадки 6 | XW7: Подрядчик по подготовке площадки 7 | XX7: Подрядчик по подготовке площадки 8 | XY7: Подрядчик по подготовке площадки 9 | XZ7: Подрядчик по подготовке площадки 10 | YA7: Подрядчик по подготовке площадки 11 | YB7: Подрядчик по подготовке площадки 12 | YC7: Подрядчик по подготовке площадки 13 | YD7: Подрядчик по подготовке площадки 14 | YE7: Всего
A8: 1 | B8: =A8+1 -> 2 | C8: =B8+1 -> 3 | D8: =C8+1 -> 4 | E8: =D8+1 -> 5 | F8: =E8+1 -> 6 | G8: =F8+1 -> 7 | H8: =G8+1 -> 8 | I8: =H8+1 -> 9 | ... YE8: =YD8+1 -> 655 | YF8: =XJ8+1 -> 635
B9: После занесения месторождения в справочник, необходимо выбрать из списка | E9: Под автономностью понимается отсутствие подключения к высоковольтным линиям централизованного электроснабжения во время бурения Да - Наличие автономии Нет - Отсутствие автономии | F9: Под автономностью понимается отсутствие проезда к месторождению / участку месторождения наземным транспортом в течение более 6 месяцев в году Да - Наличие автономии Нет - Отсутствие автономии | Q9: Заполняется по всем скважинам на отчетную дату | R9: Включает пилотный ствол и перебур по геологии | S9: Длина участка, который не входит в протяженность ствола действующей скважины, планового пилотного ствола или перебура ("перебуры по технологии" не включаются). Указать сумму длин при наличии 2х и более пилотных стволов и/или перебуров | AC9: От устья до забоя, в т.ч. по ГС | AR9: С момента спуска первого инструмента КНБК | AS9: Если скважина не введена в эксплуатацию (напр. "сухая" скважина, переведенная в пьезометр.), указывается дата окончания строительства по КС | AV9: Только для скважин, законченных бурением | BE9: Если скважина является переходящей, то в графе "дата окончания " прописывается "перех" | BN9: Амбарное/ Без амбарное | CK9: Указывается расстояние | CL9: При наличчи, указывается расстояние между кустами | CM9: При наличии, указывается длина передвижки от скважины к скважин на одном кусту | CN9: Указывается кол-во | CO9: Указывается кол-во | CP9: Указывается кол-во | CQ9: Заполняется только для переездов и мобилизации Да Нет | CY9: Комулятивная, щелевая, отсутствует | CZ9: Весь объем проппанта по всем проводимым при освоении ГРП на скважине | DD9: Указывается подрядчик, выполняющий подгот. работы (после занесения подрядчика в справочник, необходимо выбрать из списка) | DF9: Указывается подрядчик, выполняющий ВМР (после занесения подрядчика в справочник, необходимо выбрать из списка) | DK9: Включает в себя монтаж БУ, ПНР, бур.вод.колодца, монтаж АвИЭС и проч.оборуд. | DL9: Включает в себя стаскивание и демонтаж БУ, ликв.вод.колодца, демонтаж АвИЭС и проч.оборуд. | GZ9: Стоимость аренды оборудования и услуг соответствующего персонала для направленного бурения, услуги ГИС/измерений во время бурения (MWD, LWD и услуги персонала) | HU9: ГИС на кабеле (инструменте) и другие виды ГИС, проводимые не в процессе бурения (при этом в рамках цикла бурения, не включая ГИС при освоении) | IP9: Все геолого-технические, геолого-геохимические исследования во время бурения (газо-каротаж) | JK9: Включая цемент и услуги по цементированию | KF9: Включая хим. реагенты и добавки для раствора | LA9: Включая долота и прочие материалы связанные с долотным сервисом | NL9: Включая вывоз, переработка и утилизация буровых отходов | OH9: Стоимость обсадной трубы (включая стоимость хвостовиков) на складе предприятия, без затрат доставки до куста и ПРР на кусту | QV9: Все затраты, не отнесенные ни в одну из предложенных статей, но относящиеся к бурению скважин, включая затраты УСС | RR9: Включая оплаченные простои | UC9: Включая свабирование, сопровождение компрессирования, и др. возможные работы. | UX9: Всего затраты подрядчика на проведение всех проппантных ГРП при освоении скважины без учета стоимости пропанта | XJ9: Прокат оборудования, транспорт и т.п.
A10: № п/п | B10: Выбрать из списка | C10: текст | D10: текст | E10: Выбрать из списка | F10: Выбрать из списка | G10: Выбрать из списка | H10: Выбрать из списка | I10: Выбрать из списка | J10: Выбрать из списка | K10: Выбрать из списка | L10: Выбрать из списка | M10: Выбрать из списка | N10: Выбрать из списка | O10: Выбрать из списка | P10: Выбрать из списка | Q10: м | R10: м | S10: м | U10: м | V10: м | W10: м | Y10: м | Z10: м | AA10: м | AB10: м | AC10: м | AD10: м | AE10: м | AF10: м | AG10: м | AH10: м | AI10: м | AJ10: м | AK10: мм | AL10: мм | AM10: мм | AN10: мм | AO10: мм | AP10: мм | AQ10: м | AR10: ДД.ММ.ГГ | AS10: ДД.ММ.ГГ | AT10: ДД.ММ.ГГ | AU10: 00:00 | AV10: ДД.ММ.ГГ | AW10: 00:00 | AX10: сут | AY10: сут | AZ10: сут | BA10: сут | BB10: сут | BC10: сут | BD10: ДД.ММ.ГГ | BE10: ДД.ММ.ГГ | BF10: сут | BG10: сут | BH10: сут | BI10: сут | BJ10: сут | BK10: сут | BL10: ДД.ММ.ГГ | BM10: сут | BN10: Выбрать из списка | BO10: текст | BP10: Выбрать из списка | BQ10: тн | BR10: шт | BS10: Выбрать из списка | BT10: Текст | BU10: шт | BV10: Текст | BW10: шт | BX10: Выбрать из списка | BY10: Выбрать из списка | BZ10: Выбрать из списка | CA10: Выбрать из списка | CB10: Выбрать из списка | CC10: Выбрать из списка | CD10: Выбрать из списка | CE10: Выбрать из списка | CF10: Выбрать из списка | CG10: Выбрать из списка | CH10: Выбрать из списка | CI10: Выбрать из списка | CJ10: Выбрать из списка | CK10: км | CL10: км | CM10: м | CN10: Кол-во, Шт. | CO10: Кол-во, Шт. | CP10: Кол-во, Шт. | CQ10: Да = 1 | CR10: сут | CS10: сут | CT10: сут | CU10: сут | CV10: сут | CW10: сут | CX10: м | CY10: текст (Выбрать из списка) | CZ10: тн | DA10: тн | DB10: тн/сут | DC10: руб. | DD10: текст (Выбрать из списка) | DE10: руб. | DF10: текст (Выбрать из списка) | DG10: руб. | DH10: руб. | DI10: руб. | DJ10: руб. | DK10: руб. | DL10: руб. | DM10: руб. | DN10: руб. | DO10: руб. | DP10: руб. | DQ10: руб. | DR10: руб. | DS10: руб. | DT10: руб. | DU10: руб. | DV10: руб. | DW10: руб. | DX10: руб. | DY10: руб. | DZ10: руб. | EA10: руб. | EB10: руб. | EC10: руб. | ED10: руб. | EE10: руб. | EF10: руб. | EG10: руб. | EH10: руб. | EI10: руб. | EJ10: руб. | EK10: руб. | EL10: руб. | EM10: руб. | EN10: руб. | EO10: руб. | EP10: руб. | EQ10: руб. | ER10: руб. | ES10: руб. | ET10: руб. | EU10: руб. | EV10: руб. | EW10: руб. | EX10: руб. | EY10: руб. | EZ10: руб. | FA10: руб. | FB10: руб. | FC10: руб. | FD10: руб. | FE10: руб. | FF10: руб. | FG10: руб. | FH10: руб. | FI10: руб. | FJ10: руб. | FK10: руб. | FL10: руб. | FM10: руб. | FN10: руб. | FO10: руб. | FP10: руб. | FQ10: руб. | FR10: руб. | FS10: руб. | FT10: руб. | FU10: руб. | FV10: руб. | FW10: руб. | FX10: руб. | FY10: руб. | FZ10: руб. | GA10: руб. | GB10: руб. | GC10: руб. | GD10: руб. | GE10: руб. | GF10: руб. | GG10: руб. | GH10: руб. | GI10: руб. | GJ10: руб. | GK10: руб. | GL10: руб. | GM10: руб. | GN10: руб. | GO10: руб. | GP10: руб. | GQ10: руб. | GR10: руб. | GS10: руб. | GT10: руб. | GU10: руб. | GV10: руб. | GW10: руб. | GX10: руб. | GY10: руб. | GZ10: руб. | HA10: руб. | HB10: руб. | HC10: руб. | HD10: руб. | HE10: руб. | HF10: руб. | HG10: руб. | HH10: руб. | HI10: руб. | HJ10: руб. | HK10: руб. | HL10: руб. | HM10: руб. | HN10: руб. | HO10: руб. | HP10: руб. | HQ10: руб. | HR10: руб. | HS10: руб. | HT10: руб. | HU10: руб. | HV10: руб. | HW10: руб. | HX10: руб. | HY10: руб. | HZ10: руб. | IA10: руб. | IB10: руб. | IC10: руб. | ID10: руб. | IE10: руб. | IF10: руб. | IG10: руб. | IH10: руб. | II10: руб. | IJ10: руб. | IK10: руб. | IL10: руб. | IM10: руб. | IN10: руб. | IO10: руб. | IP10: руб. | IQ10: руб. | IR10: руб. | IS10: руб. | IT10: руб. | IU10: руб. | IV10: руб. | IW10: руб. | IX10: руб. | IY10: руб. | IZ10: руб. | JA10: руб. | JB10: руб. | JC10: руб. | JD10: руб. | JE10: руб. | JF10: руб. | JG10: руб. | JH10: руб. | JI10: руб. | JJ10: руб. | JK10: руб. | JL10: руб. | JM10: руб. | JN10: руб. | JO10: руб. | JP10: руб. | JQ10: руб. | JR10: руб. | JS10: руб. | JT10: руб. | JU10: руб. | JV10: руб. | JW10: руб. | JX10: руб. | JY10: руб. | JZ10: руб. | KA10: руб. | KB10: руб. | KC10: руб. | KD10: руб. | KE10: руб. | KF10: руб. | KG10: руб. | KH10: руб. | KI10: руб. | KJ10: руб. | KK10: руб. | KL10: руб. | KM10: руб. | KN10: руб. | KO10: руб. | KP10: руб. | KQ10: руб. | KR10: руб. | KS10: руб. | KT10: руб. | KU10: руб. | KV10: руб. | KW10: руб. | KX10: руб. | KY10: руб. | KZ10: руб. | LA10: руб. | LB10: руб. | LC10: руб. | LD10: руб. | LE10: руб. | LF10: руб. | LG10: руб. | LH10: руб. | LI10: руб. | LJ10: руб. | LK10: руб. | LL10: руб. | LM10: руб. | LN10: руб. | LO10: руб. | LP10: руб. | LQ10: руб. | LR10: руб. | LS10: руб. | LT10: руб. | LU10: руб. | LV10: руб. | LW10: руб. | LX10: руб. | LY10: руб. | LZ10: руб. | MA10: руб. | MB10: руб. | MC10: руб. | MD10: руб. | ME10: руб. | MF10: руб. | MG10: руб. | MH10: руб. | MI10: руб. | MJ10: руб. | MK10: руб. | ML10: руб. | MM10: руб. | MN10: руб. | MO10: руб. | MP10: руб. | MQ10: руб. | MR10: руб. | MS10: руб. | MT10: руб. | MU10: руб. | MV10: руб. | MW10: руб. | MX10: руб. | MY10: руб. | MZ10: руб. | NA10: руб. | NB10: руб. | NC10: руб. | ND10: руб. | NE10: руб. | NF10: руб. | NG10: руб. | NH10: руб. | NI10: руб. | NJ10: руб. | NK10: руб. | NL10: руб. | NM10: руб. | NN10: руб. | NO10: руб. | NP10: руб. | NQ10: руб. | NR10: руб. | NS10: руб. | NT10: руб. | NU10: руб. | NV10: руб. | NW10: руб. | NX10: руб. | NY10: руб. | NZ10: руб. | OA10: руб. | OB10: руб. | OC10: руб. | OD10: руб. | OE10: руб. | OF10: руб. | OG10: руб. | OH10: руб. | OI10: руб. | OJ10: руб. | OK10: руб. | OL10: руб. | OM10: руб. | ON10: руб. | OO10: руб. | OP10: руб. | OQ10: руб. | OR10: руб. | OS10: руб. | PB10: руб. | PC10: руб. | PD10: руб. | PE10: руб. | PF10: руб. | PG10: руб. | PH10: руб. | PI10: руб. | PJ10: руб. | PK10: руб. | PL10: руб. | PM10: руб. | PN10: руб. | PO10: руб. | PP10: руб. | PQ10: руб. | PR10: руб. | PS10: руб. | PT10: руб. | PU10: руб. | PV10: руб. | PW10: руб. | PX10: руб. | PY10: руб. | PZ10: руб. | QA10: руб. | QB10: руб. | QC10: руб. | QD10: руб. | QE10: руб. | QF10: руб. | QG10: руб. | QH10: руб. | QI10: руб. | QJ10: руб. | QK10: руб. | QL10: руб. | QM10: руб. | QN10: руб. | QO10: руб. | QP10: руб. | QQ10: руб. | QR10: руб. | QS10: руб. | QT10: руб. | QU10: руб. | QV10: руб. | QW10: руб. | QX10: руб. | QY10: руб. | QZ10: руб. | RA10: руб. | RB10: руб. | RC10: руб. | RD10: руб. | RE10: руб. | RF10: руб. | RG10: руб. | RH10: руб. | RI10: руб. | RJ10: руб. | RK10: руб. | RL10: руб. | RM10: руб. | RN10: руб. | RO10: руб. | RP10: руб. | RQ10: руб. | RR10: руб. | RS10: руб. | RT10: руб. | RU10: руб. | RV10: руб. | RW10: руб. | RX10: руб. | RY10: руб. | RZ10: руб. | SA10: руб. | SB10: руб. | SC10: руб. | SD10: руб. | SE10: руб. | SF10: руб. | SG10: руб. | SH10: руб. | SI10: руб. | SJ10: руб. | SK10: руб. | SL10: руб. | SM10: руб. | SN10: руб. | SO10: руб. | SP10: руб. | SQ10: руб. | SR10: руб. | SS10: руб. | ST10: руб. | SU10: руб. | SV10: руб. | SW10: руб. | SX10: руб. | SY10: руб. | SZ10: руб. | TA10: руб. | TB10: руб. | TC10: руб. | TD10: руб. | TE10: руб. | TF10: руб. | TG10: руб. | TH10: руб. | TI10: руб. | TJ10: руб. | TK10: руб. | TL10: руб. | TM10: руб. | TN10: руб. | TO10: руб. | TP10: руб. | TQ10: руб. | TR10: руб. | TS10: руб. | TT10: руб. | TU10: руб. | TV10: руб. | TW10: руб. | TX10: руб. | TY10: руб. | TZ10: руб. | UA10: руб. | UB10: руб. | UC10: руб. | UD10: руб. | UE10: руб. | UF10: руб. | UG10: руб. | UH10: руб. | UI10: руб. | UJ10: руб. | UK10: руб. | UL10: руб. | UM10: руб. | UN10: руб. | UO10: руб. | UP10: руб. | UQ10: руб. | UR10: руб. | US10: руб. | UT10: руб. | UU10: руб. | UV10: руб. | UW10: руб. | UX10: руб. | UY10: руб. | UZ10: руб. | VA10: руб. | VB10: руб. | VC10: руб. | VD10: руб. | VE10: руб. | VF10: руб. | VG10: руб. | VH10: руб. | VI10: руб. | VJ10: руб. | VK10: руб. | VL10: руб. | VM10: руб. | VN10: руб. | VO10: руб. | VP10: руб. | VQ10: руб. | VR10: руб. | VS10: руб. | VT10: руб. | VU10: руб. | VV10: руб. | VW10: руб. | VX10: руб. | VY10: руб. | VZ10: руб. | WA10: руб. | WB10: руб. | WC10: руб. | WF10: руб. | WN10: руб. | WO10: руб. | WP10: руб. | WQ10: руб. | WR10: руб. | WS10: руб. | WT10: руб. | WU10: руб. | WV10: руб. | WW10: руб. | WX10: руб. | WY10: руб. | WZ10: руб. | XA10: руб. | XB10: руб. | XC10: руб. | XD10: руб. | XE10: руб. | XF10: руб. | XG10: руб. | XH10: руб. | XI10: руб. | XJ10: руб. | XK10: руб. | XL10: руб. | XM10: руб. | XN10: руб. | XO10: руб. | XP10: руб. | XQ10: руб. | XR10: руб. | XS10: руб. | XT10: руб. | XU10: руб. | XV10: руб. | XW10: руб. | XX10: руб. | XY10: руб. | XZ10: руб. | YA10: руб. | YB10: руб. | YC10: руб. | YD10: руб. | YE10: руб. | YF10: Текст
