Workbook
Name ___Dec1: 0
Name ___Dec2: 0
Name ___w306: [1]wells_graf!$A$47:$P$69
Name ___w5221: [1]wells_graf!$A$24:$P$46
Name ___w606: [1]wells_graf!$A$1:$H$23
Name ___w628: [1]wells_graf!$I$47:$P$69
Name ___w68: [1]wells_graf!$I$24:$P$46
Name ___W688: [2]wells_graf!$I$24:$P$46
Name __Dec1: 0
Name __Dec2: 0
Name __w306: [1]wells_graf!$A$47:$P$69
Name __w5221: [1]wells_graf!$A$24:$P$46
Name __w606: [1]wells_graf!$A$1:$H$23
Name __w628: [1]wells_graf!$I$47:$P$69
Name __w68: [1]wells_graf!$I$24:$P$46
Name __W688: [2]wells_graf!$I$24:$P$46
Name _2049_2050: '[3]311-1Á10'!#REF!
Name _2049_2050: '[3]311-1Á10'!#REF!
Name _2049_2050: '[3]311-1Á10'!#REF!
Name _2049_2050: '[3]311-1Á10'!#REF!
Name _2049_2050: '[3]311-1Á10'!#REF!
Name _2049_2050: '[3]311-1Á10'!#REF!
Name _2049_2050: '[3]311-1Á10'!#REF!
Name _2049_2050: '[3]311-1Á10'!#REF!
Name _2049_2050: '[3]311-1Á10'!#REF!
Name _2049_2050: '[3]311-1Á10'!#REF!
Name _2049_2050: '[3]311-1Á10'!#REF!
Name _2049_2050: '[3]311-1Á10'!#REF!
Name _2049_2050: '[3]311-1Á10'!#REF!
Name _2049_2050: '[3]311-1Á10'!#REF!
Name _2049_2050: '[3]311-1Á10'!#REF!
Name _2049_2050: '[3]311-1Á10'!#REF!
Name _2049_2050: '[3]311-1Á10'!#REF!
Name _Dec1: 0
Name _Dec2: 0
Name _w306: [1]wells_graf!$A$47:$P$69
Name _w5221: [1]wells_graf!$A$24:$P$46
Name _w606: [1]wells_graf!$A$1:$H$23
Name _w628: [1]wells_graf!$I$47:$P$69
Name _w68: [1]wells_graf!$I$24:$P$46
Name _W688: [2]wells_graf!$I$24:$P$46
Name add1_1Q: [4]Resources!$C$172
Name add1_2Q: [4]Resources!$C$173
Name add1_3D_seismic: [4]Resources!$C$188
Name add1_3Q: [4]Resources!$C$174
Name add1_4Q: [4]Resources!$C$175
Name add1_bases: [4]Resources!$C$195
Name add1_capex_investments: [4]Resources!$C$183
Name add1_cell_sidetracking: '[4]1'!$C$41
Name add1_development_of_drilling_facilities: [4]Resources!$C$187
Name add1_drilling: [4]Resources!$C$185
Name add1_frac_costs: [4]Resources!$C$203
Name add1_inflow_stimulation: [4]Resources!$C$186
Name add1_investment_designation: [4]Resources!$C$169
Name add1_investments: [4]Resources!$C$182
Name add1_modernization: [4]Resources!$C$189
Name add1_motorways: [4]Resources!$C$193
Name add1_new_construction: [4]Resources!$C$198
Name add1_oil_production: [4]Resources!$C$176
Name add1_oil_production_wells_1Q: [4]Resources!$C$177

Sheet Титул 
B1: Проект: | C1: Бурение
C2: Вид проекта
B4: Название проекта: | C4: Бурение скважин в 2016-2018 гг.
G5: куст №21б Приобского месторождения
B7: Наименование организации: | C7: ОАО "Газпромнефть-Хантос"
B9: Начало проведения (мес/год) | C9: 42401 | D9: (мес/год)
B10: Конец проведения работ (мес/год) | C10: 42795 | D10: (мес/год)
B11: Буровой подрядчик | C11: не определен | F11: (наименование организации)
B12: Тип буровго станка | C12: БУ-3000 ЭУК | F12: (наименование типа БУ)
B13: Наличие ВСП | C13: да | D13: (Да/ Нет)
B14: Наличие АвИЭС | C14: нет | D14: (Да/ Нет)
B15: Наличие автономности | C15: нет | D15: (Да/ Нет/ Частично на межсезонье)
B17: ОТВЕТСТВЕННЫЕ СПЕЦИАЛИСТЫ ПО ПРОЕКТУ
B18: По технико-технологическим показателям | C18: Столбовой С.В. | H18: 925-202 | I18: Начальник производственного отдела УСС
C19: Ф.И.О. | H19: тел. | I19: должность
B20: По экономическим показателям | C20: Игумнов М.С. | H20: 354-882 | I20: Начальник планово-договорного отдела УСС
C21: Ф.И.О. | H21: тел. | I21: должность
B23: Тэхнико-экономические показатели строительства по проекту:
B25: Наименование показателя | C25: Ед. изм. | D25: Кол-во скважин, законченных бурением | F25: Кол-во скважин, законченных освоением | H25: Проходка по скважинам, м | J25: Время бурения, сут. | L25: Время осовения, сут.
D26: 2014-2016 | E26: Всего скв. | F26: =D26 -> 2014-2016 | G26: Всего скв. | H26: Всего | I26: Ср. значение на 1 скв. | J26: Всего | K26: Ср. значение на 1 скв. | L26: Всего | M26: Ср. значение на 1 скв.
B27: Итого | C27: скв. | D27: =SUM(D28:D43) -> 8 | E27: =SUM(E28:E43) -> 8 | F27: =SUM(F28:F43) -> 8 | G27: =SUM(G28:G43) -> 8 | H27: =SUM(H28:H43) -> 35000 | I27: =H27/E27 -> 4375 | J27: =SUM(J28:J43) -> 270 | K27: =J27/E27 -> 33.75 | L27: =SUM(L28:L43) -> 152 | M27: =L27/G27 -> 19
B28: Перв.скв. (тип скв) | C28: скв. | D28: 1 | E28: =D28 -> 1 | F28: =D28 -> 1 | G28: =F28 -> 1 | H28: =$E28*I28 -> 5500 | I28: ='Перв. скв '!$D$8 -> 5500 | J28: =$E28*K28 -> 45 | K28: ='Перв. скв '!$O$6 -> 45 | L28: =$G28*M28 -> 19 | M28: ='Перв. скв '!$R$6 -> 19
B29: ННС до 1300 | C29: скв. | D29: 0 | E29: =D29 -> 0 | F29: =D29 -> 0 | G29: =F29 -> 0 | H29: =$E29*I29 -> 0 | I29: =ННСдо1300!$D$8 -> 3000 | J29: =$E29*K29 -> 0 | K29: =ННСдо1300!$O$6 -> 12 | L29: =$G29*M29 -> 0 | M29: =ННСдо1300!$R$6 -> 17
B30: ННС от 1300 до 1500 | C30: скв. | D30: 0 | E30: =D30 -> 0 | F30: =D30 -> 0 | G30: =F30 -> 0 | H30: =$E30*I30 -> 0 | I30: =ННСот1300до1500!$D$8 -> 3250 | J30: =$E30*K30 -> 0 | K30: =ННСот1300до1500!$O$6 -> 12 | L30: =$G30*M30 -> 0 | M30: =ННСот1300до1500!$R$6 -> 17
B31: ННС от 1500 до 2000 | C31: скв. | D31: 0 | E31: =D31 -> 0 | F31: =D31 -> 0 | G31: =F31 -> 0 | H31: =$E31*I31 -> 0 | I31: =ННСот1500до2000!$D$8 -> 3450 | J31: =$E31*K31 -> 0 | K31: =ННСот1500до2000!$O$6 -> 15 | L31: =$G31*M31 -> 0 | M31: =ННСот1500до2000!$R$6 -> 17
B32: ННС от 2000 до 2200 | C32: скв. | D32: 0 | E32: =D32 -> 0 | F32: =D32 -> 0 | G32: =F32 -> 0 | H32: =$E32*I32 -> 0 | I32: =ННСот2000до2200!$D$8 -> 3600 | J32: =$E32*K32 -> 0 | K32: =ННСот2000до2200!$O$6 -> 16 | L32: =$G32*M32 -> 0 | M32: =ННСот2000до2200!$R$6 -> 17
B33: ННС более 2200 | C33: скв. | D33: 0 | E33: =D33 -> 0 | F33: =D33 -> 0 | G33: =F33 -> 0 | H33: =$E33*I33 -> 0 | I33: =ННСболее2200!$D$8 -> 3700 | J33: =$E33*K33 -> 0 | K33: =ННСболее2200!$O$6 -> 18 | L33: =$G33*M33 -> 0 | M33: =ННСболее2200!$R$6 -> 17
B34: Оценочная | C34: скв. | D34: 0 | E34: =D34 -> 0 | F34: =D34 -> 0 | G34: =F34 -> 0 | H34: =$E34*I34 -> 0 | I34: =Оценочная!$D$8 -> 3000 | J34: =$E34*K34 -> 0 | K34: =Оценочная!$O$6 -> 12 | L34: =$G34*M34 -> 0 | M34: =Оценочная!$R$6 -> 0
B35: ННС Юра >800 | C35: скв. | E35: =D35 -> 0 | F35: =D35 -> 0 | G35: =F35 -> 0 | H35: =$E35*I35 -> 0 | I35: ='ННСЮра>800'!$D$8 -> 0 | J35: =$E35*K35 -> 0 | K35: ='ННСЮра>800'!$O$6 -> 0 | L35: =$G35*M35 -> 0 | M35: ='ННСЮра>800'!$R$6 -> 0
B36: ГС с пилотом | C36: скв. | D36: 0 | E36: =D36 -> 0 | F36: =D36 -> 0 | G36: =F36 -> 0 | H36: =$E36*I36 -> 0 | I36: ='ГС пил'!$D$8 -> 5500 | J36: =$E36*K36 -> 0 | K36: ='ГС пил'!$O$6 -> 45 | L36: =$G36*M36 -> 0 | M36: ='ГС пил'!$R$6 -> 19
B37: ГС без пилота | C37: скв. | D37: 6 | E37: =D37 -> 6 | F37: =D37 -> 6 | G37: =F37 -> 6 | H37: =$E37*I37 -> 24000 | I37: ='ГС без пил'!$D$8 -> 4000 | J37: =$E37*K37 -> 180 | K37: ='ГС без пил'!$O$6 -> 30 | L37: =$G37*M37 -> 114 | M37: ='ГС без пил'!$R$6 -> 19
B38: ГС с пилотом и МСГРП | C38: скв. | E38: =D38 -> 0 | F38: =D38 -> 0 | G38: =F38 -> 0 | H38: =$E38*I38 -> 0 | I38: ='ГС пил МСГРП'!$D$8 -> 0 | J38: =$E38*K38 -> 0 | K38: ='ГС пил МСГРП'!$O$6 -> 0 | L38: =$G38*M38 -> 0 | M38: ='ГС пил МСГРП'!$R$6 -> 0
B39: ГС Юра с пилотом | C39: скв. | F39: =D39 -> 0 | G39: =F39 -> 0 | H39: =$E39*I39 -> 0 | I39: ='ГСЮра пил'!$D$8 -> 0 | J39: =$E39*K39 -> 0 | K39: ='ГСЮра пил'!$O$6 -> 0 | L39: =$G39*M39 -> 0 | M39: ='ГСЮра пил'!$R$6 -> 0
B40: ГС Юра без пилота | C40: скв. | F40: =D40 -> 0 | G40: =F40 -> 0 | H40: =$E40*I40 -> 0 | I40: ='ГСЮра без пил'!$D$8 -> 0 | J40: =$E40*K40 -> 0 | K40: ='ГСЮра без пил'!$O$6 -> 0 | L40: =$G40*M40 -> 0 | M40: ='ГСЮра без пил'!$R$6 -> 0
B41: ГС Юра с пилотом и МСГРП | C41: скв. | F41: =D41 -> 0 | G41: =F41 -> 0 | H41: =$E41*I41 -> 0 | I41: ='ГСЮра пил МСГРП'!$D$8 -> 0 | J41: =$E41*K41 -> 0 | K41: ='ГСЮра пил МСГРП'!$O$6 -> 0 | L41: =$G41*M41 -> 0 | M41: ='ГСЮра пил МСГРП'!$R$6 -> 0
B42: Вод/з | C42: скв. | F42: =D42 -> 0 | G42: =F42 -> 0 | H42: =$E42*I42 -> 0 | I42: =ВЗ!$D$8 -> 0 | J42: =$E42*K42 -> 0 | K42: =ВЗ!$O$6 -> 0 | L42: =$G42*M42 -> 0 | M42: =ВЗ!$R$6 -> 0
B43: Посл.скв. | C43: скв. | D43: 1 | E43: =D43 -> 1 | F43: =D43 -> 1 | G43: =F43 -> 1 | H43: =$E43*I43 -> 5500 | I43: ='Посл. скв'!$D$8 -> 5500 | J43: =$E43*K43 -> 45 | K43: ='Посл. скв'!$O$6 -> 45 | L43: =$G43*M43 -> 19 | M43: ='Посл. скв'!$R$6 -> 19
B45: Среднее по ННС | C45: скв. | D45: 0 | E45: 0 | F45: 0 | G45: 0 | H45: 0 | I45: 0 | J45: 0 | K45: 0 | L45: 0 | M45: 0
B46: Среднее по ГС | C46: скв. | D46: =D43+D37+D36+D28 -> 8 | E46: =E43+E37+E36+E28 -> 8 | F46: =F43+F37+F36+F28 -> 8 | G46: =G43+G37+G36+G28 -> 8 | H46: =H43+H37+H36+H28 -> 35000 | I46: =H46/D46 -> 4375 | J46: =J43+J37+J36+J28 -> 270 | K46: =J46/D46 -> 33.75 | L46: =L43+L37+L36+L28 -> 152 | M46: =L46/D46 -> 19
C47: ='[8]Куст №40А'!$AD$2160 -> 265913.3 | E47: =C47-E52 -> -556692.06
...

Sheet ТЭП
A2: ПОДРОБНАЯ СМЕТНАЯ СТОИМОСТЬ СКВАЖИНЫ
C4: Месторождение/ куст: | D4: ='Титул '!G5 -> куст №21б Приобского месторождения | E4: ВСЕГО СТ-ТЬ
C5: Подрядчик по бурению: | D5: ='Титул '!C11 -> не определен | E5: =E7+E9+E11+E13 -> 8.2260536e+08 | F5: =E5/1000-'Титул '!F52 -> 0
C6: Тип буровой установки: | D6: ='Титул '!C12 -> БУ-3000 ЭУК | E6: Всего ВМР
C7: Тип скважины: | D7: Наклонно-направленная | E7: =AN41 -> 33924862
C8: Проходка всего (м): | E8: Всего Бурение
C9: Наличие СВП: | D9: ='Титул '!C13 -> да | E9: =AN190 -> 4.9344461e+08
C10: Наличие АИЭС: | D10: ='Титул '!C14 -> нет | E10: Всего Освоение
C11: Наличие автономности: | D11: ='Титул '!C15 -> нет | E11: =AN206 -> 2.9523589e+08 | AN11: (руб. без НДС)
C12: Кол-во обсадных колонн (включая направл.): | E12: Обор-ие устья | F12: Вид скв. | G12: ='Титул '!B28 -> Перв.скв. (тип скв) | I12: ='Титул '!B29 -> ННС до 1300 | K12: ='Титул '!B30 -> ННС от 1300 до 1500 | M12: ='Титул '!B31 -> ННС от 1500 до 2000 | O12: ='Титул '!B32 -> ННС от 2000 до 2200 | Q12: ='Титул '!B33 -> ННС более 2200 | S12: ='Титул '!B34 -> Оценочная | U12: ='Титул '!B35 -> ННС Юра >800 | W12: ='Титул '!B36 -> ГС с пилотом | Y12: ='Титул '!B37 -> ГС без пилота | AA12: ='Титул '!B38 -> ГС с пилотом и МСГРП | AC12: ='Титул '!B39 -> ГС Юра с пилотом | AE12: ='Титул '!B40 -> ГС Юра без пилота | AG12: ='Титул '!B41 -> ГС Юра с пилотом и МСГРП | AI12: ='Титул '!B42 -> Вод/з | AK12: ='Титул '!B43 -> Посл.скв. | AM12: ИТОГО
C13: Прочие существенные условия: | E13: =AN212 -> 0 | F13: Кол-во скв. | G13: ='Титул '!E28 -> 1 | I13: ='Титул '!E29 -> 0 | K13: ='Титул '!E30 -> 0 | M13: ='Титул '!E31 -> 0 | O13: ='Титул '!E32 -> 0 | Q13: ='Титул '!E33 -> 0 | S13: ='Титул '!E34 -> 0 | U13: ='Титул '!E35 -> 0 | W13: ='Титул '!E36 -> 0 | Y13: 6 | AA13: ='Титул '!E38 -> 0 | AC13: ='Титул '!E39 -> 0 | AE13: ='Титул '!E40 -> 0 | AG13: ='Титул '!E41 -> 0 | AI13: ='Титул '!E42 -> 0 | AK13: ='Титул '!E43 -> 1 | AM13: =SUM(G13:AL13) -> 8
A15: ОПИСАНИЕ РАБОТ И УСЛУГ
A16: КОД | B16: добавочный код | C16: СТАТЬЯ ЗАТРАТ | D16: ОПИСАНИЕ | E16: Подрядчик | F16: Единица измерения | G16: Кол-во | H16: Ст-ть работ | I16: Кол-во | J16: Ст-ть работ | K16: Кол-во | L16: Ст-ть работ | M16: Кол-во | N16: Ст-ть работ | O16: Кол-во | P16: Ст-ть работ | Q16: Кол-во | R16: Ст-ть работ | S16: Кол-во | T16: Ст-ть работ | U16: Кол-во | V16: Ст-ть работ | W16: Кол-во | X16: Ст-ть работ | Y16: Кол-во | Z16: Ст-ть работ | AA16: Кол-во | AB16: Ст-ть работ | AC16: Кол-во | AD16: Ст-ть работ | AE16: Кол-во | AF16: Ст-ть работ | AG16: Кол-во | AH16: Ст-ть работ | AI16: Кол-во | AJ16: Ст-ть работ | AK16: Кол-во | AL16: Ст-ть работ | AM16: Кол-во | AN16: Ст-ть работ | AS16: Ст-ть работ
AN17: 0 | AS17: 0
C18: 1. ЭТАП ВМР
C19: ='Перв. скв '!C19 -> не определен | D19: Описание работ/услуг | AN19: 0 | AS19: 0
D20: ='Перв. скв '!D20 -> Монтаж | E20: ='Перв. скв '!E20 -> не определен | F20: ='Перв. скв '!F20 -> опер. | G20: ='Перв. скв '!$V20*G$13 -> 1 | H20: ='Перв. скв '!$W20*G$13 -> 9401938 | I20: =ННСдо1300!$V20*I$13 -> 0 | J20: =ННСдо1300!$W20*I$13 -> 0 | K20: =ННСот1300до1500!$V20*K$13 -> 0 | L20: =ННСот1300до1500!$W20*K$13 -> 0 | M20: =ННСот1500до2000!$V20*M$13 -> 0 | N20: =ННСот1500до2000!$W20*M$13 -> 0 | O20: =ННСот2000до2200!$V20*O$13 -> 0 | P20: =ННСот2000до2200!$W20*O$13 -> 0 | Q20: =ННСболее2200!$V20*Q$13 -> 0 | R20: =ННСболее2200!$W20*Q$13 -> 0 | S20: =Оценочная!$V20*S$13 -> 0 | T20: =Оценочная!$W20*S$13 -> 0 | U20: ='ННСЮра>800'!$V20*U$13 -> 0 | V20: ='ННСЮра>800'!$W20*U$13 -> 0 | W20: ='ГС пил'!V20*$W$13 -> 0 | X20: ='ГС пил'!W20*$W$13 -> 0 | Y20: ='ГС без пил'!$V20*Y$13 -> 0 | Z20: ='ГС без пил'!$W20*Y$13 -> 0 | AA20: ='ГС пил МСГРП'!$V20*AA$13 -> 0 | AB20: ='ГС пил МСГРП'!$W20*AA$13 -> 0 | AC20: ='ГСЮра пил'!$V20*AC$13 -> 0 | AD20: ='ГСЮра пил'!$W20*AC$13 -> 0 | AE20: ='ГСЮра без пил'!$V20*AE$13 -> 0 | AF20: ='ГСЮра без пил'!$W20*AE$13 -> 0 | AG20: ='ГСЮра пил МСГРП'!$V20*AG$13 -> 0 | AH20: ='ГСЮра пил МСГРП'!$W20*AG$13 -> 0 | AI20: =ВЗ!$V20*AI$13 -> 0 | AJ20: =ВЗ!$W20*AI$13 -> 0 | AK20: ='Посл. скв'!$V20*AK$13 -> 0 | AL20: ='Посл. скв'!$W20*AK$13 -> 0 | AM20: =AK20+AI20+AG20+AE20+AC20+AA20+Y20+W20++U20+S20+Q20+M20+O20+K20+I20+G20 -> 1 | AN20: =AL20+AJ20+AH20+AF20+AD20+AB20+Z20+X20++V20+T20+R20+N20+P20+L20+J20+H20 -> 9401938 | AO20: =('[8]Куст №40А'!AD1998)*1000 -> 0 | AP20: =AO20-AN20 -> -9401938 | AR20: =AS20-AN20 -> 0 | AS20: 9401938
D21: ='Перв. скв '!D21 -> Демонтаж | E21: ='Перв. скв '!E21 -> не определен | F21: ='Перв. скв '!F21 -> опер. | G21: ='Перв. скв '!$V21*G$13 -> 0 | H21: ='Перв. скв '!$W21*G$13 -> 0 | I21: =ННСдо1300!$V21*I$13 -> 0 | J21: =ННСдо1300!$W21*I$13 -> 0 | K21: =ННСот1300до1500!$V21*K$13 -> 0 | L21: =ННСот1300до1500!$W21*K$13 -> 0 | M21: =ННСот1500до2000!$V21*M$13 -> 0 | N21: =ННСот1500до2000!$W21*M$13 -> 0 | O21: =ННСот2000до2200!$V21*O$13 -> 0 | P21: =ННСот2000до2200!$W21*O$13 -> 0 | Q21: =ННСболее2200!$V21*Q$13 -> 0 | R21: =ННСболее2200!$W21*Q$13 -> 0 | S21: =Оценочная!$V21*S$13 -> 0 | T21: =Оценочная!$W21*S$13 -> 0 | U21: ='ННСЮра>800'!$V21*U$13 -> 0 | V21: ='ННСЮра>800'!$W21*U$13 -> 0 | W21: ='ГС пил'!V21*$W$13 -> 0 | X21: ='ГС пил'!W21*$W$13 -> 0 | Y21: ='ГС без пил'!$V21*Y$13 -> 0 | Z21: ='ГС без пил'!$W21*Y$13 -> 0 | AA21: ='ГС пил МСГРП'!$V21*AA$13 -> 0 | AB21: ='ГС пил МСГРП'!$W21*AA$13 -> 0 | AC21: ='ГСЮра пил'!$V21*AC$13 -> 0 | AD21: ='ГСЮра пил'!$W21*AC$13 -> 0 | AE21: ='ГСЮра без пил'!$V21*AE$13 -> 0 | AF21: ='ГСЮра без пил'!$W21*AE$13 -> 0 | AG21: ='ГСЮра пил МСГРП'!$V21*AG$13 -> 0 | AH21: ='ГСЮра пил МСГРП'!$W21*AG$13 -> 0 | AI21: =ВЗ!$V21*AI$13 -> 0 | AJ21: =ВЗ!$W21*AI$13 -> 0 | AK21: ='Посл. скв'!$V21*AK$13 -> 1 | AL21: ='Посл. скв'!$W21*AK$13 -> 2344149 | AM21: =AK21+AI21+AG21+AE21+AC21+AA21+Y21+W21++U21+S21+Q21+M21+O21+K21+I21+G21 -> 1 | AN21: =AL21+AJ21+AH21+AF21+AD21+AB21+Z21+X21++V21+T21+R21+N21+P21+L21+J21+H21 -> 2344149 | AO21: =('[8]Куст №40А'!AD1999)*1000 -> 0 | AP21: =AO21-AN21 -> -2344149 | AR21: =AS21-AN21 -> 0 | AS21: 2344149
D22: ='Перв. скв '!D22 -> Эксплуатация АВЭС | E22: ='Перв. скв '!E22 -> не определен | F22: ='Перв. скв '!F22 -> опер. | G22: ='Перв. скв '!$V22*G$13 -> 0 | H22: ='Перв. скв '!$W22*G$13 -> 0 | I22: =ННСдо1300!$V22*I$13 -> 0 | J22: =ННСдо1300!$W22*I$13 -> 0 | K22: =ННСот1300до1500!$V22*K$13 -> 0 | L22: =ННСот1300до1500!$W22*K$13 -> 0 | M22: =ННСот1500до2000!$V22*M$13 -> 0 | N22: =ННСот1500до2000!$W22*M$13 -> 0 | O22: =ННСот2000до2200!$V22*O$13 -> 0 | P22: =ННСот2000до2200!$W22*O$13 -> 0 | Q22: =ННСболее2200!$V22*Q$13 -> 0 | R22: =ННСболее2200!$W22*Q$13 -> 0 | S22: =Оценочная!$V22*S$13 -> 0 | T22: =Оценочная!$W22*S$13 -> 0 | U22: ='ННСЮра>800'!$V22*U$13 -> 0 | V22: ='ННСЮра>800'!$W22*U$13 -> 0 | W22: ='ГС пил'!V22*$W$13 -> 0 | X22: ='ГС пил'!W22*$W$13 -> 0 | Y22: ='ГС без пил'!$V22*Y$13 -> 0 | Z22: ='ГС без пил'!$W22*Y$13 -> 0 | AA22: ='ГС пил МСГРП'!$V22*AA$13 -> 0 | AB22: ='ГС пил МСГРП'!$W22*AA$13 -> 0 | AC22: ='ГСЮра пил'!$V22*AC$13 -> 0 | AD22: ='ГСЮра пил'!$W22*AC$13 -> 0 | AE22: ='ГСЮра без пил'!$V22*AE$13 -> 0 | AF22: ='ГСЮра без пил'!$W22*AE$13 -> 0 | AG22: ='ГСЮра пил МСГРП'!$V22*AG$13 -> 0 | AH22: ='ГСЮра пил МСГРП'!$W22*AG$13 -> 0 | AI22: =ВЗ!$V22*AI$13 -> 0 | AJ22: =ВЗ!$W22*AI$13 -> 0 | AK22: ='Посл. скв'!$V22*AK$13 -> 0 | AL22: ='Посл. скв'!$W22*AK$13 -> 0 | AM22: =AK22+AI22+AG22+AE22+AC22+AA22+Y22+W22++U22+S22+Q22+M22+O22+K22+I22+G22 -> 0 | AN22: =AL22+AJ22+AH22+AF22+AD22+AB22+Z22+X22++V22+T22+R22+N22+P22+L22+J22+H22 -> 0 | AO22: =('[8]Куст №40А'!AD2000)*1000 -> 0 | AP22: =AO22-AN22 -> 0 | AR22: =AS22-AN22 -> 0 | AS22: 0
D23: ='Перв. скв '!D23 -> Передислокация БУ в пределах м-я | E23: ='Перв. скв '!E23 -> не определен | F23: ='Перв. скв '!F23 -> опер. | G23: ='Перв. скв '!$V23*G$13 -> 0 | H23: ='Перв. скв '!$W23*G$13 -> 0 | I23: =ННСдо1300!$V23*I$13 -> 0 | J23: =ННСдо1300!$W23*I$13 -> 0 | K23: =ННСот1300до1500!$V23*K$13 -> 0 | L23: =ННСот1300до1500!$W23*K$13 -> 0 | M23: =ННСот1500до2000!$V23*M$13 -> 0 | N23: =ННСот1500до2000!$W23*M$13 -> 0 | O23: =ННСот2000до2200!$V23*O$13 -> 0 | P23: =ННСот2000до2200!$W23*O$13 -> 0 | Q23: =ННСболее2200!$V23*Q$13 -> 0 | R23: =ННСболее2200!$W23*Q$13 -> 0 | S23: =Оценочная!$V23*S$13 -> 0 | T23: =Оценочная!$W23*S$13 -> 0 | U23: ='ННСЮра>800'!$V23*U$13 -> 0 | V23: ='ННСЮра>800'!$W23*U$13 -> 0 | W23: ='ГС пил'!V23*$W$13 -> 0 | X23: ='ГС пил'!W23*$W$13 -> 0 | Y23: ='ГС без пил'!$V23*Y$13 -> 0 | Z23: ='ГС без пил'!$W23*Y$13 -> 0 | AA23: ='ГС пил МСГРП'!$V23*AA$13 -> 0 | AB23: ='ГС пил МСГРП'!$W23*AA$13 -> 0 | AC23: ='ГСЮра пил'!$V23*AC$13 -> 0 | AD23: ='ГСЮра пил'!$W23*AC$13 -> 0 | AE23: ='ГСЮра без пил'!$V23*AE$13 -> 0 | AF23: ='ГСЮра без пил'!$W23*AE$13 -> 0 | AG23: ='ГСЮра пил МСГРП'!$V23*AG$13 -> 0 | AH23: ='ГСЮра пил МСГРП'!$W23*AG$13 -> 0 | AI23: =ВЗ!$V23*AI$13 -> 0 | AJ23: =ВЗ!$W23*AI$13 -> 0 | AK23: ='Посл. скв'!$V23*AK$13 -> 0 | AL23: ='Посл. скв'!$W23*AK$13 -> 0 | AM23: =AK23+AI23+AG23+AE23+AC23+AA23+Y23+W23++U23+S23+Q23+M23+O23+K23+I23+G23 -> 0 | AN23: =AL23+AJ23+AH23+AF23+AD23+AB23+Z23+X23++V23+T23+R23+N23+P23+L23+J23+H23 -> 0 | AO23: =('[8]Куст №40А'!AD2001)*1000 -> 0 | AP23: =AO23-AN23 -> 0 | AR23: =AS23-AN23 -> 693236 | AS23: 693236
D24: ='Перв. скв '!D24 -> Передислокация БУ 250-500 км. | E24: ='Перв. скв '!E24 -> не определен | F24: ='Перв. скв '!F24 -> опер. | G24: ='Перв. скв '!$V24*G$13 -> 1 | H24: ='Перв. скв '!$W24*G$13 -> 9837322 | I24: =ННСдо1300!$V24*I$13 -> 0 | J24: =ННСдо1300!$W24*I$13 -> 0 | K24: =ННСот1300до1500!$V24*K$13 -> 0 | L24: =ННСот1300до1500!$W24*K$13 -> 0 | M24: =ННСот1500до2000!$V24*M$13 -> 0 | N24: =ННСот1500до2000!$W24*M$13 -> 0 | O24: =ННСот2000до2200!$V24*O$13 -> 0 | P24: =ННСот2000до2200!$W24*O$13 -> 0 | Q24: =ННСболее2200!$V24*Q$13 -> 0 | R24: =ННСболее2200!$W24*Q$13 -> 0 | S24: =Оценочная!$V24*S$13 -> 0 | T24: =Оценочная!$W24*S$13 -> 0 | U24: ='ННСЮра>800'!$V24*U$13 -> 0 | V24: ='ННСЮра>800'!$W24*U$13 -> 0 | W24: ='ГС пил'!V24*$W$13 -> 0 | X24: ='ГС пил'!W24*$W$13 -> 0 | Y24: ='ГС без пил'!$V24*Y$13 -> 0 | Z24: ='ГС без пил'!$W24*Y$13 -> 0 | AA24: ='ГС пил МСГРП'!$V24*AA$13 -> 0 | AB24: ='ГС пил МСГРП'!$W24*AA$13 -> 0 | AC24: ='ГСЮра пил'!$V24*AC$13 -> 0 | AD24: ='ГСЮра пил'!$W24*AC$13 -> 0 | AE24: ='ГСЮра без пил'!$V24*AE$13 -> 0 | AF24: ='ГСЮра без пил'!$W24*AE$13 -> 0 | AG24: ='ГСЮра пил МСГРП'!$V24*AG$13 -> 0 | AH24: ='ГСЮра пил МСГРП'!$W24*AG$13 -> 0 | AI24: =ВЗ!$V24*AI$13 -> 0 | AJ24: =ВЗ!$W24*AI$13 -> 0 | AK24: ='Посл. скв'!$V24*AK$13 -> 0 | AL24: ='Посл. скв'!$W24*AK$13 -> 0 | AM24: =AK24+AI24+AG24+AE24+AC24+AA24+Y24+W24++U24+S24+Q24+M24+O24+K24+I24+G24 -> 1 | AN24: =AL24+AJ24+AH24+AF24+AD24+AB24+Z24+X24++V24+T24+R24+N24+P24+L24+J24+H24 -> 9837322 | AO24: =('[8]Куст №40А'!AD2002)*1000 -> 0 | AP24: =AO24-AN24 -> -9837322 | AR24: =AS24-AN24 -> -9837322 | AS24: 0
D25: ='Перв. скв '!D25 -> Передислокация бр. бур в пределах м-я | E25: ='Перв. скв '!E25 -> не определен | F25: ='Перв. скв '!F25 -> опер. | G25: ='Перв. скв '!$V25*G$13 -> 0 | H25: ='Перв. скв '!$W25*G$13 -> 0 | I25: =ННСдо1300!$V25*I$13 -> 0 | J25: =ННСдо1300!$W25*I$13 -> 0 | K25: =ННСот1300до1500!$V25*K$13 -> 0 | L25: =ННСот1300до1500!$W25*K$13 -> 0 | M25: =ННСот1500до2000!$V25*M$13 -> 0 | N25: =ННСот1500до2000!$W25*M$13 -> 0 | O25: =ННСот2000до2200!$V25*O$13 -> 0 | P25: =ННСот2000до2200!$W25*O$13 -> 0 | Q25: =ННСболее2200!$V25*Q$13 -> 0 | R25: =ННСболее2200!$W25*Q$13 -> 0 | S25: =Оценочная!$V25*S$13 -> 0 | T25: =Оценочная!$W25*S$13 -> 0 | U25: ='ННСЮра>800'!$V25*U$13 -> 0 | V25: ='ННСЮра>800'!$W25*U$13 -> 0 | W25: ='ГС пил'!V25*$W$13 -> 0 | X25: ='ГС пил'!W25*$W$13 -> 0 | Y25: ='ГС без пил'!$V25*Y$13 -> 0 | Z25: ='ГС без пил'!$W25*Y$13 -> 0 | AA25: ='ГС пил МСГРП'!$V25*AA$13 -> 0 | AB25: ='ГС пил МСГРП'!$W25*AA$13 -> 0 | AC25: ='ГСЮра пил'!$V25*AC$13 -> 0 | AD25: ='ГСЮра пил'!$W25*AC$13 -> 0 | AE25: ='ГСЮра без пил'!$V25*AE$13 -> 0 | AF25: ='ГСЮра без пил'!$W25*AE$13 -> 0 | AG25: ='ГСЮра пил МСГРП'!$V25*AG$13 -> 0 | AH25: ='ГСЮра пил МСГРП'!$W25*AG$13 -> 0 | AI25: =ВЗ!$V25*AI$13 -> 0 | AJ25: =ВЗ!$W25*AI$13 -> 0 | AK25: ='Посл. скв'!$V25*AK$13 -> 0 | AL25: ='Посл. скв'!$W25*AK$13 -> 0 | AM25: =AK25+AI25+AG25+AE25+AC25+AA25+Y25+W25++U25+S25+Q25+M25+O25+K25+I25+G25 -> 0 | AN25: =AL25+AJ25+AH25+AF25+AD25+AB25+Z25+X25++V25+T25+R25+N25+P25+L25+J25+H25 -> 0 | AO25: =('[8]Куст №40А'!AD2003)*1000 -> 0 | AP25: =AO25-AN25 -> 0 | AR25: =AS25-AN25 -> 130867 | AS25: 130867
D26: ='Перв. скв '!D26 -> Передислокация бр. бур 250-500 км. | E26: ='Перв. скв '!E26 -> не определен | F26: ='Перв. скв '!F26 -> опер. | G26: ='Перв. скв '!$V26*G$13 -> 1 | H26: ='Перв. скв '!$W26*G$13 -> 1788526 | I26: =ННСдо1300!$V26*I$13 -> 0 | J26: =ННСдо1300!$W26*I$13 -> 0 | K26: =ННСот1300до1500!$V26*K$13 -> 0 | L26: =ННСот1300до1500!$W26*K$13 -> 0 | M26: =ННСот1500до2000!$V26*M$13 -> 0 | N26: =ННСот1500до2000!$W26*M$13 -> 0 | O26: =ННСот2000до2200!$V26*O$13 -> 0 | P26: =ННСот2000до2200!$W26*O$13 -> 0 | Q26: =ННСболее2200!$V26*Q$13 -> 0 | R26: =ННСболее2200!$W26*Q$13 -> 0 | S26: =Оценочная!$V26*S$13 -> 0 | T26: =Оценочная!$W26*S$13 -> 0 | U26: ='ННСЮра>800'!$V26*U$13 -> 0 | V26: ='ННСЮра>800'!$W26*U$13 -> 0 | W26: ='ГС пил'!V26*$W$13 -> 0 | X26: ='ГС пил'!W26*$W$13 -> 0 | Y26: ='ГС без пил'!$V26*Y$13 -> 0 | Z26: ='ГС без пил'!$W26*Y$13 -> 0 | AA26: ='ГС пил МСГРП'!$V26*AA$13 -> 0 | AB26: ='ГС пил МСГРП'!$W26*AA$13 -> 0 | AC26: ='ГСЮра пил'!$V26*AC$13 -> 0 | AD26: ='ГСЮра пил'!$W26*AC$13 -> 0 | AE26: ='ГСЮра без пил'!$V26*AE$13 -> 0 | AF26: ='ГСЮра без пил'!$W26*AE$13 -> 0 | AG26: ='ГСЮра пил МСГРП'!$V26*AG$13 -> 0 | AH26: ='ГСЮра пил МСГРП'!$W26*AG$13 -> 0 | AI26: =ВЗ!$V26*AI$13 -> 0 | AJ26: =ВЗ!$W26*AI$13 -> 0 | AK26: ='Посл. скв'!$V26*AK$13 -> 0 | AL26: ='Посл. скв'!$W26*AK$13 -> 0 | AM26: =AK26+AI26+AG26+AE26+AC26+AA26+Y26+W26++U26+S26+Q26+M26+O26+K26+I26+G26 -> 1 | AN26: =AL26+AJ26+AH26+AF26+AD26+AB26+Z26+X26++V26+T26+R26+N26+P26+L26+J26+H26 -> 1788526 | AO26: =('[8]Куст №40А'!AD2004)*1000 -> 0 | AP26: =AO26-AN26 -> -1788526 | AR26: =AS26-AN26 -> -1788526 | AS26: 0
D27: ='Перв. скв '!D27 -> Передислокация бригады ВМР в пределах м-я | E27: ='Перв. скв '!E27 -> не определен | F27: ='Перв. скв '!F27 -> опер. | G27: ='Перв. скв '!$V27*G$13 -> 0 | H27: ='Перв. скв '!$W27*G$13 -> 0 | I27: =ННСдо1300!$V27*I$13 -> 0 | J27: =ННСдо1300!$W27*I$13 -> 0 | K27: =ННСот1300до1500!$V27*K$13 -> 0 | L27: =ННСот1300до1500!$W27*K$13 -> 0 | M27: =ННСот1500до2000!$V27*M$13 -> 0 | N27: =ННСот1500до2000!$W27*M$13 -> 0 | O27: =ННСот2000до2200!$V27*O$13 -> 0 | P27: =ННСот2000до2200!$W27*O$13 -> 0 | Q27: =ННСболее2200!$V27*Q$13 -> 0 | R27: =ННСболее2200!$W27*Q$13 -> 0 | S27: =Оценочная!$V27*S$13 -> 0 | T27: =Оценочная!$W27*S$13 -> 0 | U27: ='ННСЮра>800'!$V27*U$13 -> 0 | V27: ='ННСЮра>800'!$W27*U$13 -> 0 | W27: ='ГС пил'!V27*$W$13 -> 0 | X27: ='ГС пил'!W27*$W$13 -> 0 | Y27: ='ГС без пил'!$V27*Y$13 -> 0 | Z27: ='ГС без пил'!$W27*Y$13 -> 0 | AA27: ='ГС пил МСГРП'!$V27*AA$13 -> 0 | AB27: ='ГС пил МСГРП'!$W27*AA$13 -> 0 | AC27: ='ГСЮра пил'!$V27*AC$13 -> 0 | AD27: ='ГСЮра пил'!$W27*AC$13 -> 0 | AE27: ='ГСЮра без пил'!$V27*AE$13 -> 0 | AF27: ='ГСЮра без пил'!$W27*AE$13 -> 0 | AG27: ='ГСЮра пил МСГРП'!$V27*AG$13 -> 0 | AH27: ='ГСЮра пил МСГРП'!$W27*AG$13 -> 0 | AI27: =ВЗ!$V27*AI$13 -> 0 | AJ27: =ВЗ!$W27*AI$13 -> 0 | AK27: ='Посл. скв'!$V27*AK$13 -> 0 | AL27: ='Посл. скв'!$W27*AK$13 -> 0 | AM27: =AK27+AI27+AG27+AE27+AC27+AA27+Y27+W27++U27+S27+Q27+M27+O27+K27+I27+G27 -> 0 | AN27: =AL27+AJ27+AH27+AF27+AD27+AB27+Z27+X27++V27+T27+R27+N27+P27+L27+J27+H27 -> 0 | AO27: =('[8]Куст №40А'!AD2005)*1000 -> 0 | AP27: =AO27-AN27 -> 0 | AR27: =AS27-AN27 -> 130867 | AS27: 130867
D28: ='Перв. скв '!D28 -> Передислокация бригады ВМР 250-500 км. | E28: ='Перв. скв '!E28 -> не определен | F28: ='Перв. скв '!F28 -> опер. | G28: ='Перв. скв '!$V28*G$13 -> 2 | H28: ='Перв. скв '!$W28*G$13 -> 3577052 | I28: =ННСдо1300!$V28*I$13 -> 0 | J28: =ННСдо1300!$W28*I$13 -> 0 | K28: =ННСот1300до1500!$V28*K$13 -> 0 | L28: =ННСот1300до1500!$W28*K$13 -> 0 | M28: =ННСот1500до2000!$V28*M$13 -> 0 | N28: =ННСот1500до2000!$W28*M$13 -> 0 | O28: =ННСот2000до2200!$V28*O$13 -> 0 | P28: =ННСот2000до2200!$W28*O$13 -> 0 | Q28: =ННСболее2200!$V28*Q$13 -> 0 | R28: =ННСболее2200!$W28*Q$13 -> 0 | S28: =Оценочная!$V28*S$13 -> 0 | T28: =Оценочная!$W28*S$13 -> 0 | U28: ='ННСЮра>800'!$V28*U$13 -> 0 | V28: ='ННСЮра>800'!$W28*U$13 -> 0 | W28: ='ГС пил'!V28*$W$13 -> 0 | X28: ='ГС пил'!W28*$W$13 -> 0 | Y28: ='ГС без пил'!$V28*Y$13 -> 0 | Z28: ='ГС без пил'!$W28*Y$13 -> 0 | AA28: ='ГС пил МСГРП'!$V28*AA$13 -> 0 | AB28: ='ГС пил МСГРП'!$W28*AA$13 -> 0 | AC28: ='ГСЮра пил'!$V28*AC$13 -> 0 | AD28: ='ГСЮра пил'!$W28*AC$13 -> 0 | AE28: ='ГСЮра без пил'!$V28*AE$13 -> 0 | AF28: ='ГСЮра без пил'!$W28*AE$13 -> 0 | AG28: ='ГСЮра пил МСГРП'!$V28*AG$13 -> 0 | AH28: ='ГСЮра пил МСГРП'!$W28*AG$13 -> 0 | AI28: =ВЗ!$V28*AI$13 -> 0 | AJ28: =ВЗ!$W28*AI$13 -> 0 | AK28: ='Посл. скв'!$V28*AK$13 -> 2 | AL28: ='Посл. скв'!$W28*AK$13 -> 3577052 | AM28: =AK28+AI28+AG28+AE28+AC28+AA28+Y28+W28++U28+S28+Q28+M28+O28+K28+I28+G28 -> 4 | AN28: =AL28+AJ28+AH28+AF28+AD28+AB28+Z28+X28++V28+T28+R28+N28+P28+L28+J28+H28 -> 7154104 | AO28: =('[8]Куст №40А'!AD2006)*1000 -> 0 | AP28: =AO28-AN28 -> -7154104 | AR28: =AS28-AN28 -> -7154104 | AS28: 0
D29: ='Перв. скв '!D29 -> Передвижка 5 м. | E29: ='Перв. скв '!E29 -> не определен | F29: ='Перв. скв '!F29 -> опер. | G29: ='Перв. скв '!$V29*G$13 -> 0 | H29: ='Перв. скв '!$W29*G$13 -> 0 | I29: =ННСдо1300!$V29*I$13 -> 0 | J29: =ННСдо1300!$W29*I$13 -> 0 | K29: =ННСот1300до1500!$V29*K$13 -> 0 | L29: =ННСот1300до1500!$W29*K$13 -> 0 | M29: =ННСот1500до2000!$V29*M$13 -> 0 | N29: =ННСот1500до2000!$W29*M$13 -> 0 | O29: =ННСот2000до2200!$V29*O$13 -> 0 | P29: =ННСот2000до2200!$W29*O$13 -> 0 | Q29: =ННСболее2200!$V29*Q$13 -> 0 | R29: =ННСболее2200!$W29*Q$13 -> 0 | S29: =Оценочная!$V29*S$13 -> 0 | T29: =Оценочная!$W29*S$13 -> 0 | U29: ='ННСЮра>800'!$V29*U$13 -> 0 | V29: ='ННСЮра>800'!$W29*U$13 -> 0 | W29: ='ГС пил'!V29*$W$13 -> 0 | X29: ='ГС пил'!W29*$W$13 -> 0 | Y29: ='ГС без пил'!$V29*Y$13 -> 0 | Z29: ='ГС без пил'!$W29*Y$13 -> 0 | AA29: ='ГС пил МСГРП'!$V29*AA$13 -> 0 | AB29: ='ГС пил МСГРП'!$W29*AA$13 -> 0 | AC29: ='ГСЮра пил'!$V29*AC$13 -> 0 | AD29: ='ГСЮра пил'!$W29*AC$13 -> 0 | AE29: ='ГСЮра без пил'!$V29*AE$13 -> 0 | AF29: ='ГСЮра без пил'!$W29*AE$13 -> 0 | AG29: ='ГСЮра пил МСГРП'!$V29*AG$13 -> 0 | AH29: ='ГСЮра пил МСГРП'!$W29*AG$13 -> 0 | AI29: =ВЗ!$V29*AI$13 -> 0 | AJ29: =ВЗ!$W29*AI$13 -> 0 | AK29: ='Посл. скв'!$V29*AK$13 -> 0 | AL29: ='Посл. скв'!$W29*AK$13 -> 0 | AM29: =AK29+AI29+AG29+AE29+AC29+AA29+Y29+W29++U29+S29+Q29+M29+O29+K29+I29+G29 -> 0 | AN29: =AL29+AJ29+AH29+AF29+AD29+AB29+Z29+X29++V29+T29+R29+N29+P29+L29+J29+H29 -> 0 | AO29: =('[8]Куст №40А'!AD2007)*1000 -> 0 | AP29: =AO29-AN29 -> 0 | AR29: =AS29-AN29 -> 0 | AS29: 0
D30: ='Перв. скв '!D30 -> Передвижка 9 м. | E30: ='Перв. скв '!E30 -> не определен | F30: ='Перв. скв '!F30 -> опер. | G30: ='Перв. скв '!$V30*G$13 -> 0 | H30: ='Перв. скв '!$W30*G$13 -> 0 | I30: =ННСдо1300!$V30*I$13 -> 0 | J30: =ННСдо1300!$W30*I$13 -> 0 | K30: =ННСот1300до1500!$V30*K$13 -> 0 | L30: =ННСот1300до1500!$W30*K$13 -> 0 | M30: =ННСот1500до2000!$V30*M$13 -> 0 | N30: =ННСот1500до2000!$W30*M$13 -> 0 | O30: =ННСот2000до2200!$V30*O$13 -> 0 | P30: =ННСот2000до2200!$W30*O$13 -> 0 | Q30: =ННСболее2200!$V30*Q$13 -> 0 | R30: =ННСболее2200!$W30*Q$13 -> 0 | S30: =Оценочная!$V30*S$13 -> 0 | T30: =Оценочная!$W30*S$13 -> 0 | U30: ='ННСЮра>800'!$V30*U$13 -> 0 | V30: ='ННСЮра>800'!$W30*U$13 -> 0 | W30: ='ГС пил'!V30*$W$13 -> 0 | X30: ='ГС пил'!W30*$W$13 -> 0 | Y30: ='ГС без пил'!$V30*Y$13 -> 6 | Z30: ='ГС без пил'!$W30*Y$13 -> 1592190 | AA30: ='ГС пил МСГРП'!$V30*AA$13 -> 0 | AB30: ='ГС пил МСГРП'!$W30*AA$13 -> 0 | AC30: ='ГСЮра пил'!$V30*AC$13 -> 0 | AD30: ='ГСЮра пил'!$W30*AC$13 -> 0 | AE30: ='ГСЮра без пил'!$V30*AE$13 -> 0 | AF30: ='ГСЮра без пил'!$W30*AE$13 -> 0 | AG30: ='ГСЮра пил МСГРП'!$V30*AG$13 -> 0 | AH30: ='ГСЮра пил МСГРП'!$W30*AG$13 -> 0 | AI30: =ВЗ!$V30*AI$13 -> 0 | AJ30: =ВЗ!$W30*AI$13 -> 0 | AK30: ='Посл. скв'!$V30*AK$13 -> 0 | AL30: ='Посл. скв'!$W30*AK$13 -> 0 | AM30: =AK30+AI30+AG30+AE30+AC30+AA30+Y30+W30++U30+S30+Q30+M30+O30+K30+I30+G30 -> 6 | AN30: =AL30+AJ30+AH30+AF30+AD30+AB30+Z30+X30++V30+T30+R30+N30+P30+L30+J30+H30 -> 1592190 | AO30: =('[8]Куст №40А'!AD2008)*1000 -> 1532030 | AP30: =AO30-AN30 -> -60160 | AR30: =AS30-AN30 -> 0 | AS30: 1592190
D31: ='Перв. скв '!D31 -> Передвижка 18 м. | E31: ='Перв. скв '!E31 -> не определен | F31: ='Перв. скв '!F31 -> опер. | G31: ='Перв. скв '!$V31*G$13 -> 0 | H31: ='Перв. скв '!$W31*G$13 -> 0 | I31: =ННСдо1300!$V31*I$13 -> 0 | J31: =ННСдо1300!$W31*I$13 -> 0 | K31: =ННСот1300до1500!$V31*K$13 -> 0 | L31: =ННСот1300до1500!$W31*K$13 -> 0 | M31: =ННСот1500до2000!$V31*M$13 -> 0 | N31: =ННСот1500до2000!$W31*M$13 -> 0 | O31: =ННСот2000до2200!$V31*O$13 -> 0 | P31: =ННСот2000до2200!$W31*O$13 -> 0 | Q31: =ННСболее2200!$V31*Q$13 -> 0 | R31: =ННСболее2200!$W31*Q$13 -> 0 | S31: =Оценочная!$V31*S$13 -> 0 | T31: =Оценочная!$W31*S$13 -> 0 | U31: ='ННСЮра>800'!$V31*U$13 -> 0 | V31: ='ННСЮра>800'!$W31*U$13 -> 0 | W31: ='ГС пил'!V31*$W$13 -> 0 | X31: ='ГС пил'!W31*$W$13 -> 0 | Y31: ='ГС без пил'!$V31*Y$13 -> 0 | Z31: ='ГС без пил'!$W31*Y$13 -> 0 | AA31: ='ГС пил МСГРП'!$V31*AA$13 -> 0 | AB31: ='ГС пил МСГРП'!$W31*AA$13 -> 0 | AC31: ='ГСЮра пил'!$V31*AC$13 -> 0 | AD31: ='ГСЮра пил'!$W31*AC$13 -> 0 | AE31: ='ГСЮра без пил'!$V31*AE$13 -> 0 | AF31: ='ГСЮра без пил'!$W31*AE$13 -> 0 | AG31: ='ГСЮра пил МСГРП'!$V31*AG$13 -> 0 | AH31: ='ГСЮра пил МСГРП'!$W31*AG$13 -> 0 | AI31: =ВЗ!$V31*AI$13 -> 0 | AJ31: =ВЗ!$W31*AI$13 -> 0 | AK31: ='Посл. скв'!$V31*AK$13 -> 1 | AL31: ='Посл. скв'!$W31*AK$13 -> 406328 | AM31: =AK31+AI31+AG31+AE31+AC31+AA31+Y31+W31++U31+S31+Q31+M31+O31+K31+I31+G31 -> 1 | AN31: =AL31+AJ31+AH31+AF31+AD31+AB31+Z31+X31++V31+T31+R31+N31+P31+L31+J31+H31 -> 406328 | AO31: =('[8]Куст №40А'!AD2009)*1000 -> 813354 | AP31: =AO31-AN31 -> 407026 | AR31: =AS31-AN31 -> 0 | AS31: 406328
... D40: ='Перв. скв '!D40 -> Завоз и монтаж новой насосной группы | E40: ='Перв. скв '!E40 -> не определен | F40: ='Перв. скв '!F40 -> опер. | G40: ='Перв. скв '!$V40*G$13 -> 0 | H40: ='Перв. скв '!$W40*G$13 -> 0 | I40: =ННСдо1300!$V40*I$13 -> 0 | J40: =ННСдо1300!$W40*I$13 -> 0 | K40: =ННСот1300до1500!$V40*K$13 -> 0 | L40: =ННСот1300до1500!$W40*K$13 -> 0 | M40: =ННСот1500до2000!$V40*M$13 -> 0 | N40: =ННСот1500до2000!$W40*M$13 -> 0 | O40: =ННСот2000до2200!$V40*O$13 -> 0 | P40: =ННСот2000до2200!$W40*O$13 -> 0 | Q40: =ННСболее2200!$V40*Q$13 -> 0 | R40: =ННСболее2200!$W40*Q$13 -> 0 | S40: =Оценочная!$V40*S$13 -> 0 | T40: =Оценочная!$W40*S$13 -> 0 | U40: ='ННСЮра>800'!$V40*U$13 -> 0 | V40: ='ННСЮра>800'!$W40*U$13 -> 0 | W40: ='ГС пил'!V40*$W$13 -> 0 | X40: ='ГС пил'!W40*$W$13 -> 0 | Y40: ='ГС без пил'!$V40*Y$13 -> 0 | Z40: ='ГС без пил'!$W40*Y$13 -> 0 | AA40: ='ГС пил МСГРП'!$V40*AA$13 -> 0 | AB40: ='ГС пил МСГРП'!$W40*AA$13 -> 0 | AC40: ='ГСЮра пил'!$V40*AC$13 -> 0 | AD40: ='ГСЮра пил'!$W40*AC$13 -> 0 | AE40: ='ГСЮра без пил'!$V40*AE$13 -> 0 | AF40: ='ГСЮра без пил'!$W40*AE$13 -> 0 | AG40: ='ГСЮра пил МСГРП'!$V40*AG$13 -> 0 | AH40: ='ГСЮра пил МСГРП'!$W40*AG$13 -> 0 | AI40: =ВЗ!$V40*AI$13 -> 0 | AJ40: =ВЗ!$W40*AI$13 -> 0 | AK40: ='Посл. скв'!$V40*AK$13 -> 0 | AL40: ='Посл. скв'!$W40*AK$13 -> 0 | AM40: =AK40+AI40+AG40+AE40+AC40+AA40+Y40+W40++U40+S40+Q40+M40+O40+K40+I40+G40 -> 0 | AN40: =AL40+AJ40+AH40+AF40+AD40+AB40+Z40+X40++V40+T40+R40+N40+P40+L40+J40+H40 -> 0 | AO40: =('[8]Куст №40А'!AD2018)*1000 -> 0 | AP40: =AO40-AN40 -> 0 | AR40: =AS40-AN40 -> 0 | AS40: 0
C41: ОБЩАЯ СТОИМОСТЬ ВМР | H41: =SUM(H20:H40) -> 25714124 | J41: =SUM(J20:J40) -> 0 | L41: =SUM(L20:L40) -> 0 | N41: =SUM(N20:N40) -> 0 | P41: =SUM(P20:P40) -> 0 | R41: =SUM(R20:R40) -> 0 | T41: =SUM(T20:T40) -> 0 | V41: =SUM(V20:V40) -> 0 | X41: =SUM(X20:X40) -> 0 | Z41: =SUM(Z20:Z40) -> 1592190 | AB41: =SUM(AB20:AB40) -> 0 | AD41: =SUM(AD20:AD40) -> 0 | AF41: =SUM(AF20:AF40) -> 0 | AH41: =SUM(AH20:AH40) -> 0 | AJ41: =SUM(AJ20:AJ40) -> 0 | AL41: =SUM(AL20:AL40) -> 6618548 | AN41: =SUM(AN20:AN40) -> 33924862 | AR41: =AS41-AN41 -> -17824982 | AS41: 16099880
AN42: 0 | AR42: =AS42-AN42 -> 0 | AS42: 0
C43: 2. ЭТАП БУРЕНИЯ: | AR43: =AS43-AN43 -> 0
C44: ='Перв. скв '!C44 -> не определен | D44: Описание работ/услуг | AN44: 0 | AR44: =AS44-AN44 -> 0 | AS44: 0
C45: (технико-технологичексие особенности) | D45: ='Перв. скв '!D45 -> Фиксированная ставка за скважину с отходом до 1300 м. | E45: ='Перв. скв '!E45 -> не определен | F45: ='Перв. скв '!F45 -> скв. | G45: ='Перв. скв '!$V45*G$13 -> 0 | H45: ='Перв. скв '!$W45*G$13 -> 0 | I45: =ННСдо1300!$V45*I$13 -> 0 | J45: =ННСдо1300!$W45*I$13 -> 0 | K45: =ННСот1300до1500!$V45*K$13 -> 0 | L45: =ННСот1300до1500!$W45*K$13 -> 0 | M45: =ННСот1500до2000!$V45*M$13 -> 0 | N45: =ННСот1500до2000!$W45*M$13 -> 0 | O45: =ННСот2000до2200!$V45*O$13 -> 0 | P45: =ННСот2000до2200!$W45*O$13 -> 0 | Q45: =ННСболее2200!$V45*Q$13 -> 0 | R45: =ННСболее2200!$W45*Q$13 -> 0 | S45: =Оценочная!$V45*S$13 -> 0 | T45: =Оценочная!$W45*S$13 -> 0 | U45: ='ННСЮра>800'!$V45*U$13 -> 0 | V45: ='ННСЮра>800'!$W45*U$13 -> 0 | W45: ='ГС пил'!V45*$W$13 -> 0 | X45: ='ГС пил'!W45*$W$13 -> 0 | Y45: ='ГС без пил'!$V45*Y$13 -> 0 | Z45: ='ГС без пил'!$W45*Y$13 -> 0 | AA45: ='ГС пил МСГРП'!$V45*AA$13 -> 0 | AB45: ='ГС пил МСГРП'!$W45*AA$13 -> 0 | AC45: ='ГСЮра пил'!$V45*AC$13 -> 0 | AD45: ='ГСЮра пил'!$W45*AC$13 -> 0 | AE45: ='ГСЮра без пил'!$V45*AE$13 -> 0 | AF45: ='ГСЮра без пил'!$W45*AE$13 -> 0 | AG45: ='ГСЮра пил МСГРП'!$V45*AG$13 -> 0 | AH45: ='ГСЮра пил МСГРП'!$W45*AG$13 -> 0 | AI45: =ВЗ!$V45*AI$13 -> 0 | AJ45: =ВЗ!$W45*AI$13 -> 0 | AK45: ='Посл. скв'!$V45*AK$13 -> 0 | AL45: ='Посл. скв'!$W45*AK$13 -> 0 | AM45: =AK45+AI45+AG45+AE45+AC45+AA45+Y45+W45++U45+S45+Q45+M45+O45+K45+I45+G45 -> 0 | AN45: =AL45+AJ45+AH45+AF45+AD45+AB45+Z45+X45++V45+T45+R45+N45+P45+L45+J45+H45 -> 0 | AO45: =('[8]Куст №40А'!$AD$170)*1000 -> 33813075 | AP45: =AO45-AN45 -> 33813075 | AR45: =AS45-AN45 -> 0 | AS45: 0
D46: ='Перв. скв '!D46 -> Фиксированная ставка за скважину с отходом от 1300 до 1500 м. | E46: ='Перв. скв '!E46 -> не определен | F46: ='Перв. скв '!F46 -> скв. | G46: ='Перв. скв '!$V46*G$13 -> 0 | H46: ='Перв. скв '!$W46*G$13 -> 0 | I46: =ННСдо1300!$V46*I$13 -> 0 | J46: =ННСдо1300!$W46*I$13 -> 0 | K46: =ННСот1300до1500!$V46*K$13 -> 0 | L46: =ННСот1300до1500!$W46*K$13 -> 0 | M46: =ННСот1500до2000!$V46*M$13 -> 0 | N46: =ННСот1500до2000!$W46*M$13 -> 0 | O46: =ННСот2000до2200!$V46*O$13 -> 0 | P46: =ННСот2000до2200!$W46*O$13 -> 0 | Q46: =ННСболее2200!$V46*Q$13 -> 0 | R46: =ННСболее2200!$W46*Q$13 -> 0 | S46: =Оценочная!$V46*S$13 -> 0 | T46: =Оценочная!$W46*S$13 -> 0 | U46: ='ННСЮра>800'!$V46*U$13 -> 0 | V46: ='ННСЮра>800'!$W46*U$13 -> 0 | W46: ='ГС пил'!V46*$W$13 -> 0 | X46: ='ГС пил'!W46*$W$13 -> 0 | Y46: ='ГС без пил'!$V46*Y$13 -> 0 | Z46: ='ГС без пил'!$W46*Y$13 -> 0 | AA46: ='ГС пил МСГРП'!$V46*AA$13 -> 0 | AB46: ='ГС пил МСГРП'!$W46*AA$13 -> 0 | AC46: ='ГСЮра пил'!$V46*AC$13 -> 0 | AD46: ='ГСЮра пил'!$W46*AC$13 -> 0 | AE46: ='ГСЮра без пил'!$V46*AE$13 -> 0 | AF46: ='ГСЮра без пил'!$W46*AE$13 -> 0 | AG46: ='ГСЮра пил МСГРП'!$V46*AG$13 -> 0 | AH46: ='ГСЮра пил МСГРП'!$W46*AG$13 -> 0 | AI46: =ВЗ!$V46*AI$13 -> 0 | AJ46: =ВЗ!$W46*AI$13 -> 0 | AK46: ='Посл. скв'!$V46*AK$13 -> 0 | AL46: ='Посл. скв'!$W46*AK$13 -> 0 | AM46: =AK46+AI46+AG46+AE46+AC46+AA46+Y46+W46++U46+S46+Q46+M46+O46+K46+I46+G46 -> 0 | AN46: =AL46+AJ46+AH46+AF46+AD46+AB46+Z46+X46++V46+T46+R46+N46+P46+L46+J46+H46 -> 0 | AO46: =('[8]Куст №40А'!$AD$445)*1000 -> 16666394 | AP46: =AO46-AN46 -> 16666394 | AR46: =AS46-AN46 -> 0 | AS46: 0
D47: ='Перв. скв '!D47 -> Фиксированная ставка за скважину с отходом от 1500 до 2000 м. | E47: ='Перв. скв '!E47 -> не определен | F47: ='Перв. скв '!F47 -> скв. | G47: ='Перв. скв '!$V47*G$13 -> 0 | H47: ='Перв. скв '!$W47*G$13 -> 0 | I47: =ННСдо1300!$V47*I$13 -> 0 | J47: =ННСдо1300!$W47*I$13 -> 0 | K47: =ННСот1300до1500!$V47*K$13 -> 0 | L47: =ННСот1300до1500!$W47*K$13 -> 0 | M47: =ННСот1500до2000!$V47*M$13 -> 0 | N47: =ННСот1500до2000!$W47*M$13 -> 0 | O47: =ННСот2000до2200!$V47*O$13 -> 0 | P47: =ННСот2000до2200!$W47*O$13 -> 0 | Q47: =ННСболее2200!$V47*Q$13 -> 0 | R47: =ННСболее2200!$W47*Q$13 -> 0 | S47: =Оценочная!$V47*S$13 -> 0 | T47: =Оценочная!$W47*S$13 -> 0 | U47: ='ННСЮра>800'!$V47*U$13 -> 0 | V47: ='ННСЮра>800'!$W47*U$13 -> 0 | W47: ='ГС пил'!V47*$W$13 -> 0 | X47: ='ГС пил'!W47*$W$13 -> 0 | Y47: ='ГС без пил'!$V47*Y$13 -> 0 | Z47: ='ГС без пил'!$W47*Y$13 -> 0 | AA47: ='ГС пил МСГРП'!$V47*AA$13 -> 0 | AB47: ='ГС пил МСГРП'!$W47*AA$13 -> 0 | AC47: ='ГСЮра пил'!$V47*AC$13 -> 0 | AD47: ='ГСЮра пил'!$W47*AC$13 -> 0 | AE47: ='ГСЮра без пил'!$V47*AE$13 -> 0 | AF47: ='ГСЮра без пил'!$W47*AE$13 -> 0 | AG47: ='ГСЮра пил МСГРП'!$V47*AG$13 -> 0 | AH47: ='ГСЮра пил МСГРП'!$W47*AG$13 -> 0 | AI47: =ВЗ!$V47*AI$13 -> 0 | AJ47: =ВЗ!$W47*AI$13 -> 0 | AK47: ='Посл. скв'!$V47*AK$13 -> 0 | AL47: ='Посл. скв'!$W47*AK$13 -> 0 | AM47: =AK47+AI47+AG47+AE47+AC47+AA47+Y47+W47++U47+S47+Q47+M47+O47+K47+I47+G47 -> 0 | AN47: =AL47+AJ47+AH47+AF47+AD47+AB47+Z47+X47++V47+T47+R47+N47+P47+L47+J47+H47 -> 0 | AO47: =('[8]Куст №40А'!$AD$720)*1000 -> 0 | AP47: =AO47-AN47 -> 0 | AR47: =AS47-AN47 -> 0 | AS47: 0
D48: ='Перв. скв '!D48 -> Фиксированная ставка за скважину с отходом от 2000 до 2200 м. | E48: ='Перв. скв '!E48 -> не определен | F48: ='Перв. скв '!F48 -> скв. | G48: ='Перв. скв '!$V48*G$13 -> 0 | H48: ='Перв. скв '!$W48*G$13 -> 0 | I48: =ННСдо1300!$V48*I$13 -> 0 | J48: =ННСдо1300!$W48*I$13 -> 0 | K48: =ННСот1300до1500!$V48*K$13 -> 0 | L48: =ННСот1300до1500!$W48*K$13 -> 0 | M48: =ННСот1500до2000!$V48*M$13 -> 0 | N48: =ННСот1500до2000!$W48*M$13 -> 0 | O48: =ННСот2000до2200!$V48*O$13 -> 0 | P48: =ННСот2000до2200!$W48*O$13 -> 0 | Q48: =ННСболее2200!$V48*Q$13 -> 0 | R48: =ННСболее2200!$W48*Q$13 -> 0 | S48: =Оценочная!$V48*S$13 -> 0 | T48: =Оценочная!$W48*S$13 -> 0 | U48: ='ННСЮра>800'!$V48*U$13 -> 0 | V48: ='ННСЮра>800'!$W48*U$13 -> 0 | W48: ='ГС пил'!V48*$W$13 -> 0 | X48: ='ГС пил'!W48*$W$13 -> 0 | Y48: ='ГС без пил'!$V48*Y$13 -> 0 | Z48: ='ГС без пил'!$W48*Y$13 -> 0 | AA48: ='ГС пил МСГРП'!$V48*AA$13 -> 0 | AB48: ='ГС пил МСГРП'!$W48*AA$13 -> 0 | AC48: ='ГСЮра пил'!$V48*AC$13 -> 0 | AD48: ='ГСЮра пил'!$W48*AC$13 -> 0 | AE48: ='ГСЮра без пил'!$V48*AE$13 -> 0 | AF48: ='ГСЮра без пил'!$W48*AE$13 -> 0 | AG48: ='ГСЮра пил МСГРП'!$V48*AG$13 -> 0 | AH48: ='ГСЮра пил МСГРП'!$W48*AG$13 -> 0 | AI48: =ВЗ!$V48*AI$13 -> 0 | AJ48: =ВЗ!$W48*AI$13 -> 0 | AK48: ='Посл. скв'!$V48*AK$13 -> 0 | AL48: ='Посл. скв'!$W48*AK$13 -> 0 | AM48: =AK48+AI48+AG48+AE48+AC48+AA48+Y48+W48++U48+S48+Q48+M48+O48+K48+I48+G48 -> 0 | AN48: =AL48+AJ48+AH48+AF48+AD48+AB48+Z48+X48++V48+T48+R48+N48+P48+L48+J48+H48 -> 0 | AO48: =('[8]Куст №40А'!$AD$994)*1000 -> 0 | AP48: =AO48-AN48 -> 0 | AR48: =AS48-AN48 -> 0 | AS48: 0
D49: ='Перв. скв '!D49 -> Фиксированная ставка за скважину с отходом более 2200 м. | E49: ='Перв. скв '!E49 -> не определен | F49: ='Перв. скв '!F49 -> скв. | G49: ='Перв. скв '!$V49*G$13 -> 0 | H49: ='Перв. скв '!$W49*G$13 -> 0 | I49: =ННСдо1300!$V49*I$13 -> 0 | J49: =ННСдо1300!$W49*I$13 -> 0 | K49: =ННСот1300до1500!$V49*K$13 -> 0 | L49: =ННСот1300до1500!$W49*K$13 -> 0 | M49: =ННСот1500до2000!$V49*M$13 -> 0 | N49: =ННСот1500до2000!$W49*M$13 -> 0 | O49: =ННСот2000до2200!$V49*O$13 -> 0 | P49: =ННСот2000до2200!$W49*O$13 -> 0 | Q49: =ННСболее2200!$V49*Q$13 -> 0 | R49: =ННСболее2200!$W49*Q$13 -> 0 | S49: =Оценочная!$V49*S$13 -> 0 | T49: =Оценочная!$W49*S$13 -> 0 | U49: ='ННСЮра>800'!$V49*U$13 -> 0 | V49: ='ННСЮра>800'!$W49*U$13 -> 0 | W49: ='ГС пил'!V49*$W$13 -> 0 | X49: ='ГС пил'!W49*$W$13 -> 0 | Y49: ='ГС без пил'!$V49*Y$13 -> 0 | Z49: ='ГС без пил'!$W49*Y$13 -> 0 | AA49: ='ГС пил МСГРП'!$V49*AA$13 -> 0 | AB49: ='ГС пил МСГРП'!$W49*AA$13 -> 0 | AC49: ='ГСЮра пил'!$V49*AC$13 -> 0 | AD49: ='ГСЮра пил'!$W49*AC$13 -> 0 | AE49: ='ГСЮра без пил'!$V49*AE$13 -> 0 | AF49: ='ГСЮра без пил'!$W49*AE$13 -> 0 | AG49: ='ГСЮра пил МСГРП'!$V49*AG$13 -> 0 | AH49: ='ГСЮра пил МСГРП'!$W49*AG$13 -> 0 | AI49: =ВЗ!$V49*AI$13 -> 0 | AJ49: =ВЗ!$W49*AI$13 -> 0 | AK49: ='Посл. скв'!$V49*AK$13 -> 0 | AL49: ='Посл. скв'!$W49*AK$13 -> 0 | AM49: =AK49+AI49+AG49+AE49+AC49+AA49+Y49+W49++U49+S49+Q49+M49+O49+K49+I49+G49 -> 0 | AN49: =AL49+AJ49+AH49+AF49+AD49+AB49+Z49+X49++V49+T49+R49+N49+P49+L49+J49+H49 -> 0 | AO49: =('[8]Куст №40А'!$AD$1268)*1000 -> 0 | AP49: =AO49-AN49 -> 0 | AR49: =AS49-AN49 -> 0 | AS49: 0
D50: ='Перв. скв '!D50 -> Расчет объема капитальных вложений по ГС | E50: ='Перв. скв '!E50 -> не определен | F50: ='Перв. скв '!F50 -> сут. | G50: ='Перв. скв '!$V50*G$13 -> 1 | H50: ='Перв. скв '!$W50*G$13 -> 31646673 | I50: =ННСдо1300!$V50*I$13 -> 0 | J50: =ННСдо1300!$W50*I$13 -> 0 | K50: =ННСот1300до1500!$V50*K$13 -> 0 | L50: =ННСот1300до1500!$W50*K$13 -> 0 | M50: =ННСот1500до2000!$V50*M$13 -> 0 | N50: =ННСот1500до2000!$W50*M$13 -> 0 | O50: =ННСот2000до2200!$V50*O$13 -> 0 | P50: =ННСот2000до2200!$W50*O$13 -> 0 | Q50: =ННСболее2200!$V50*Q$13 -> 0 | R50: =ННСболее2200!$W50*Q$13 -> 0 | S50: =Оценочная!$V50*S$13 -> 0 | T50: =Оценочная!$W50*S$13 -> 0 | U50: ='ННСЮра>800'!$V50*U$13 -> 0 | V50: ='ННСЮра>800'!$W50*U$13 -> 0 | W50: ='ГС пил'!V50*$W$13 -> 0 | X50: ='ГС пил'!W50*$W$13 -> 0 | Y50: ='ГС без пил'!$V50*Y$13 -> 6 | Z50: ='ГС без пил'!$W50*Y$13 -> 168266778 | AA50: ='ГС пил МСГРП'!$V50*AA$13 -> 0 | AB50: ='ГС пил МСГРП'!$W50*AA$13 -> 0 | AC50: ='ГСЮра пил'!$V50*AC$13 -> 0 | AD50: ='ГСЮра пил'!$W50*AC$13 -> 0 | AE50: ='ГСЮра без пил'!$V50*AE$13 -> 0 | AF50: ='ГСЮра без пил'!$W50*AE$13 -> 0 | AG50: ='ГСЮра пил МСГРП'!$V50*AG$13 -> 0 | AH50: ='ГСЮра пил МСГРП'!$W50*AG$13 -> 0 | AI50: =ВЗ!$V50*AI$13 -> 0 | AJ50: =ВЗ!$W50*AI$13 -> 0 | AK50: ='Посл. скв'!$V50*AK$13 -> 1 | AL50: ='Посл. скв'!$W50*AK$13 -> 31646673 | AM50: =AK50+AI50+AG50+AE50+AC50+AA50+Y50+W50++U50+S50+Q50+M50+O50+K50+I50+G50 -> 8 | AN50: =AL50+AJ50+AH50+AF50+AD50+AB50+Z50+X50++V50+T50+R50+N50+P50+L50+J50+H50 -> 2.3156012e+08 | AO50: =('[8]Куст №40А'!$AD$1542)*1000 -> 0 | AP50: =AO50-AN50 -> -2.3156012e+08 | AR50: =AS50-AN50 -> 0 | AS50: 2.3156012e+08
D51: ='Перв. скв '!D51 -> Переработка бурового шлама | E51: ='Перв. скв '!E51 -> не определен | F51: ='Перв. скв '!F51 -> скв. | G51: ='Перв. скв '!$V51*G$13 -> 810.39 | H51: ='Перв. скв '!$W51*G$13 -> 2325008.9 | I51: =ННСдо1300!$V51*I$13 -> 0 | J51: =ННСдо1300!$W51*I$13 -> 0 | K51: =ННСот1300до1500!$V51*K$13 -> 0 | L51: =ННСот1300до1500!$W51*K$13 -> 0 | M51: =ННСот1500до2000!$V51*M$13 -> 0 | N51: =ННСот1500до2000!$W51*M$13 -> 0 | O51: =ННСот2000до2200!$V51*O$13 -> 0 | P51: =ННСот2000до2200!$W51*O$13 -> 0 | Q51: =ННСболее2200!$V51*Q$13 -> 0 | R51: =ННСболее2200!$W51*Q$13 -> 0 | S51: =Оценочная!$V51*S$13 -> 0 | T51: =Оценочная!$W51*S$13 -> 0 | U51: ='ННСЮра>800'!$V51*U$13 -> 0 | V51: ='ННСЮра>800'!$W51*U$13 -> 0 | W51: ='ГС пил'!V51*$W$13 -> 0 | X51: ='ГС пил'!W51*$W$13 -> 0 | Y51: ='ГС без пил'!$V51*Y$13 -> 4157.64 | Z51: ='ГС без пил'!$W51*Y$13 -> 11928269 | AA51: ='ГС пил МСГРП'!$V51*AA$13 -> 0 | AB51: ='ГС пил МСГРП'!$W51*AA$13 -> 0 | AC51: ='ГСЮра пил'!$V51*AC$13 -> 0 | AD51: ='ГСЮра пил'!$W51*AC$13 -> 0 | AE51: ='ГСЮра без пил'!$V51*AE$13 -> 0 | AF51: ='ГСЮра без пил'!$W51*AE$13 -> 0 | AG51: ='ГСЮра пил МСГРП'!$V51*AG$13 -> 0 | AH51: ='ГСЮра пил МСГРП'!$W51*AG$13 -> 0 | AI51: =ВЗ!$V51*AI$13 -> 0 | AJ51: =ВЗ!$W51*AI$13 -> 0 | AK51: ='Посл. скв'!$V51*AK$13 -> 810.39 | AL51: ='Посл. скв'!$W51*AK$13 -> 2325008.9 | AM51: =AK51+AI51+AG51+AE51+AC51+AA51+Y51+W51++U51+S51+Q51+M51+O51+K51+I51+G51 -> 5778.42 | AN51: =AL51+AJ51+AH51+AF51+AD51+AB51+Z51+X51++V51+T51+R51+N51+P51+L51+J51+H51 -> 16578287 | AO51: =('[8]Куст №40А'!$AD$1818)*1000 -> 10206000 | AP51: =AO51-AN51 -> -6372287 | AR51: =AS51-AN51 -> 0 | AS51: 16578287
...

Sheet Перв. скв 
A2: ПОДРОБНАЯ СМЕТНАЯ СТОИМОСТЬ СКВАЖИНЫ
C4: Месторождение/ куст: | D4: Приобского_ месторождения | E4: ВСЕГО СТ-ТЬ | F4: Исходные данные | H4: Перед забуркой | I4: Направление | J4: Кондуктор | K4: Техническая колонна | L4: Эксплуат-ая колонна | M4: Крепление колонн | N4: Хвостовик | O4: ВСЕГО БУРЕНИЕ | P4: Исходные данные | R4: ВСЕГО ОСВОЕНИЕ
C5: Подрядчик по бурению: | D5: не определен | E5: =IF(($L$45+$L$46+$L$47+$L$48+$L$49+$L$50)>0,$D$214,0) -> 1.3238393e+08
C6: Тип буровой установки: | D6: БУ-3000 ЭУК | E6: Всего ВМР | F6: Время бурения секции, сут: | I6: 1 | J6: 4 | L6: 21 | M6: 3 | N6: 16 | O6: =SUM(I6:N6) -> 45 | P6: Время освоения, сут: | R6: =R8+R9+R10 -> 19
C7: Тип скважины: | D7: Горизонт | E7: =IF(($L$45+$L$46+$L$47+$L$48+$L$49+$L$50)>0,$W$41,0) -> 25714124 | F7: Глубина (по стволу), м: | I7: 120 | J7: 1250 | L7: 3200 | N7: 4100 | O7: ВСЕГО ПРОХОДКА | P7: В т.ч.время работы бригад КРС
C8: Проходка всего (м): | D8: 5500 | E8: Всего Бурение | F8: Диаметр долота, мм: | I8: 393 | J8: 300 | L8: 220 | N8: 155.6 | P8: - ПЗР к ГРП/МСГРП, сут. | R8: 11
C9: Наличие СВП: | D9: да | E9: =IF(($L$45+$L$46+$L$47+$L$48+$L$49+$L$50)>0,$W$190,0) -> 69765317 | F9: Диаметр колонны, мм: | I9: 324 | J9: 245 | L9: 178 | N9: 114 | O9: =D8 -> 5500 | P9: - проведение ГРП/МСГРП, сут. | R9: 1
C10: Наличие АИЭС: | D10: нет | E10: Всего Освоение | F10: Исходные данные | H10: Отход | I10: Пилот ГС | J10: Перебур | K10: Гориз.уч. 1 | L10: Гориз.уч. 2 | M10: Керн | O10: ГЛУБИНА ПО ВЕРТ-ЛИ | P10: - проведение ГНКТ, сут. | R10: 7
C11: Наличие автономности: | D11: нет | E11: =IF(($L$45+$L$46+$L$47+$L$48+$L$49+$L$50)>0,$W$206,0) -> 36904487 | F11: Отдельные стволы, керн, м: | P11: - кол-во стадий МСГРП, шт. | R11: 6
C12: Кол-во обсадных колонн (включая направл.): | D12: 4 | E12: Обор-ие устья | F12: Примечание: | P12: Примечание:
C13: Прочие существенные условия: | E13: =IF(($L$45+$L$46+$L$47+$L$48+$L$49+$L$50)>0,$W$212,0) -> 0
A15: ОПИСАНИЕ РАБОТ И УСЛУГ | H15: КОЛИЧЕСТВО | O15: СТОИМОСТЬ | V15: ВСЕГО
A16: КОД | B16: добавочный код | C16: СТАТЬЯ ЗАТРАТ | D16: ОПИСАНИЕ | E16: Подрядчик | F16: Единица измерения | G16: Руб. / Ед.изм. | H16: ПЗР (в т.ч. ВМР и осв.) | I16: =+I4 -> Направление | J16: =+J4 -> Кондуктор | K16: =+K4 -> Техническая колонна | L16: =+L4 -> Эксплуат-ая колонна | M16: Крепление колонн | N16: =+N4 -> Хвостовик | O16: ПЗР (в т.ч. ВМР и осв.) | P16: =+I16 -> Направление | Q16: =+J16 -> Кондуктор | R16: =+K16 -> Техническая колонна | S16: =+L16 -> Эксплуат-ая колонна | T16: Крепление колонн | U16: =+N16 -> Хвостовик | V16: Количество | W16: Стоимость (руб) | X16: ВСЕГО СТОИМОСТЬ
C18: 1. ЭТАП ВМР | X18: =SUM(W20:W40) -> 25714124
C19: =D5 -> не определен | D19: Описание работ/услуг
D20: Монтаж | E20: =D$5 -> не определен | F20: опер. | G20: 9401938 | H20: 1 | O20: =H20*G20 -> 9401938 | V20: =SUM(H20:N20) -> 1 | W20: =SUM(O20:U20) -> 9401938
D21: Демонтаж | E21: =D$5 -> не определен | F21: опер. | G21: 2344149 | O21: =H21*G21 -> 0 | V21: =SUM(H21:N21) -> 0 | W21: =SUM(O21:U21) -> 0
D22: Эксплуатация АВЭС | E22: =D$5 -> не определен | F22: опер. | G22: 0 | O22: =H22*G22 -> 0 | V22: =SUM(H22:N22) -> 0 | W22: =SUM(O22:U22) -> 0
D23: Передислокация БУ в пределах м-я | E23: =D$5 -> не определен | F23: опер. | G23: 693236 | O23: =H23*G23 -> 0 | V23: =SUM(H23:N23) -> 0 | W23: =SUM(O23:U23) -> 0
D24: Передислокация БУ 250-500 км. | E24: =D$5 -> не определен | F24: опер. | G24: 9837322 | H24: 1 | O24: =H24*G24 -> 9837322 | V24: =SUM(H24:N24) -> 1 | W24: =SUM(O24:U24) -> 9837322
D25: Передислокация бр. бур в пределах м-я | E25: =D$5 -> не определен | F25: опер. | G25: 130867 | O25: =H25*G25 -> 0 | V25: =SUM(H25:N25) -> 0 | W25: =SUM(O25:U25) -> 0
D26: Передислокация бр. бур 250-500 км. | E26: =D$5 -> не определен | F26: опер. | G26: 1788526 | H26: 1 | O26: =H26*G26 -> 1788526 | V26: =SUM(H26:N26) -> 1 | W26: =SUM(O26:U26) -> 1788526
D27: Передислокация бригады ВМР в пределах м-я | E27: =D$5 -> не определен | F27: опер. | G27: 130867 | O27: =H27*G27 -> 0 | V27: =SUM(H27:N27) -> 0 | W27: =SUM(O27:U27) -> 0
D28: Передислокация бригады ВМР 250-500 км. | E28: =D$5 -> не определен | F28: опер. | G28: 1788526 | H28: 2 | O28: =H28*G28 -> 3577052 | V28: =SUM(H28:N28) -> 2 | W28: =SUM(O28:U28) -> 3577052
D29: Передвижка 5 м. | E29: =D$5 -> не определен | F29: опер. | G29: 244497 | O29: =H29*G29 -> 0 | V29: =SUM(H29:N29) -> 0 | W29: =SUM(O29:U29) -> 0
D30: Передвижка 9 м. | E30: =D$5 -> не определен | F30: опер. | G30: 265365 | O30: =H30*G30 -> 0 | V30: =SUM(H30:N30) -> 0 | W30: =SUM(O30:U30) -> 0
D31: Передвижка 18 м. | E31: =D$5 -> не определен | F31: опер. | G31: 406328 | O31: =H31*G31 -> 0 | V31: =SUM(H31:N31) -> 0 | W31: =SUM(O31:U31) -> 0
D32: Передвижка 25 м. | E32: =D$5 -> не определен | F32: опер. | G32: 462462 | O32: =H32*G32 -> 0 | V32: =SUM(H32:N32) -> 0 | W32: =SUM(O32:U32) -> 0
D33: Передвижка 50 м. | E33: =D$5 -> не определен | F33: опер. | G33: 889289 | O33: =H33*G33 -> 0 | V33: =SUM(H33:N33) -> 0 | W33: =SUM(O33:U33) -> 0
D34: Сдвижка 25 м. | E34: =D$5 -> не определен | F34: опер. | G34: 291019 | O34: =H34*G34 -> 0 | V34: =SUM(H34:N34) -> 0 | W34: =SUM(O34:U34) -> 0
D35: Пуско-наладочные работы | E35: =D$5 -> не определен | F35: опер. | G35: 633406 | H35: 1 | O35: =H35*G35 -> 633406 | V35: =SUM(H35:N35) -> 1 | W35: =SUM(O35:U35) -> 633406
D36: Артезианская скважина | E36: =D$5 -> не определен | F36: опер. | G36: 475880 | H36: 1 | O36: =H36*G36 -> 475880 | V36: =SUM(H36:N36) -> 1 | W36: =SUM(O36:U36) -> 475880
D37: Авиапревозки | E37: =D$5 -> не определен | F37: опер. | G37: 205937.12 | O37: =H37*G37 -> 0 | V37: =SUM(H37:N37) -> 0 | W37: =SUM(O37:U37) -> 0
D38: Мобилизация и монтаж энергокомплекса | E38: =D$5 -> не определен | F38: опер. | G38: 0 | O38: =H38*G38 -> 0 | V38: =SUM(H38:N38) -> 0 | W38: =SUM(O38:U38) -> 0
D39: Завоз и монтаж верхнего силового привода | E39: =D$5 -> не определен | F39: опер. | G39: ='[9]Исходные данные'!$O$3110*1000 -> 2078246 | O39: =H39*G39 -> 0 | V39: =SUM(H39:N39) -> 0 | W39: =SUM(O39:U39) -> 0
D40: Завоз и монтаж новой насосной группы | E40: =D$5 -> не определен | F40: опер. | G40: ='[9]Исходные данные'!$N$3111*1000 -> 899742 | O40: =H40*G40 -> 0 | V40: =SUM(H40:N40) -> 0 | W40: =SUM(O40:U40) -> 0
C41: ОБЩАЯ СТОИМОСТЬ ВМР | D41: =W41 -> 25714124 | O41: =SUM(O20:O40) -> 25714124 | W41: =SUM(W20:W40) -> 25714124
C43: 2. ЭТАП БУРЕНИЯ: | X43: =SUM(W45:W55) -> 39031838
C44: =D5 -> не определен | D44: Описание работ/услуг
C45: (технико-технологичексие особенности) | D45: Фиксированная ставка за скважину с отходом до 1300 м. | E45: =D$5 -> не определен | F45: скв. | G45: 6559232 | O45: =H45*G45 -> 0 | P45: =I45*G45 -> 0 | Q45: =J45*G45 -> 0 | R45: =K45*G45 -> 0 | S45: =L45*G45 -> 0 | T45: =M45*G45 -> 0 | U45: =N45*G45 -> 0 | V45: =SUM(H45:N45) -> 0 | W45: =SUM(O45:U45) -> 0
...

Sheet ННСдо1300
A2: ПОДРОБНАЯ СМЕТНАЯ СТОИМОСТЬ СКВАЖИНЫ
C4: Месторождение/ куст: | D4: ='Титул '!G5 -> куст №21б Приобского месторождения | E4: ВСЕГО СТ-ТЬ | F4: Исходные данные | H4: Перед забуркой | I4: Направление | J4: Кондуктор | K4: Техническая колонна | L4: Эксплуат-ая колонна | M4: Крепление колонн | N4: Хвостовик | O4: ВСЕГО БУРЕНИЕ | P4: Исходные данные | R4: ВСЕГО ОСВОЕНИЕ
C5: Подрядчик по бурению: | D5: ='Титул '!C11 -> не определен | E5: =IF(($L$45+$L$46+$L$47+$L$48+$L$49+$L$50)>0,$D$214,0) -> 1.0621282e+08
C6: Тип буровой установки: | D6: ='Титул '!C12 -> БУ-3000 ЭУК | E6: Всего ВМР | F6: Время бурения секции, сут: | I6: 1 | J6: 2.5 | L6: 5.5 | M6: 3 | N6: 0 | O6: =IF(($L$45+$L$46+$L$47+$L$48+$L$49+$L$50)>0,SUM(I6:N6),0) -> 12 | P6: Время освоения, сут: | R6: =IF(($L$45+$L$46+$L$47+$L$48+$L$49+$L$50)>0,SUM(R8:R10),0) -> 17
C7: Тип скважины: | D7: Наклонно-направленная | E7: =IF(($L$45+$L$46+$L$47+$L$48+$L$49+$L$50)>0,$W$41,0) -> 471302.12 | F7: Глубина (по стволу), м: | I7: 120 | J7: 1280 | L7: 3000 | O7: ВСЕГО ПРОХОДКА | P7: В т.ч.время работы бригад КРС
C8: Проходка всего (м): | D8: 3000 | E8: Всего Бурение | F8: Диаметр долота, мм: | I8: 393 | J8: 300 | L8: 220 | P8: - ПЗР к ГРП/МСГРП, сут. | R8: 13
C9: Наличие СВП: | D9: ='Титул '!C13 -> да | E9: =IF(($L$45+$L$46+$L$47+$L$48+$L$49+$L$50)>0,$W$190,0) -> 68837029 | F9: Диаметр колонны, мм: | I9: 324 | J9: 245 | L9: 168 | O9: =D8 -> 3000 | P9: - проведение ГРП/МСГРП, сут. | R9: 1
C10: Наличие АИЭС: | D10: ='Титул '!C14 -> нет | E10: Всего Освоение | F10: Исходные данные | H10: Отход | I10: Пилот ГС | J10: Перебур | K10: Гориз.уч. 1 | L10: Гориз.уч. 2 | M10: Керн | O10: ГЛУБИНА ПО ВЕРТ-ЛИ | P10: - проведение ГНКТ, сут. | R10: 3
C11: Наличие автономности: | D11: ='Титул '!C15 -> нет | E11: =IF(($L$45+$L$46+$L$47+$L$48+$L$49+$L$50)>0,$W$206,0) -> 36904487 | F11: Отдельные стволы, керн, м: | P11: - кол-во стадий МСГРП, шт. | R11: 2
C12: Кол-во обсадных колонн (включая направл.): | D12: 3 | E12: Обор-ие устья | F12: Примечание: | P12: Примечание:
C13: Прочие существенные условия: | E13: =IF(($L$45+$L$46+$L$47+$L$48+$L$49+$L$50)>0,$W$212,0) -> 0
A15: ОПИСАНИЕ РАБОТ И УСЛУГ | H15: КОЛИЧЕСТВО | O15: СТОИМОСТЬ | V15: ВСЕГО
A16: КОД | B16: добавочный код | C16: СТАТЬЯ ЗАТРАТ | D16: ОПИСАНИЕ | E16: Подрядчик | F16: Единица измерения | G16: Руб. / Ед.изм. | H16: ПЗР (в т.ч. ВМР и осв.) | I16: =+I4 -> Направление | J16: =+J4 -> Кондуктор | K16: =+K4 -> Техническая колонна | L16: =+L4 -> Эксплуат-ая колонна | M16: Крепление колонн | N16: =+N4 -> Хвостовик | O16: ПЗР (в т.ч. ВМР и осв.) | P16: =+I16 -> Направление | Q16: =+J16 -> Кондуктор | R16: =+K16 -> Техническая колонна | S16: =+L16 -> Эксплуат-ая колонна | T16: Крепление колонн | U16: =+N16 -> Хвостовик | V16: Количество | W16: Стоимость (руб) | X16: ВСЕГО СТОИМОСТЬ
C18: 1. ЭТАП ВМР | X18: =SUM(W20:W40) -> 471302.12
C19: ='Перв. скв '!C19 -> не определен | D19: Описание работ/услуг
D20: ='Перв. скв '!D20 -> Монтаж | E20: =D$5 -> не определен | F20: ='Перв. скв '!F20 -> опер. | G20: ='Перв. скв '!G20 -> 9401938 | O20: =H20*G20 -> 0 | V20: =SUM(H20:N20) -> 0 | W20: =SUM(O20:U20) -> 0
D21: ='Перв. скв '!D21 -> Демонтаж | E21: =D$5 -> не определен | F21: ='Перв. скв '!F21 -> опер. | G21: ='Перв. скв '!G21 -> 2344149 | O21: =H21*G21 -> 0 | V21: =SUM(H21:N21) -> 0 | W21: =SUM(O21:U21) -> 0
D22: ='Перв. скв '!D22 -> Эксплуатация АВЭС | E22: =D$5 -> не определен | F22: ='Перв. скв '!F22 -> опер. | G22: ='Перв. скв '!G22 -> 0 | O22: =H22*G22 -> 0 | V22: =SUM(H22:N22) -> 0 | W22: =SUM(O22:U22) -> 0
D23: ='Перв. скв '!D23 -> Передислокация БУ в пределах м-я | E23: =D$5 -> не определен | F23: ='Перв. скв '!F23 -> опер. | G23: ='Перв. скв '!G23 -> 693236 | O23: =H23*G23 -> 0 | V23: =SUM(H23:N23) -> 0 | W23: =SUM(O23:U23) -> 0
D24: ='Перв. скв '!D24 -> Передислокация БУ 250-500 км. | E24: =D$5 -> не определен | F24: ='Перв. скв '!F24 -> опер. | G24: ='Перв. скв '!G24 -> 9837322 | O24: =H24*G24 -> 0 | V24: =SUM(H24:N24) -> 0 | W24: =SUM(O24:U24) -> 0
D25: ='Перв. скв '!D25 -> Передислокация бр. бур в пределах м-я | E25: =D$5 -> не определен | F25: ='Перв. скв '!F25 -> опер. | G25: ='Перв. скв '!G25 -> 130867 | O25: =H25*G25 -> 0 | V25: =SUM(H25:N25) -> 0 | W25: =SUM(O25:U25) -> 0
D26: ='Перв. скв '!D26 -> Передислокация бр. бур 250-500 км. | E26: =D$5 -> не определен | F26: ='Перв. скв '!F26 -> опер. | G26: ='Перв. скв '!G26 -> 1788526 | O26: =H26*G26 -> 0 | V26: =SUM(H26:N26) -> 0 | W26: =SUM(O26:U26) -> 0
D27: ='Перв. скв '!D27 -> Передислокация бригады ВМР в пределах м-я | E27: =D$5 -> не определен | F27: ='Перв. скв '!F27 -> опер. | G27: ='Перв. скв '!G27 -> 130867 | O27: =H27*G27 -> 0 | V27: =SUM(H27:N27) -> 0 | W27: =SUM(O27:U27) -> 0
D28: ='Перв. скв '!D28 -> Передислокация бригады ВМР 250-500 км. | E28: =D$5 -> не определен | F28: ='Перв. скв '!F28 -> опер. | G28: ='Перв. скв '!G28 -> 1788526 | O28: =H28*G28 -> 0 | V28: =SUM(H28:N28) -> 0 | W28: =SUM(O28:U28) -> 0
D29: ='Перв. скв '!D29 -> Передвижка 5 м. | E29: =D$5 -> не определен | F29: ='Перв. скв '!F29 -> опер. | G29: ='Перв. скв '!G29 -> 244497 | O29: =H29*G29 -> 0 | V29: =SUM(H29:N29) -> 0 | W29: =SUM(O29:U29) -> 0
D30: ='Перв. скв '!D30 -> Передвижка 9 м. | E30: =D$5 -> не определен | F30: ='Перв. скв '!F30 -> опер. | G30: ='Перв. скв '!G30 -> 265365 | H30: 1 | O30: =H30*G30 -> 265365 | V30: =SUM(H30:N30) -> 1 | W30: =SUM(O30:U30) -> 265365
D31: ='Перв. скв '!D31 -> Передвижка 18 м. | E31: =D$5 -> не определен | F31: ='Перв. скв '!F31 -> опер. | G31: ='Перв. скв '!G31 -> 406328 | O31: =H31*G31 -> 0 | V31: =SUM(H31:N31) -> 0 | W31: =SUM(O31:U31) -> 0
D32: ='Перв. скв '!D32 -> Передвижка 25 м. | E32: =D$5 -> не определен | F32: ='Перв. скв '!F32 -> опер. | G32: ='Перв. скв '!G32 -> 462462 | O32: =H32*G32 -> 0 | V32: =SUM(H32:N32) -> 0 | W32: =SUM(O32:U32) -> 0
D33: ='Перв. скв '!D33 -> Передвижка 50 м. | E33: =D$5 -> не определен | F33: ='Перв. скв '!F33 -> опер. | G33: ='Перв. скв '!G33 -> 889289 | O33: =H33*G33 -> 0 | V33: =SUM(H33:N33) -> 0 | W33: =SUM(O33:U33) -> 0
D34: ='Перв. скв '!D34 -> Сдвижка 25 м. | E34: =D$5 -> не определен | F34: ='Перв. скв '!F34 -> опер. | G34: ='Перв. скв '!G34 -> 291019 | O34: =H34*G34 -> 0 | V34: =SUM(H34:N34) -> 0 | W34: =SUM(O34:U34) -> 0
D35: ='Перв. скв '!D35 -> Пуско-наладочные работы | E35: =D$5 -> не определен | F35: ='Перв. скв '!F35 -> опер. | G35: ='Перв. скв '!G35 -> 633406 | O35: =H35*G35 -> 0 | V35: =SUM(H35:N35) -> 0 | W35: =SUM(O35:U35) -> 0
D36: ='Перв. скв '!D36 -> Артезианская скважина | E36: =D$5 -> не определен | F36: ='Перв. скв '!F36 -> опер. | G36: ='Перв. скв '!G36 -> 475880 | O36: =H36*G36 -> 0 | V36: =SUM(H36:N36) -> 0 | W36: =SUM(O36:U36) -> 0
D37: ='Перв. скв '!D37 -> Авиапревозки | E37: =D$5 -> не определен | F37: ='Перв. скв '!F37 -> опер. | G37: ='Перв. скв '!G37 -> 205937.12 | H37: 1 | O37: =H37*G37 -> 205937.12 | V37: =SUM(H37:N37) -> 1 | W37: =SUM(O37:U37) -> 205937.12
D38: ='Перв. скв '!D38 -> Мобилизация и монтаж энергокомплекса | E38: =D$5 -> не определен | F38: ='Перв. скв '!F38 -> опер. | G38: ='Перв. скв '!G38 -> 0 | O38: =H38*G38 -> 0 | V38: =SUM(H38:N38) -> 0 | W38: =SUM(O38:U38) -> 0
D39: ='Перв. скв '!D39 -> Завоз и монтаж верхнего силового привода | E39: =D$5 -> не определен | F39: ='Перв. скв '!F39 -> опер. | G39: ='Перв. скв '!G39 -> 2078246 | O39: =H39*G39 -> 0 | V39: =SUM(H39:N39) -> 0 | W39: =SUM(O39:U39) -> 0
D40: ='Перв. скв '!D40 -> Завоз и монтаж новой насосной группы | E40: =D$5 -> не определен | F40: ='Перв. скв '!F40 -> опер. | G40: ='Перв. скв '!G40 -> 899742 | O40: =H40*G40 -> 0 | V40: =SUM(H40:N40) -> 0 | W40: =SUM(O40:U40) -> 0
C41: ОБЩАЯ СТОИМОСТЬ ВМР | D41: =W41 -> 471302.12 | O41: =SUM(O20:O40) -> 471302.12 | W41: =SUM(W20:W40) -> 471302.12
C43: 2. ЭТАП БУРЕНИЯ: | X43: =SUM(W45:W55) -> 40617487
C44: ='Перв. скв '!C44 -> не определен | D44: Описание работ/услуг
C45: (технико-технологичексие особенности) | D45: ='Перв. скв '!D45 -> Фиксированная ставка за скважину с отходом до 1300 м. | E45: =D$5 -> не определен | F45: ='Перв. скв '!F45 -> скв. | G45: ='Перв. скв '!G45 -> 6559232 | H45: ='Перв. скв '!H45 -> 0 | I45: ='Перв. скв '!I45 -> 0 | J45: ='Перв. скв '!J45 -> 0 | K45: ='Перв. скв '!K45 -> 0 | L45: 1 | M45: ='Перв. скв '!M45 -> 0 | N45: ='Перв. скв '!N45 -> 0 | O45: =H45*G45 -> 0 | P45: =I45*G45 -> 0 | Q45: =J45*G45 -> 0 | R45: =K45*G45 -> 0 | S45: =L45*G45 -> 6559232 | T45: =M45*G45 -> 0 | U45: =N45*G45 -> 0 | V45: =SUM(H45:N45) -> 1 | W45: =SUM(O45:U45) -> 6559232
...

Sheet ННСот1300до1500
A2: ПОДРОБНАЯ СМЕТНАЯ СТОИМОСТЬ СКВАЖИНЫ
C4: Месторождение/ куст: | D4: ='Титул '!G5 -> куст №21б Приобского месторождения | E4: ВСЕГО СТ-ТЬ | F4: Исходные данные | H4: Перед забуркой | I4: Направление | J4: Кондуктор | K4: Техническая колонна | L4: Эксплуат-ая колонна | M4: Крепление колонн | N4: Хвостовик | O4: ВСЕГО БУРЕНИЕ | P4: Исходные данные | R4: ВСЕГО ОСВОЕНИЕ
C5: Подрядчик по бурению: | D5: ='Титул '!C11 -> не определен | E5: =IF(($L$45+$L$46+$L$47+$L$48+$L$49+$L$50)>0,$D$214,0) -> 1.0850179e+08
