Workbook
Name ___Dec1: 0
Name ___Dec2: 0
Name ___w306: [1]wells_graf!$A$47:$P$69
Name ___w5221: [1]wells_graf!$A$24:$P$46
Name ___w606: [1]wells_graf!$A$1:$H$23
Name ___w628: [1]wells_graf!$I$47:$P$69
Name ___w68: [1]wells_graf!$I$24:$P$46
Name ___W688: [2]wells_graf!$I$24:$P$46
Name __Dec1: 0
Name __Dec2: 0
Name __w306: [1]wells_graf!$A$47:$P$69
Name __w5221: [1]wells_graf!$A$24:$P$46
Name __w606: [1]wells_graf!$A$1:$H$23
Name __w628: [1]wells_graf!$I$47:$P$69
Name __w68: [1]wells_graf!$I$24:$P$46
Name __W688: [2]wells_graf!$I$24:$P$46
Name _2049_2050: '[3]311-1Á10'!#REF!
Name _2049_2050: '[3]311-1Á10'!#REF!
Name _2049_2050: '[3]311-1Á10'!#REF!
Name _2049_2050: '[3]311-1Á10'!#REF!
Name _2049_2050: '[3]311-1Á10'!#REF!
Name _2049_2050: '[3]311-1Á10'!#REF!
Name _2049_2050: '[3]311-1Á10'!#REF!
Name _2049_2050: '[3]311-1Á10'!#REF!
Name _2049_2050: '[3]311-1Á10'!#REF!
Name _2049_2050: '[3]311-1Á10'!#REF!
Name _2049_2050: '[3]311-1Á10'!#REF!
Name _2049_2050: '[3]311-1Á10'!#REF!
Name _2049_2050: '[3]311-1Á10'!#REF!
Name _2049_2050: '[3]311-1Á10'!#REF!
Name _2049_2050: '[3]311-1Á10'!#REF!
Name _2049_2050: '[3]311-1Á10'!#REF!
Name _2049_2050: '[3]311-1Á10'!#REF!
Name _2049_2050: '[3]311-1Á10'!#REF!
Name _Dec1: 0
Name _Dec2: 0
Name _w306: [1]wells_graf!$A$47:$P$69
Name _w5221: [1]wells_graf!$A$24:$P$46
Name _w606: [1]wells_graf!$A$1:$H$23
Name _w628: [1]wells_graf!$I$47:$P$69
Name _w68: [1]wells_graf!$I$24:$P$46
Name _W688: [2]wells_graf!$I$24:$P$46
Name add1_1Q: [4]Resources!$C$172
Name add1_2Q: [4]Resources!$C$173
Name add1_3D_seismic: [4]Resources!$C$188
Name add1_3Q: [4]Resources!$C$174
Name add1_4Q: [4]Resources!$C$175
Name add1_bases: [4]Resources!$C$195
Name add1_capex_investments: [4]Resources!$C$183
Name add1_cell_sidetracking: '[4]1'!$C$41
Name add1_development_of_drilling_facilities: [4]Resources!$C$187
Name add1_drilling: [4]Resources!$C$185
Name add1_frac_costs: [4]Resources!$C$203
Name add1_inflow_stimulation: [4]Resources!$C$186
Name add1_investment_designation: [4]Resources!$C$169
Name add1_investments: [4]Resources!$C$182
Name add1_modernization: [4]Resources!$C$189
Name add1_motorways: [4]Resources!$C$193
Name add1_new_construction: [4]Resources!$C$198
Name add1_oil_production: [4]Resources!$C$176

Sheet Справочник подстановки
A1: Справочник выплывающих значений
A2: Тип скважины | C2: Кол-во колонн | D2: Наличие пилотного ствола (ликвидированного по геологич.причинам) | E2: Кол-во пил.стволов | F2: Многозабойность | G2: Кол-во продуктивных стволов | H2: Проведение ГРП | I2: количество стадий ГРП | J2: Назначение скважины | K2: Отход | L2: Примечание | M2: ед.изм | N2: да/нет
A3: ННС | B3: ЮРА | C3: 2к | D3: пилот | E3: 1 | F3: многозабойная | G3: 1 | H3: ГРП | I3: 1ст | J3: Добывающая | K3: <800 | L3: 2гор.уч. | M3: сут | N3: да
A4: ГС | B4: Палеозой | C4: 3к | D4: без пилота | E4: 2 | G4: 2 | H4: МГРП | I4: 2ст | J4: Нагнетательная | K4: 800-1300 | L4: 3гор.уч. | M4: операция | N4: нет
A5: ВЗ | B5: Бажен | C5: 4к | E5: 3 | G5: 3 | I5: 3ст | J5: Водозаборная | K5: 1300-1800 | L5: 2Пилота | M5: шт | N5: Частично на межсезонье
C6: 5к | E6: 4 | G6: 4 | I6: 4ст | J6: Газовая | K6: 1800-2200 | L6: 3Пилота | M6: пог.м.
C7: 6к | E7: 5 | G7: 5 | I7: 5ст | J7: Разведочная | K7: >2200 | L7: Газовая | M7: тн
C8: 7к | G8: 6 | I8: 6ст | J8: Пьезометрическая | L8: Пологая | M8: комплекс
I9: 7ст | L9: Разведочная | M9: бр.ч.
I10: 8ст | L10: Оценочная | M10: м3
I11: 9ст | M11: к-т
I12: 10ст | M12: м
I13: 11ст | M13: скв
I14: 12ст
I15: 13ст
I16: 14ст
I17: 15ст
I18: 16ст
I19: 17ст
I20: 18ст
I21: 19ст
I22: 20ст

Sheet Титул 
B1: Проект: | K1: Бурение
K2: Вид проекта
B4: Название проекта: | K4: Бурение скважин в 2014 - 2017 гг.
K5: 3 куст Новопортовского месторождения
B7: Наименование организации: | K7: ООО "Газпром нефть Новый Порт"
B9: Начало поведения (мес/год) | K9: 41792 | L9: (мес/год)
B10: Конец проведения работ (мес/год) | K10: 42775 | L10: (мес/год)
B11: Буровой подрядчик | K11: ООО "Буровая компания "Евразия" | N11: (наименование организации)
B12: Тип буровго станка | K12: ZJ-50 | N12: (наименование типа БУ)
B13: Наличие ВСП | L13: (Да/ Нет)
B14: Наличие АвИЭС | K14: да | L14: (Да/ Нет)
B15: Наличие автономности | K15: да | L15: (Да/ Нет/ Частично на межсезонье)
B17: ОТВЕТСТВЕННЫЕ СПЕЦИАЛИСТЫ ПО ПРОЕКТУ
B18: По технико-технологическим показателям | K18: Пильник Сергей Васильевич | Q18: Начальник отдела инжиниринга
K19: Ф.И.О. | P19: тел. | Q19: должность
B20: По экономическим показателям | K20: Полубояринова Эвелина Вячеславовна | Q20: Начальник отдела экономического анализа
K21: Ф.И.О. | P21: тел. | Q21: должность
B23: Тэхнико-экономические показатели строительства по проекту:
B25: Наименование показателя | K25: Ед. изм. | L25: Кол-во скважин, законченных бурением | N25: Кол-во скважин, законченных освоением | P25: Проходка по скважинам, м | R25: Время бурения, сут. | T25: Время осовения, сут.
L26: Текущий год | M26: Всего скв. | N26: Текущий год | O26: Всего скв. | P26: Всего | Q26: Ср. значение на 1 скв. | R26: Всего | S26: Ср. значение на 1 скв. | T26: Всего | U26: Ср. значение на 1 скв.
B27: № п/п | C27: Тип скважины | E27: Отход от вертикали | F27: Пилотный ствол | G27: (М)ГРП | H27: кол-во стадий ГРП | I27: Кол-во колонн | J27: Примечание | K27: скв. | L27: =SUM(L28:L44) -> 0 | M27: =SUM(M28:M44) -> 32 | N27: =SUM(N28:N44) -> 0 | O27: =SUM(O28:O44) -> 32 | P27: =SUM(P28:P44) -> 128505 | Q27: =SUM(Q28:Q44) -> 26218 | R27: =SUM(R28:R44) -> 1162 | S27: =SUM(S28:S44) -> 292 | ... U27: =SUM(U28:U44) -> 0
B28: 1 (Первая) | C28: ГС | D28: ЮРА | F28: без пилота | G28: МГРП | H28: 8ст | K28: скв. | M28: 2 | O28: =M28 -> 2 | P28: =$M28*Q28 -> 9456 | Q28: ='Перв. скв '!$D$8 -> 4728 | R28: =$M28*S28 -> 68 | S28: ='Перв. скв '!$O$6 -> 34 | T28: =$O28*U28 -> 0 | U28: ='Перв. скв '!$R$6 -> 0
B29: 2 | C29: ГС | K29: скв. | P29: =$M29*Q29 -> 0 | Q29: ='2'!$D$8 -> 0 | R29: =$M29*S29 -> 0 | S29: ='2'!$O$6 -> 0 | T29: =$O29*U29 -> 0 | U29: ='2'!$R$6 -> 0
B30: 3 | C30: ННС | K30: скв. | P30: =$M30*Q30 -> 0 | Q30: ='3'!$D$8 -> 0 | R30: =$M30*S30 -> 0 | S30: ='3'!$O$6 -> 0 | T30: =$O30*U30 -> 0 | U30: ='3'!$R$6 -> 0
B31: 4 | C31: ГС | K31: скв. | P31: =$M31*Q31 -> 0 | Q31: ='4'!$D$8 -> 0 | R31: =$M31*S31 -> 0 | S31: ='4'!$O$6 -> 0 | T31: =$O31*U31 -> 0 | U31: ='4'!$R$6 -> 0
B32: 5 | C32: ГС | K32: скв. | P32: =$M32*Q32 -> 0 | Q32: ='5'!$D$8 -> 0 | R32: =$M32*S32 -> 0 | S32: ='5'!$O$6 -> 0 | T32: =$O32*U32 -> 0 | U32: ='5'!$R$6 -> 0
B33: 6 | C33: ГС | K33: скв. | P33: =$M33*Q33 -> 0 | Q33: ='6'!$D$8 -> 0 | R33: =$M33*S33 -> 0 | S33: ='6'!$O$6 -> 0 | T33: =$O33*U33 -> 0 | U33: ='6'!$R$6 -> 0
B34: 7 | C34: ГС | K34: скв. | P34: =$M34*Q34 -> 0 | Q34: ='7'!$D$8 -> 0 | R34: =$M34*S34 -> 0 | S34: ='7'!$O$6 -> 0 | T34: =$O34*U34 -> 0 | U34: ='7'!$R$6 -> 0
B35: 8 | C35: ГС | K35: скв. | P35: =$M35*Q35 -> 0 | Q35: ='8'!$D$8 -> 0 | R35: =$M35*S35 -> 0 | S35: ='8'!$O$6 -> 0 | T35: =$O35*U35 -> 0 | U35: ='8'!$R$6 -> 0
B36: 9 | C36: ГС | K36: скв. | P36: =$M36*Q36 -> 0 | Q36: ='9'!$D$8 -> 0 | R36: =$M36*S36 -> 0 | S36: ='9'!$O$6 -> 0 | T36: =$O36*U36 -> 0 | U36: ='9'!$R$6 -> 0
B37: 10 | C37: ВЗ | F37: без пилота | K37: скв. | M37: =ВЗ!B12 -> 2 | O37: =M37 -> 2 | P37: =$M37*Q37 -> 2796 | Q37: =ВЗ!$D$8 -> 1398 | R37: =$M37*S37 -> 80 | S37: =ВЗ!$O$6 -> 40 | T37: =$O37*U37 -> 0 | U37: =ВЗ!$R$6 -> 0
B38: 11 | C38: ГС | F38: без пилота | K38: скв. | M38: ='ГС без пил 1000м гор'!B12 -> 8 | O38: =M38 -> 8 | P38: =$M38*Q38 -> 31432 | Q38: ='ГС без пил 1000м гор'!$D$8 -> 3929 | R38: =$M38*S38 -> 264 | S38: ='ГС без пил 1000м гор'!$O$6 -> 33 | T38: =$O38*U38 -> 0 | U38: ='ГС без пил 1000м гор'!$R$6 -> 0
B39: 12 | C39: ГС | F39: пилот | K39: скв. | M39: ='ГС пил 1500м гор'!B12 -> 0 | O39: =M39 -> 0 | P39: =$M39*Q39 -> 0 | Q39: ='ГС пил 1500м гор'!$D$8 -> 0 | R39: =$M39*S39 -> 0 | S39: ='ГС пил 1500м гор'!$O$6 -> 0 | T39: =$O39*U39 -> 0 | U39: ='ГС пил 1500м гор'!$R$6 -> 0
B40: 13 | C40: ГС | F40: без пилота | K40: скв. | M40: ='ГС без пилот 1500м гор'!B12 -> 6 | O40: =M40 -> 6 | P40: =$M40*Q40 -> 25938 | Q40: ='ГС без пилот 1500м гор'!$D$8 -> 4323 | R40: =$M40*S40 -> 204 | S40: ='ГС без пилот 1500м гор'!$O$6 -> 34 | T40: =$O40*U40 -> 0 | U40: ='ГС без пилот 1500м гор'!$R$6 -> 0
B41: 14 | C41: ГС | D41: ЮРА | F41: без пилота | G41: МГРП | H41: 8ст | K41: скв. | M41: ='ГСЮра без пил МГРП'!B12-2 -> 9 | O41: =M41 -> 9 | P41: =$M41*Q41 -> 36990 | Q41: ='ГСЮра без пил МГРП'!$D$8 -> 4110 | R41: =$M41*S41 -> 306 | S41: ='ГСЮра без пил МГРП'!$O$6 -> 34 | T41: =$O41*U41 -> 0 | U41: ='ГСЮра без пил МГРП'!$R$6 -> 0
B42: 15 | C42: ГС | D42: ЮРА | F42: пилот | G42: МГРП | H42: 8ст | K42: скв. | M42: ='ГСЮра пил МСГРП'!B12 -> 4 | O42: =M42 -> 4 | P42: =$M42*Q42 -> 18884 | Q42: ='ГСЮра пил МСГРП'!$D$8 -> 4721 | R42: =$M42*S42 -> 164 | S42: ='ГСЮра пил МСГРП'!$O$6 -> 41 | T42: =$O42*U42 -> 0 | U42: ='ГСЮра пил МСГРП'!$R$6 -> 0
B43: 16 | C43: ГС | D43: ЮРА | K43: скв. | M43: ='ГСЮра керн ГИС'!B12 -> 1 | O43: =M43 -> 1 | P43: =$M43*Q43 -> 3009 | Q43: ='ГСЮра керн ГИС'!$D$8 -> 3009 | R43: =$M43*S43 -> 76 | S43: ='ГСЮра керн ГИС'!$O$6 -> 76 | T43: =$O43*U43 -> 0 | U43: ='ГСЮра керн ГИС'!$R$6 -> 0
B44: 17 (Последняя) | C44: ГС | K44: скв. | P44: =$M44*Q44 -> 0 | Q44: =Посл.скв.!$D$8 -> 0 | R44: =$M44*S44 -> 0 | S44: =Посл.скв.!$O$6 -> 0 | T44: =$O44*U44 -> 0 | U44: =Посл.скв.!$R$6 -> 0
B46: Среднее по ННС | K46: скв. | L46: =SUMIF($C$28:$C$44,"ННС",L28:L44)+SUMIF($C$28:$C$44,"ВЗ",L28:L44) -> 0 | M46: =SUMIF($C$28:$C$44,"ННС",M28:M44)+SUMIF($C$28:$C$44,"ВЗ",M28:M44) -> 2 | N46: =SUMIF($C$28:$C$44,"ННС",N28:N44)+SUMIF($C$28:$C$44,"ВЗ",N28:N44) -> 0 | O46: =SUMIF($C$28:$C$44,"ННС",O28:O44)+SUMIF($C$28:$C$44,"ВЗ",O28:O44) -> 2 | P46: =SUMIF($C$28:$C$44,"ННС",P28:P44)+SUMIF($C$28:$C$44,"ВЗ",P28:P44) -> 2796 | Q46: =IF(M46=0,0,P46/$M$46) -> 1398 | R46: =SUMIF($C$28:$C$44,"ННС",R28:R44)+SUMIF($C$28:$C$44,"ВЗ",R28:R44) -> 80 | S46: =IF(M46=0,0,R46/$M$46) -> 40 | T46: =SUMIF($C$28:$C$44,"ННС",T28:T44)+SUMIF($C$28:$C$44,"ВЗ",T28:T44) -> 0 | U46: =IF(M46=0,0,T46/$M$46) -> 0
B47: Среднее по ГС | K47: скв. | L47: =SUMIF($C$28:$C$44,"ГС",L28:L44) -> 0 | M47: =SUMIF($C$28:$C$44,"ГС",M28:M44) -> 30 | N47: =SUMIF($C$28:$C$44,"ГС",N28:N44) -> 0 | O47: =SUMIF($C$28:$C$44,"ГС",O28:O44) -> 30 | P47: =SUMIF($C$28:$C$44,"ГС",P28:P44) -> 125709 | Q47: =IF(M47=0,0,P47/$M$46) -> 62854.5 | R47: =SUMIF($C$28:$C$44,"ГС",R28:R44) -> 1082 | S47: =IF(M47=0,0,R47/$M$47) -> 36.066667 | T47: =SUMIF($C$28:$C$44,"ГС",T28:T44) -> 0 | U47: =IF(M47=0,0,T47/$M$47) -> 0
...

Sheet ТЭП
A2: ПОДРОБНАЯ СМЕТНАЯ СТОИМОСТЬ СКВАЖИНЫ
C4: Месторождение/ куст: | D4: ='Титул '!$K$5 -> 3 куст Новопортовского месторождения | E4: ВСЕГО СТ-ТЬ
C5: Подрядчик по бурению: | D5: ='Титул '!K11 -> ООО "Буровая компания "Евразия" | E5: =E7+E9+E11+E13 -> 6.3867824e+09
C6: Тип буровой установки: | D6: ='Титул '!K12 -> ZJ-50 | E6: Всего ВМР
C7: Тип скважины: | E7: =AP69 -> 3.0750741e+08
C8: Проходка всего (м): | E8: Всего Бурение
C9: Наличие СВП: | D9: ='Титул '!K13 -> 0 | E9: =AP341 -> 4.4222181e+09
C10: Наличие АИЭС: | D10: ='Титул '!K14 -> да | E10: Всего Освоение
C11: Наличие автономности: | D11: ='Титул '!K15 -> да | E11: =AP361 -> 1.6570569e+09 | AP11: (руб. без НДС)
C12: Кол-во обсадных колонн (включая направл.): | E12: Обор-ие устья | F12: Вид скв. | G12: =CONCATENATE('Титул '!$C$28," ",'Титул '!$D$28," ",'Титул '!$E$28," ",'Титул '!$F$28," ",'Титул '!$G$28," ",'Титул '!$H$28," ",'Титул '!$J$28," ",'Титул '!$I$28) -> ГС ЮРА без пилота МГРП 8ст | I12: =CONCATENATE('Титул '!$C$29," ",'Титул '!$D$29," ",'Титул '!$E$29," ",'Титул '!$F$29," ",'Титул '!$G$29," ",'Титул '!$H$29," ",'Титул '!$J$29," ",'Титул '!$I$29) -> ГС | K12: =CONCATENATE('Титул '!$C$30," ",'Титул '!$D$30," ",'Титул '!$E$30," ",'Титул '!$F$30," ",'Титул '!$G$30," ",'Титул '!$H$30," ",'Титул '!$J$30," ",'Титул '!$I$30) -> ННС | M12: =CONCATENATE('Титул '!$C$31," ",'Титул '!$D$31," ",'Титул '!$E$31," ",'Титул '!$F$31," ",'Титул '!$G$31," ",'Титул '!$H$31," ",'Титул '!$J$31," ",'Титул '!$I$31) -> ГС | O12: =CONCATENATE('Титул '!$C$32," ",'Титул '!$D$32," ",'Титул '!$E$32," ",'Титул '!$F$32," ",'Титул '!$G$32," ",'Титул '!$H$32," ",'Титул '!$J$32," ",'Титул '!$I$32) -> ГС | Q12: =CONCATENATE('Титул '!$C$33," ",'Титул '!$D$33," ",'Титул '!$E$33," ",'Титул '!$F$33," ",'Титул '!$G$33," ",'Титул '!$H$33," ",'Титул '!$J$33," ",'Титул '!$I$33) -> ГС | S12: =CONCATENATE('Титул '!$C$34," ",'Титул '!$D$34," ",'Титул '!$E$34," ",'Титул '!$F$34," ",'Титул '!$G$34," ",'Титул '!$H$34," ",'Титул '!$J$34," ",'Титул '!$I$34) -> ГС | U12: =CONCATENATE('Титул '!$C$35," ",'Титул '!$D$35," ",'Титул '!$E$35," ",'Титул '!$F$35," ",'Титул '!$G$35," ",'Титул '!$H$35," ",'Титул '!$J$35," ",'Титул '!$I$35) -> ГС | W12: =CONCATENATE('Титул '!$C$36," ",'Титул '!$D$36," ",'Титул '!$E$36," ",'Титул '!$F$36," ",'Титул '!$G$36," ",'Титул '!$H$36," ",'Титул '!$J$36," ",'Титул '!$I$36) -> ГС | Y12: =CONCATENATE('Титул '!$C$37," ",'Титул '!$D$37," ",'Титул '!$E$37," ",'Титул '!$F$37," ",'Титул '!$G$37," ",'Титул '!$H$37," ",'Титул '!$J$37," ",'Титул '!$I$37) -> ВЗ без пилота | AA12: =CONCATENATE('Титул '!$C$38," ",'Титул '!$D$38," ",'Титул '!$E$38," ",'Титул '!$F$38," ",'Титул '!$G$38," ",'Титул '!$H$38," ",'Титул '!$J$38," ",'Титул '!$I$38) -> ГС без пилота | AC12: =CONCATENATE('Титул '!$C$39," ",'Титул '!$D$39," ",'Титул '!$E$39," ",'Титул '!$F$39," ",'Титул '!$G$39," ",'Титул '!$H$39," ",'Титул '!$J$39," ",'Титул '!$I$39) -> ГС пилот | AE12: =CONCATENATE('Титул '!$C$40," ",'Титул '!$D$40," ",'Титул '!$E$40," ",'Титул '!$F$40," ",'Титул '!$G$40," ",'Титул '!$H$40," ",'Титул '!$J$40," ",'Титул '!$I$40) -> ГС без пилота | AG12: =CONCATENATE('Титул '!$C$41," ",'Титул '!$D$41," ",'Титул '!$E$41," ",'Титул '!$F$41," ",'Титул '!$G$41," ",'Титул '!$H$41," ",'Титул '!$J$41," ",'Титул '!$I$41) -> ГС ЮРА без пилота МГРП 8ст | AI12: =CONCATENATE('Титул '!$C$42," ",'Титул '!$D$42," ",'Титул '!$E$42," ",'Титул '!$F$42," ",'Титул '!$G$42," ",'Титул '!$H$42," ",'Титул '!$J$42," ",'Титул '!$I$42) -> ГС ЮРА пилот МГРП 8ст | AK12: =CONCATENATE('Титул '!$C$43," ",'Титул '!$D$43," ",'Титул '!$E$43," ",'Титул '!$F$43," ",'Титул '!$G$43," ",'Титул '!$H$43," ",'Титул '!$J$43," ",'Титул '!$I$43) -> ГС ЮРА | AM12: =CONCATENATE('Титул '!$C$44," ",'Титул '!$D$44," ",'Титул '!$E$44," ",'Титул '!$F$44," ",'Титул '!$G$44," ",'Титул '!$H$44," ",'Титул '!$J$44," ",'Титул '!$I$44) -> ГС | AO12: ИТОГО
C13: Прочие существенные условия: | E13: =AP367 -> 0 | F13: Кол-во скв. | G13: ='Титул '!$M$28 -> 2 | I13: ='Титул '!$M$29 -> 0 | K13: ='Титул '!$M$30 -> 0 | M13: ='Титул '!$M$31 -> 0 | O13: ='Титул '!$M$32 -> 0 | Q13: ='Титул '!$M$33 -> 0 | S13: ='Титул '!$M$34 -> 0 | U13: ='Титул '!$M$35 -> 0 | W13: ='Титул '!$M$36 -> 0 | Y13: ='Титул '!$M$37 -> 2 | AA13: ='Титул '!$M$38 -> 8 | AC13: ='Титул '!$M$39 -> 0 | AE13: ='Титул '!$M$40 -> 6 | AG13: ='Титул '!$M$41 -> 9 | AI13: ='Титул '!$M$42 -> 4 | AK13: ='Титул '!$M$43 -> 1 | AM13: ='Титул '!$M$44 -> 0 | AO13: =SUM(G13:AN13) -> 32
A15: ОПИСАНИЕ РАБОТ И УСЛУГ
A16: КОД | B16: добавочный код | C16: СТАТЬЯ ЗАТРАТ | D16: ОПИСАНИЕ | E16: Подрядчик | F16: Единица измерения | G16: Кол-во | H16: Ст-ть работ | I16: Кол-во | J16: Ст-ть работ | K16: Кол-во | L16: Ст-ть работ | M16: Кол-во | N16: Ст-ть работ | O16: Кол-во | P16: Ст-ть работ | Q16: Кол-во | R16: Ст-ть работ | S16: Кол-во | T16: Ст-ть работ | U16: Кол-во | V16: Ст-ть работ | W16: Кол-во | X16: Ст-ть работ | Y16: Кол-во | Z16: Ст-ть работ | AA16: Кол-во | AB16: Ст-ть работ | AC16: Кол-во | AD16: Ст-ть работ | AE16: Кол-во | AF16: Ст-ть работ | AG16: Кол-во | AH16: Ст-ть работ | AI16: Кол-во | AJ16: Ст-ть работ | AK16: Кол-во | AL16: Ст-ть работ | AM16: Кол-во | AN16: Ст-ть работ | AO16: Кол-во | AP16: Ст-ть работ
C18: 1. ЭТАП ВМР
C19: ='Перв. скв '!C19 -> ООО "Буровая компания "Евразия" | D19: Описание работ/услуг
C20: ='Перв. скв '!C20 -> Работы, связанные с мобилизацией БУ (переездом), а так же прочего бурового оборудования и бригадного хозяйства, автономного источника энергоснабжения, материалов подрядчика и прочее. | D20: ='Перв. скв '!D20 -> Мобилизация БУ (переезд) | E20: ='Перв. скв '!E20 -> ООО "Буровая компания "Евразия" | F20: ='Перв. скв '!F20 -> операция | G20: ='Перв. скв '!$V20*G$13 -> 2 | H20: ='Перв. скв '!$W20*G$13 -> 2.5786548e+08 | I20: ='2'!$V20*I$13 -> 0 | J20: ='2'!$W20*I$13 -> 0 | K20: ='3'!$V20*K$13 -> 0 | L20: ='3'!$W20*K$13 -> 0 | M20: ='4'!$V20*M$13 -> 0 | N20: ='4'!$W20*M$13 -> 0 | O20: ='5'!$V20*O$13 -> 0 | P20: ='5'!$W20*O$13 -> 0 | Q20: ='6'!$V20*Q$13 -> 0 | R20: ='6'!$W20*Q$13 -> 0 | S20: ='7'!$V20*S$13 -> 0 | T20: ='7'!$W20*S$13 -> 0 | U20: ='8'!$V20*U$13 -> 0 | V20: ='8'!$W20*U$13 -> 0 | W20: ='9'!$V20*W$13 -> 0 | X20: ='9'!$W20*W$13 -> 0 | Y20: =ВЗ!$V20*Y$13 -> 0 | Z20: =ВЗ!$W20*Y$13 -> 0 | AA20: ='ГС без пил 1000м гор'!$V20*AA$13 -> 0 | AB20: ='ГС без пил 1000м гор'!$W20*AA$13 -> 0 | AC20: ='ГС пил 1500м гор'!$V20*AC$13 -> 0 | AD20: ='ГС пил 1500м гор'!$W20*AC$13 -> 0 | AE20: ='ГС без пилот 1500м гор'!$V20*AE$13 -> 0 | AF20: ='ГС без пилот 1500м гор'!$W20*AE$13 -> 0 | AG20: ='ГСЮра без пил МГРП'!$V20*AG$13 -> 0 | AH20: ='ГСЮра без пил МГРП'!$W20*AG$13 -> 0 | AI20: ='ГСЮра пил МСГРП'!$V20*AI$13 -> 0 | AJ20: ='ГСЮра пил МСГРП'!$W20*AI$13 -> 0 | AK20: ='ГСЮра керн ГИС'!$V20*AK$13 -> 0 | AL20: ='ГСЮра керн ГИС'!$W20*AK$13 -> 0 | AM20: =Посл.скв.!$V20*AM$13 -> 0 | AN20: =Посл.скв.!$W20*AM$13 -> 0 | AO20: =AM20+AK20+AI20+AG20+AE20+AC20+AA20+Y20++W20+U20+S20+Q20+M20+O20+K20+I20+G20 -> 2 | AP20: =AN20+AL20+AJ20+AH20+AF20+AD20+AB20+Z20++X20+V20+T20+R20+N20+P20+L20+J20+H20 -> 2.5786548e+08
C21: ='Перв. скв '!C21 -> 0 | D21: ='Перв. скв '!D21 -> - мобилизация БУ (переезд) | E21: ='Перв. скв '!E21 -> ООО "Буровая компания "Евразия" | F21: ='Перв. скв '!F21 -> операция | G21: ='Перв. скв '!$V21*G$13 -> 0 | H21: ='Перв. скв '!$W21*G$13 -> 0 | I21: ='2'!$V21*I$13 -> 0 | J21: ='2'!$W21*I$13 -> 0 | K21: ='3'!$V21*K$13 -> 0 | L21: ='3'!$W21*K$13 -> 0 | M21: ='4'!$V21*M$13 -> 0 | N21: ='4'!$W21*M$13 -> 0 | O21: ='5'!$V21*O$13 -> 0 | P21: ='5'!$W21*O$13 -> 0 | Q21: ='6'!$V21*Q$13 -> 0 | R21: ='6'!$W21*Q$13 -> 0 | S21: ='7'!$V21*S$13 -> 0 | T21: ='7'!$W21*S$13 -> 0 | U21: ='8'!$V21*U$13 -> 0 | V21: ='8'!$W21*U$13 -> 0 | W21: ='9'!$V21*W$13 -> 0 | X21: ='9'!$W21*W$13 -> 0 | Y21: =ВЗ!$V21*Y$13 -> 0 | Z21: =ВЗ!$W21*Y$13 -> 0 | AA21: ='ГС без пил 1000м гор'!$V21*AA$13 -> 0 | AB21: ='ГС без пил 1000м гор'!$W21*AA$13 -> 0 | AC21: ='ГС пил 1500м гор'!$V21*AC$13 -> 0 | AD21: ='ГС пил 1500м гор'!$W21*AC$13 -> 0 | AE21: ='ГС без пилот 1500м гор'!$V21*AE$13 -> 0 | AF21: ='ГС без пилот 1500м гор'!$W21*AE$13 -> 0 | AG21: ='ГСЮра без пил МГРП'!$V21*AG$13 -> 0 | AH21: ='ГСЮра без пил МГРП'!$W21*AG$13 -> 0 | AI21: ='ГСЮра пил МСГРП'!$V21*AI$13 -> 0 | AJ21: ='ГСЮра пил МСГРП'!$W21*AI$13 -> 0 | AK21: ='ГСЮра керн ГИС'!$V21*AK$13 -> 0 | AL21: ='ГСЮра керн ГИС'!$W21*AK$13 -> 0 | AM21: =Посл.скв.!$V21*AM$13 -> 0 | AN21: =Посл.скв.!$W21*AM$13 -> 0 | AO21: =AM21+AK21+AI21+AG21+AE21+AC21+AA21+Y21++W21+U21+S21+Q21+M21+O21+K21+I21+G21 -> 0 | AP21: =AN21+AL21+AJ21+AH21+AF21+AD21+AB21+Z21++X21+V21+T21+R21+N21+P21+L21+J21+H21 -> 0
C22: ='Перв. скв '!C22 -> 0 | D22: ='Перв. скв '!D22 -> - мобилизация БХ и БИ (перевозка) | E22: ='Перв. скв '!E22 -> ООО "Буровая компания "Евразия" | F22: ='Перв. скв '!F22 -> операция | G22: ='Перв. скв '!$V22*G$13 -> 0 | H22: ='Перв. скв '!$W22*G$13 -> 0 | I22: ='2'!$V22*I$13 -> 0 | J22: ='2'!$W22*I$13 -> 0 | K22: ='3'!$V22*K$13 -> 0 | L22: ='3'!$W22*K$13 -> 0 | M22: ='4'!$V22*M$13 -> 0 | N22: ='4'!$W22*M$13 -> 0 | O22: ='5'!$V22*O$13 -> 0 | P22: ='5'!$W22*O$13 -> 0 | Q22: ='6'!$V22*Q$13 -> 0 | R22: ='6'!$W22*Q$13 -> 0 | S22: ='7'!$V22*S$13 -> 0 | T22: ='7'!$W22*S$13 -> 0 | U22: ='8'!$V22*U$13 -> 0 | V22: ='8'!$W22*U$13 -> 0 | W22: ='9'!$V22*W$13 -> 0 | X22: ='9'!$W22*W$13 -> 0 | Y22: =ВЗ!$V22*Y$13 -> 0 | Z22: =ВЗ!$W22*Y$13 -> 0 | AA22: ='ГС без пил 1000м гор'!$V22*AA$13 -> 0 | AB22: ='ГС без пил 1000м гор'!$W22*AA$13 -> 0 | AC22: ='ГС пил 1500м гор'!$V22*AC$13 -> 0 | AD22: ='ГС пил 1500м гор'!$W22*AC$13 -> 0 | AE22: ='ГС без пилот 1500м гор'!$V22*AE$13 -> 0 | AF22: ='ГС без пилот 1500м гор'!$W22*AE$13 -> 0 | AG22: ='ГСЮра без пил МГРП'!$V22*AG$13 -> 0 | AH22: ='ГСЮра без пил МГРП'!$W22*AG$13 -> 0 | AI22: ='ГСЮра пил МСГРП'!$V22*AI$13 -> 0 | AJ22: ='ГСЮра пил МСГРП'!$W22*AI$13 -> 0 | AK22: ='ГСЮра керн ГИС'!$V22*AK$13 -> 0 | AL22: ='ГСЮра керн ГИС'!$W22*AK$13 -> 0 | AM22: =Посл.скв.!$V22*AM$13 -> 0 | AN22: =Посл.скв.!$W22*AM$13 -> 0 | AO22: =AM22+AK22+AI22+AG22+AE22+AC22+AA22+Y22++W22+U22+S22+Q22+M22+O22+K22+I22+G22 -> 0 | AP22: =AN22+AL22+AJ22+AH22+AF22+AD22+AB22+Z22++X22+V22+T22+R22+N22+P22+L22+J22+H22 -> 0
C23: ='Перв. скв '!C23 -> 0 | D23: ='Перв. скв '!D23 -> - мобилизация АвИЭС (переезд) | E23: ='Перв. скв '!E23 -> ООО "Буровая компания "Евразия" | F23: ='Перв. скв '!F23 -> операция | G23: ='Перв. скв '!$V23*G$13 -> 0 | H23: ='Перв. скв '!$W23*G$13 -> 0 | I23: ='2'!$V23*I$13 -> 0 | J23: ='2'!$W23*I$13 -> 0 | K23: ='3'!$V23*K$13 -> 0 | L23: ='3'!$W23*K$13 -> 0 | M23: ='4'!$V23*M$13 -> 0 | N23: ='4'!$W23*M$13 -> 0 | O23: ='5'!$V23*O$13 -> 0 | P23: ='5'!$W23*O$13 -> 0 | Q23: ='6'!$V23*Q$13 -> 0 | R23: ='6'!$W23*Q$13 -> 0 | S23: ='7'!$V23*S$13 -> 0 | T23: ='7'!$W23*S$13 -> 0 | U23: ='8'!$V23*U$13 -> 0 | V23: ='8'!$W23*U$13 -> 0 | W23: ='9'!$V23*W$13 -> 0 | X23: ='9'!$W23*W$13 -> 0 | Y23: =ВЗ!$V23*Y$13 -> 0 | Z23: =ВЗ!$W23*Y$13 -> 0 | AA23: ='ГС без пил 1000м гор'!$V23*AA$13 -> 0 | AB23: ='ГС без пил 1000м гор'!$W23*AA$13 -> 0 | AC23: ='ГС пил 1500м гор'!$V23*AC$13 -> 0 | AD23: ='ГС пил 1500м гор'!$W23*AC$13 -> 0 | AE23: ='ГС без пилот 1500м гор'!$V23*AE$13 -> 0 | AF23: ='ГС без пилот 1500м гор'!$W23*AE$13 -> 0 | AG23: ='ГСЮра без пил МГРП'!$V23*AG$13 -> 0 | AH23: ='ГСЮра без пил МГРП'!$W23*AG$13 -> 0 | AI23: ='ГСЮра пил МСГРП'!$V23*AI$13 -> 0 | AJ23: ='ГСЮра пил МСГРП'!$W23*AI$13 -> 0 | AK23: ='ГСЮра керн ГИС'!$V23*AK$13 -> 0 | AL23: ='ГСЮра керн ГИС'!$W23*AK$13 -> 0 | AM23: =Посл.скв.!$V23*AM$13 -> 0 | AN23: =Посл.скв.!$W23*AM$13 -> 0 | AO23: =AM23+AK23+AI23+AG23+AE23+AC23+AA23+Y23++W23+U23+S23+Q23+M23+O23+K23+I23+G23 -> 0 | AP23: =AN23+AL23+AJ23+AH23+AF23+AD23+AB23+Z23++X23+V23+T23+R23+N23+P23+L23+J23+H23 -> 0
C24: ='Перв. скв '!C24 -> 0 | D24: ='Перв. скв '!D24 -> 0 | E24: ='Перв. скв '!E24 -> ООО "Буровая компания "Евразия" | F24: ='Перв. скв '!F24 -> операция | G24: ='Перв. скв '!$V24*G$13 -> 0 | H24: ='Перв. скв '!$W24*G$13 -> 0 | I24: ='2'!$V24*I$13 -> 0 | J24: ='2'!$W24*I$13 -> 0 | K24: ='3'!$V24*K$13 -> 0 | L24: ='3'!$W24*K$13 -> 0 | M24: ='4'!$V24*M$13 -> 0 | N24: ='4'!$W24*M$13 -> 0 | O24: ='5'!$V24*O$13 -> 0 | P24: ='5'!$W24*O$13 -> 0 | Q24: ='6'!$V24*Q$13 -> 0 | R24: ='6'!$W24*Q$13 -> 0 | S24: ='7'!$V24*S$13 -> 0 | T24: ='7'!$W24*S$13 -> 0 | U24: ='8'!$V24*U$13 -> 0 | V24: ='8'!$W24*U$13 -> 0 | W24: ='9'!$V24*W$13 -> 0 | X24: ='9'!$W24*W$13 -> 0 | Y24: =ВЗ!$V24*Y$13 -> 0 | Z24: =ВЗ!$W24*Y$13 -> 0 | AA24: ='ГС без пил 1000м гор'!$V24*AA$13 -> 0 | AB24: ='ГС без пил 1000м гор'!$W24*AA$13 -> 0 | AC24: ='ГС пил 1500м гор'!$V24*AC$13 -> 0 | AD24: ='ГС пил 1500м гор'!$W24*AC$13 -> 0 | AE24: ='ГС без пилот 1500м гор'!$V24*AE$13 -> 0 | AF24: ='ГС без пилот 1500м гор'!$W24*AE$13 -> 0 | AG24: ='ГСЮра без пил МГРП'!$V24*AG$13 -> 0 | AH24: ='ГСЮра без пил МГРП'!$W24*AG$13 -> 0 | AI24: ='ГСЮра пил МСГРП'!$V24*AI$13 -> 0 | AJ24: ='ГСЮра пил МСГРП'!$W24*AI$13 -> 0 | AK24: ='ГСЮра керн ГИС'!$V24*AK$13 -> 0 | AL24: ='ГСЮра керн ГИС'!$W24*AK$13 -> 0 | AM24: =Посл.скв.!$V24*AM$13 -> 0 | AN24: =Посл.скв.!$W24*AM$13 -> 0 | AO24: =AM24+AK24+AI24+AG24+AE24+AC24+AA24+Y24++W24+U24+S24+Q24+M24+O24+K24+I24+G24 -> 0 | AP24: =AN24+AL24+AJ24+AH24+AF24+AD24+AB24+Z24++X24+V24+T24+R24+N24+P24+L24+J24+H24 -> 0
C25: ='Перв. скв '!C25 -> 0 | D25: ='Перв. скв '!D25 -> 0 | E25: ='Перв. скв '!E25 -> ООО "Буровая компания "Евразия" | F25: ='Перв. скв '!F25 -> операция | G25: ='Перв. скв '!$V25*G$13 -> 0 | H25: ='Перв. скв '!$W25*G$13 -> 0 | I25: ='2'!$V25*I$13 -> 0 | J25: ='2'!$W25*I$13 -> 0 | K25: ='3'!$V25*K$13 -> 0 | L25: ='3'!$W25*K$13 -> 0 | M25: ='4'!$V25*M$13 -> 0 | N25: ='4'!$W25*M$13 -> 0 | O25: ='5'!$V25*O$13 -> 0 | P25: ='5'!$W25*O$13 -> 0 | Q25: ='6'!$V25*Q$13 -> 0 | R25: ='6'!$W25*Q$13 -> 0 | S25: ='7'!$V25*S$13 -> 0 | T25: ='7'!$W25*S$13 -> 0 | U25: ='8'!$V25*U$13 -> 0 | V25: ='8'!$W25*U$13 -> 0 | W25: ='9'!$V25*W$13 -> 0 | X25: ='9'!$W25*W$13 -> 0 | Y25: =ВЗ!$V25*Y$13 -> 0 | Z25: =ВЗ!$W25*Y$13 -> 0 | AA25: ='ГС без пил 1000м гор'!$V25*AA$13 -> 0 | AB25: ='ГС без пил 1000м гор'!$W25*AA$13 -> 0 | AC25: ='ГС пил 1500м гор'!$V25*AC$13 -> 0 | AD25: ='ГС пил 1500м гор'!$W25*AC$13 -> 0 | AE25: ='ГС без пилот 1500м гор'!$V25*AE$13 -> 0 | AF25: ='ГС без пилот 1500м гор'!$W25*AE$13 -> 0 | AG25: ='ГСЮра без пил МГРП'!$V25*AG$13 -> 0 | AH25: ='ГСЮра без пил МГРП'!$W25*AG$13 -> 0 | AI25: ='ГСЮра пил МСГРП'!$V25*AI$13 -> 0 | AJ25: ='ГСЮра пил МСГРП'!$W25*AI$13 -> 0 | AK25: ='ГСЮра керн ГИС'!$V25*AK$13 -> 0 | AL25: ='ГСЮра керн ГИС'!$W25*AK$13 -> 0 | AM25: =Посл.скв.!$V25*AM$13 -> 0 | AN25: =Посл.скв.!$W25*AM$13 -> 0 | AO25: =AM25+AK25+AI25+AG25+AE25+AC25+AA25+Y25++W25+U25+S25+Q25+M25+O25+K25+I25+G25 -> 0 | AP25: =AN25+AL25+AJ25+AH25+AF25+AD25+AB25+Z25++X25+V25+T25+R25+N25+P25+L25+J25+H25 -> 0
C26: ='Перв. скв '!C26 -> 0 | D26: ='Перв. скв '!D26 -> 0 | E26: ='Перв. скв '!E26 -> ООО "Буровая компания "Евразия" | F26: ='Перв. скв '!F26 -> операция | G26: ='Перв. скв '!$V26*G$13 -> 0 | H26: ='Перв. скв '!$W26*G$13 -> 0 | I26: ='2'!$V26*I$13 -> 0 | J26: ='2'!$W26*I$13 -> 0 | K26: ='3'!$V26*K$13 -> 0 | L26: ='3'!$W26*K$13 -> 0 | M26: ='4'!$V26*M$13 -> 0 | N26: ='4'!$W26*M$13 -> 0 | O26: ='5'!$V26*O$13 -> 0 | P26: ='5'!$W26*O$13 -> 0 | Q26: ='6'!$V26*Q$13 -> 0 | R26: ='6'!$W26*Q$13 -> 0 | S26: ='7'!$V26*S$13 -> 0 | T26: ='7'!$W26*S$13 -> 0 | U26: ='8'!$V26*U$13 -> 0 | V26: ='8'!$W26*U$13 -> 0 | W26: ='9'!$V26*W$13 -> 0 | X26: ='9'!$W26*W$13 -> 0 | Y26: =ВЗ!$V26*Y$13 -> 0 | Z26: =ВЗ!$W26*Y$13 -> 0 | AA26: ='ГС без пил 1000м гор'!$V26*AA$13 -> 0 | AB26: ='ГС без пил 1000м гор'!$W26*AA$13 -> 0 | AC26: ='ГС пил 1500м гор'!$V26*AC$13 -> 0 | AD26: ='ГС пил 1500м гор'!$W26*AC$13 -> 0 | AE26: ='ГС без пилот 1500м гор'!$V26*AE$13 -> 0 | AF26: ='ГС без пилот 1500м гор'!$W26*AE$13 -> 0 | AG26: ='ГСЮра без пил МГРП'!$V26*AG$13 -> 0 | AH26: ='ГСЮра без пил МГРП'!$W26*AG$13 -> 0 | AI26: ='ГСЮра пил МСГРП'!$V26*AI$13 -> 0 | AJ26: ='ГСЮра пил МСГРП'!$W26*AI$13 -> 0 | AK26: ='ГСЮра керн ГИС'!$V26*AK$13 -> 0 | AL26: ='ГСЮра керн ГИС'!$W26*AK$13 -> 0 | AM26: =Посл.скв.!$V26*AM$13 -> 0 | AN26: =Посл.скв.!$W26*AM$13 -> 0 | AO26: =AM26+AK26+AI26+AG26+AE26+AC26+AA26+Y26++W26+U26+S26+Q26+M26+O26+K26+I26+G26 -> 0 | AP26: =AN26+AL26+AJ26+AH26+AF26+AD26+AB26+Z26++X26+V26+T26+R26+N26+P26+L26+J26+H26 -> 0
C27: ='Перв. скв '!C27 -> 0 | D27: ='Перв. скв '!D27 -> 0 | E27: ='Перв. скв '!E27 -> ООО "Буровая компания "Евразия" | F27: ='Перв. скв '!F27 -> операция | G27: ='Перв. скв '!$V27*G$13 -> 0 | H27: ='Перв. скв '!$W27*G$13 -> 0 | I27: ='2'!$V27*I$13 -> 0 | J27: ='2'!$W27*I$13 -> 0 | K27: ='3'!$V27*K$13 -> 0 | L27: ='3'!$W27*K$13 -> 0 | M27: ='4'!$V27*M$13 -> 0 | N27: ='4'!$W27*M$13 -> 0 | O27: ='5'!$V27*O$13 -> 0 | P27: ='5'!$W27*O$13 -> 0 | Q27: ='6'!$V27*Q$13 -> 0 | R27: ='6'!$W27*Q$13 -> 0 | S27: ='7'!$V27*S$13 -> 0 | T27: ='7'!$W27*S$13 -> 0 | U27: ='8'!$V27*U$13 -> 0 | V27: ='8'!$W27*U$13 -> 0 | W27: ='9'!$V27*W$13 -> 0 | X27: ='9'!$W27*W$13 -> 0 | Y27: =ВЗ!$V27*Y$13 -> 0 | Z27: =ВЗ!$W27*Y$13 -> 0 | AA27: ='ГС без пил 1000м гор'!$V27*AA$13 -> 0 | AB27: ='ГС без пил 1000м гор'!$W27*AA$13 -> 0 | AC27: ='ГС пил 1500м гор'!$V27*AC$13 -> 0 | AD27: ='ГС пил 1500м гор'!$W27*AC$13 -> 0 | AE27: ='ГС без пилот 1500м гор'!$V27*AE$13 -> 0 | AF27: ='ГС без пилот 1500м гор'!$W27*AE$13 -> 0 | AG27: ='ГСЮра без пил МГРП'!$V27*AG$13 -> 0 | AH27: ='ГСЮра без пил МГРП'!$W27*AG$13 -> 0 | AI27: ='ГСЮра пил МСГРП'!$V27*AI$13 -> 0 | AJ27: ='ГСЮра пил МСГРП'!$W27*AI$13 -> 0 | AK27: ='ГСЮра керн ГИС'!$V27*AK$13 -> 0 | AL27: ='ГСЮра керн ГИС'!$W27*AK$13 -> 0 | AM27: =Посл.скв.!$V27*AM$13 -> 0 | AN27: =Посл.скв.!$W27*AM$13 -> 0 | AO27: =AM27+AK27+AI27+AG27+AE27+AC27+AA27+Y27++W27+U27+S27+Q27+M27+O27+K27+I27+G27 -> 0 | AP27: =AN27+AL27+AJ27+AH27+AF27+AD27+AB27+Z27++X27+V27+T27+R27+N27+P27+L27+J27+H27 -> 0
C28: ='Перв. скв '!C28 -> 0 | D28: ='Перв. скв '!D28 -> 0 | E28: ='Перв. скв '!E28 -> ООО "Буровая компания "Евразия" | F28: ='Перв. скв '!F28 -> операция | G28: ='Перв. скв '!$V28*G$13 -> 0 | H28: ='Перв. скв '!$W28*G$13 -> 0 | I28: ='2'!$V28*I$13 -> 0 | J28: ='2'!$W28*I$13 -> 0 | K28: ='3'!$V28*K$13 -> 0 | L28: ='3'!$W28*K$13 -> 0 | M28: ='4'!$V28*M$13 -> 0 | N28: ='4'!$W28*M$13 -> 0 | O28: ='5'!$V28*O$13 -> 0 | P28: ='5'!$W28*O$13 -> 0 | Q28: ='6'!$V28*Q$13 -> 0 | R28: ='6'!$W28*Q$13 -> 0 | S28: ='7'!$V28*S$13 -> 0 | T28: ='7'!$W28*S$13 -> 0 | U28: ='8'!$V28*U$13 -> 0 | V28: ='8'!$W28*U$13 -> 0 | W28: ='9'!$V28*W$13 -> 0 | X28: ='9'!$W28*W$13 -> 0 | Y28: =ВЗ!$V28*Y$13 -> 0 | Z28: =ВЗ!$W28*Y$13 -> 0 | AA28: ='ГС без пил 1000м гор'!$V28*AA$13 -> 0 | AB28: ='ГС без пил 1000м гор'!$W28*AA$13 -> 0 | AC28: ='ГС пил 1500м гор'!$V28*AC$13 -> 0 | AD28: ='ГС пил 1500м гор'!$W28*AC$13 -> 0 | AE28: ='ГС без пилот 1500м гор'!$V28*AE$13 -> 0 | AF28: ='ГС без пилот 1500м гор'!$W28*AE$13 -> 0 | AG28: ='ГСЮра без пил МГРП'!$V28*AG$13 -> 0 | AH28: ='ГСЮра без пил МГРП'!$W28*AG$13 -> 0 | AI28: ='ГСЮра пил МСГРП'!$V28*AI$13 -> 0 | AJ28: ='ГСЮра пил МСГРП'!$W28*AI$13 -> 0 | AK28: ='ГСЮра керн ГИС'!$V28*AK$13 -> 0 | AL28: ='ГСЮра керн ГИС'!$W28*AK$13 -> 0 | AM28: =Посл.скв.!$V28*AM$13 -> 0 | AN28: =Посл.скв.!$W28*AM$13 -> 0 | AO28: =AM28+AK28+AI28+AG28+AE28+AC28+AA28+Y28++W28+U28+S28+Q28+M28+O28+K28+I28+G28 -> 0 | AP28: =AN28+AL28+AJ28+AH28+AF28+AD28+AB28+Z28++X28+V28+T28+R28+N28+P28+L28+J28+H28 -> 0
C29: ='Перв. скв '!C29 -> Работы связанные со сборкой (монтажем) и подключением БУ, бурового и вспомогательного оборудования | D29: ='Перв. скв '!D29 -> Монтаж БУ | E29: ='Перв. скв '!E29 -> ООО "Буровая компания "Евразия" | F29: ='Перв. скв '!F29 -> операция | G29: ='Перв. скв '!$V29*G$13 -> 0 | H29: ='Перв. скв '!$W29*G$13 -> 0 | I29: ='2'!$V29*I$13 -> 0 | J29: ='2'!$W29*I$13 -> 0 | K29: ='3'!$V29*K$13 -> 0 | L29: ='3'!$W29*K$13 -> 0 | M29: ='4'!$V29*M$13 -> 0 | N29: ='4'!$W29*M$13 -> 0 | O29: ='5'!$V29*O$13 -> 0 | P29: ='5'!$W29*O$13 -> 0 | Q29: ='6'!$V29*Q$13 -> 0 | R29: ='6'!$W29*Q$13 -> 0 | S29: ='7'!$V29*S$13 -> 0 | T29: ='7'!$W29*S$13 -> 0 | U29: ='8'!$V29*U$13 -> 0 | V29: ='8'!$W29*U$13 -> 0 | W29: ='9'!$V29*W$13 -> 0 | X29: ='9'!$W29*W$13 -> 0 | Y29: =ВЗ!$V29*Y$13 -> 0 | Z29: =ВЗ!$W29*Y$13 -> 0 | AA29: ='ГС без пил 1000м гор'!$V29*AA$13 -> 0 | AB29: ='ГС без пил 1000м гор'!$W29*AA$13 -> 0 | AC29: ='ГС пил 1500м гор'!$V29*AC$13 -> 0 | AD29: ='ГС пил 1500м гор'!$W29*AC$13 -> 0 | AE29: ='ГС без пилот 1500м гор'!$V29*AE$13 -> 0 | AF29: ='ГС без пилот 1500м гор'!$W29*AE$13 -> 0 | AG29: ='ГСЮра без пил МГРП'!$V29*AG$13 -> 0 | AH29: ='ГСЮра без пил МГРП'!$W29*AG$13 -> 0 | AI29: ='ГСЮра пил МСГРП'!$V29*AI$13 -> 0 | AJ29: ='ГСЮра пил МСГРП'!$W29*AI$13 -> 0 | AK29: ='ГСЮра керн ГИС'!$V29*AK$13 -> 0 | AL29: ='ГСЮра керн ГИС'!$W29*AK$13 -> 0 | AM29: =Посл.скв.!$V29*AM$13 -> 0 | AN29: =Посл.скв.!$W29*AM$13 -> 0 | AO29: =AM29+AK29+AI29+AG29+AE29+AC29+AA29+Y29++W29+U29+S29+Q29+M29+O29+K29+I29+G29 -> 0 | AP29: =AN29+AL29+AJ29+AH29+AF29+AD29+AB29+Z29++X29+V29+T29+R29+N29+P29+L29+J29+H29 -> 0
C30: ='Перв. скв '!C30 -> 0 | D30: ='Перв. скв '!D30 -> - монтаж БУ | E30: ='Перв. скв '!E30 -> ООО "Буровая компания "Евразия" | F30: ='Перв. скв '!F30 -> операция | G30: ='Перв. скв '!$V30*G$13 -> 0 | H30: ='Перв. скв '!$W30*G$13 -> 0 | I30: ='2'!$V30*I$13 -> 0 | J30: ='2'!$W30*I$13 -> 0 | K30: ='3'!$V30*K$13 -> 0 | L30: ='3'!$W30*K$13 -> 0 | M30: ='4'!$V30*M$13 -> 0 | N30: ='4'!$W30*M$13 -> 0 | O30: ='5'!$V30*O$13 -> 0 | P30: ='5'!$W30*O$13 -> 0 | Q30: ='6'!$V30*Q$13 -> 0 | R30: ='6'!$W30*Q$13 -> 0 | S30: ='7'!$V30*S$13 -> 0 | T30: ='7'!$W30*S$13 -> 0 | U30: ='8'!$V30*U$13 -> 0 | V30: ='8'!$W30*U$13 -> 0 | W30: ='9'!$V30*W$13 -> 0 | X30: ='9'!$W30*W$13 -> 0 | Y30: =ВЗ!$V30*Y$13 -> 0 | Z30: =ВЗ!$W30*Y$13 -> 0 | AA30: ='ГС без пил 1000м гор'!$V30*AA$13 -> 0 | AB30: ='ГС без пил 1000м гор'!$W30*AA$13 -> 0 | AC30: ='ГС пил 1500м гор'!$V30*AC$13 -> 0 | AD30: ='ГС пил 1500м гор'!$W30*AC$13 -> 0 | AE30: ='ГС без пилот 1500м гор'!$V30*AE$13 -> 0 | AF30: ='ГС без пилот 1500м гор'!$W30*AE$13 -> 0 | AG30: ='ГСЮра без пил МГРП'!$V30*AG$13 -> 0 | AH30: ='ГСЮра без пил МГРП'!$W30*AG$13 -> 0 | AI30: ='ГСЮра пил МСГРП'!$V30*AI$13 -> 0 | AJ30: ='ГСЮра пил МСГРП'!$W30*AI$13 -> 0 | AK30: ='ГСЮра керн ГИС'!$V30*AK$13 -> 0 | AL30: ='ГСЮра керн ГИС'!$W30*AK$13 -> 0 | AM30: =Посл.скв.!$V30*AM$13 -> 0 | AN30: =Посл.скв.!$W30*AM$13 -> 0 | AO30: =AM30+AK30+AI30+AG30+AE30+AC30+AA30+Y30++W30+U30+S30+Q30+M30+O30+K30+I30+G30 -> 0 | AP30: =AN30+AL30+AJ30+AH30+AF30+AD30+AB30+Z30++X30+V30+T30+R30+N30+P30+L30+J30+H30 -> 0
C31: ='Перв. скв '!C31 -> 0 | D31: ='Перв. скв '!D31 -> - монтаж АвИЭС | E31: ='Перв. скв '!E31 -> ООО "Буровая компания "Евразия" | F31: ='Перв. скв '!F31 -> операция | G31: ='Перв. скв '!$V31*G$13 -> 0 | H31: ='Перв. скв '!$W31*G$13 -> 0 | I31: ='2'!$V31*I$13 -> 0 | J31: ='2'!$W31*I$13 -> 0 | K31: ='3'!$V31*K$13 -> 0 | L31: ='3'!$W31*K$13 -> 0 | M31: ='4'!$V31*M$13 -> 0 | N31: ='4'!$W31*M$13 -> 0 | O31: ='5'!$V31*O$13 -> 0 | P31: ='5'!$W31*O$13 -> 0 | Q31: ='6'!$V31*Q$13 -> 0 | R31: ='6'!$W31*Q$13 -> 0 | S31: ='7'!$V31*S$13 -> 0 | T31: ='7'!$W31*S$13 -> 0 | U31: ='8'!$V31*U$13 -> 0 | V31: ='8'!$W31*U$13 -> 0 | W31: ='9'!$V31*W$13 -> 0 | X31: ='9'!$W31*W$13 -> 0 | Y31: =ВЗ!$V31*Y$13 -> 0 | Z31: =ВЗ!$W31*Y$13 -> 0 | AA31: ='ГС без пил 1000м гор'!$V31*AA$13 -> 0 | AB31: ='ГС без пил 1000м гор'!$W31*AA$13 -> 0 | AC31: ='ГС пил 1500м гор'!$V31*AC$13 -> 0 | AD31: ='ГС пил 1500м гор'!$W31*AC$13 -> 0 | AE31: ='ГС без пилот 1500м гор'!$V31*AE$13 -> 0 | AF31: ='ГС без пилот 1500м гор'!$W31*AE$13 -> 0 | AG31: ='ГСЮра без пил МГРП'!$V31*AG$13 -> 0 | AH31: ='ГСЮра без пил МГРП'!$W31*AG$13 -> 0 | AI31: ='ГСЮра пил МСГРП'!$V31*AI$13 -> 0 | AJ31: ='ГСЮра пил МСГРП'!$W31*AI$13 -> 0 | AK31: ='ГСЮра керн ГИС'!$V31*AK$13 -> 0 | AL31: ='ГСЮра керн ГИС'!$W31*AK$13 -> 0 | AM31: =Посл.скв.!$V31*AM$13 -> 0 | AN31: =Посл.скв.!$W31*AM$13 -> 0 | AO31: =AM31+AK31+AI31+AG31+AE31+AC31+AA31+Y31++W31+U31+S31+Q31+M31+O31+K31+I31+G31 -> 0 | AP31: =AN31+AL31+AJ31+AH31+AF31+AD31+AB31+Z31++X31+V31+T31+R31+N31+P31+L31+J31+H31 -> 0
... C35: ='Перв. скв '!C35 -> 0 | D35: ='Перв. скв '!D35 -> 0 | E35: ='Перв. скв '!E35 -> ООО "Буровая компания "Евразия" | F35: ='Перв. скв '!F35 -> операция | G35: ='Перв. скв '!$V35*G$13 -> 0 | H35: ='Перв. скв '!$W35*G$13 -> 0 | I35: ='2'!$V35*I$13 -> 0 | J35: ='2'!$W35*I$13 -> 0 | K35: ='3'!$V35*K$13 -> 0 | L35: ='3'!$W35*K$13 -> 0 | M35: ='4'!$V35*M$13 -> 0 | N35: ='4'!$W35*M$13 -> 0 | O35: ='5'!$V35*O$13 -> 0 | P35: ='5'!$W35*O$13 -> 0 | Q35: ='6'!$V35*Q$13 -> 0 | R35: ='6'!$W35*Q$13 -> 0 | S35: ='7'!$V35*S$13 -> 0 | T35: ='7'!$W35*S$13 -> 0 | U35: ='8'!$V35*U$13 -> 0 | V35: ='8'!$W35*U$13 -> 0 | W35: ='9'!$V35*W$13 -> 0 | X35: ='9'!$W35*W$13 -> 0 | Y35: =ВЗ!$V35*Y$13 -> 0 | Z35: =ВЗ!$W35*Y$13 -> 0 | AA35: ='ГС без пил 1000м гор'!$V35*AA$13 -> 0 | AB35: ='ГС без пил 1000м гор'!$W35*AA$13 -> 0 | AC35: ='ГС пил 1500м гор'!$V35*AC$13 -> 0 | AD35: ='ГС пил 1500м гор'!$W35*AC$13 -> 0 | AE35: ='ГС без пилот 1500м гор'!$V35*AE$13 -> 0 | AF35: ='ГС без пилот 1500м гор'!$W35*AE$13 -> 0 | AG35: ='ГСЮра без пил МГРП'!$V35*AG$13 -> 0 | AH35: ='ГСЮра без пил МГРП'!$W35*AG$13 -> 0 | AI35: ='ГСЮра пил МСГРП'!$V35*AI$13 -> 0 | AJ35: ='ГСЮра пил МСГРП'!$W35*AI$13 -> 0 | AK35: ='ГСЮра керн ГИС'!$V35*AK$13 -> 0 | AL35: ='ГСЮра керн ГИС'!$W35*AK$13 -> 0 | AM35: =Посл.скв.!$V35*AM$13 -> 0 | AN35: =Посл.скв.!$W35*AM$13 -> 0 | AO35: =AM35+AK35+AI35+AG35+AE35+AC35+AA35+Y35++W35+U35+S35+Q35+M35+O35+K35+I35+G35 -> 0 | AP35: =AN35+AL35+AJ35+AH35+AF35+AD35+AB35+Z35++X35+V35+T35+R35+N35+P35+L35+J35+H35 -> 0
D36: ='Перв. скв '!D36 -> 0 | E36: ='Перв. скв '!E36 -> ООО "Буровая компания "Евразия" | F36: ='Перв. скв '!F36 -> операция | G36: ='Перв. скв '!$V36*G$13 -> 0 | H36: ='Перв. скв '!$W36*G$13 -> 0 | I36: ='2'!$V36*I$13 -> 0 | J36: ='2'!$W36*I$13 -> 0 | K36: ='3'!$V36*K$13 -> 0 | L36: ='3'!$W36*K$13 -> 0 | M36: ='4'!$V36*M$13 -> 0 | N36: ='4'!$W36*M$13 -> 0 | O36: ='5'!$V36*O$13 -> 0 | P36: ='5'!$W36*O$13 -> 0 | Q36: ='6'!$V36*Q$13 -> 0 | R36: ='6'!$W36*Q$13 -> 0 | S36: ='7'!$V36*S$13 -> 0 | T36: ='7'!$W36*S$13 -> 0 | U36: ='8'!$V36*U$13 -> 0 | V36: ='8'!$W36*U$13 -> 0 | W36: ='9'!$V36*W$13 -> 0 | X36: ='9'!$W36*W$13 -> 0 | Y36: =ВЗ!$V36*Y$13 -> 0 | Z36: =ВЗ!$W36*Y$13 -> 0 | AA36: ='ГС без пил 1000м гор'!$V36*AA$13 -> 0 | AB36: ='ГС без пил 1000м гор'!$W36*AA$13 -> 0 | AC36: ='ГС пил 1500м гор'!$V36*AC$13 -> 0 | AD36: ='ГС пил 1500м гор'!$W36*AC$13 -> 0 | AE36: ='ГС без пилот 1500м гор'!$V36*AE$13 -> 0 | AF36: ='ГС без пилот 1500м гор'!$W36*AE$13 -> 0 | AG36: ='ГСЮра без пил МГРП'!$V36*AG$13 -> 0 | AH36: ='ГСЮра без пил МГРП'!$W36*AG$13 -> 0 | AI36: ='ГСЮра пил МСГРП'!$V36*AI$13 -> 0 | AJ36: ='ГСЮра пил МСГРП'!$W36*AI$13 -> 0 | AK36: ='ГСЮра керн ГИС'!$V36*AK$13 -> 0 | AL36: ='ГСЮра керн ГИС'!$W36*AK$13 -> 0 | AM36: =Посл.скв.!$V36*AM$13 -> 0 | AN36: =Посл.скв.!$W36*AM$13 -> 0 | AO36: =AM36+AK36+AI36+AG36+AE36+AC36+AA36+Y36++W36+U36+S36+Q36+M36+O36+K36+I36+G36 -> 0 | AP36: =AN36+AL36+AJ36+AH36+AF36+AD36+AB36+Z36++X36+V36+T36+R36+N36+P36+L36+J36+H36 -> 0
C37: ='Перв. скв '!C37 -> 0 | D37: ='Перв. скв '!D37 -> 0 | E37: ='Перв. скв '!E37 -> ООО "Буровая компания "Евразия" | F37: ='Перв. скв '!F37 -> операция | G37: ='Перв. скв '!$V37*G$13 -> 0 | H37: ='Перв. скв '!$W37*G$13 -> 0 | I37: ='2'!$V37*I$13 -> 0 | J37: ='2'!$W37*I$13 -> 0 | K37: ='3'!$V37*K$13 -> 0 | L37: ='3'!$W37*K$13 -> 0 | M37: ='4'!$V37*M$13 -> 0 | N37: ='4'!$W37*M$13 -> 0 | O37: ='5'!$V37*O$13 -> 0 | P37: ='5'!$W37*O$13 -> 0 | Q37: ='6'!$V37*Q$13 -> 0 | R37: ='6'!$W37*Q$13 -> 0 | S37: ='7'!$V37*S$13 -> 0 | T37: ='7'!$W37*S$13 -> 0 | U37: ='8'!$V37*U$13 -> 0 | V37: ='8'!$W37*U$13 -> 0 | W37: ='9'!$V37*W$13 -> 0 | X37: ='9'!$W37*W$13 -> 0 | Y37: =ВЗ!$V37*Y$13 -> 0 | Z37: =ВЗ!$W37*Y$13 -> 0 | AA37: ='ГС без пил 1000м гор'!$V37*AA$13 -> 0 | AB37: ='ГС без пил 1000м гор'!$W37*AA$13 -> 0 | AC37: ='ГС пил 1500м гор'!$V37*AC$13 -> 0 | AD37: ='ГС пил 1500м гор'!$W37*AC$13 -> 0 | AE37: ='ГС без пилот 1500м гор'!$V37*AE$13 -> 0 | AF37: ='ГС без пилот 1500м гор'!$W37*AE$13 -> 0 | AG37: ='ГСЮра без пил МГРП'!$V37*AG$13 -> 0 | AH37: ='ГСЮра без пил МГРП'!$W37*AG$13 -> 0 | AI37: ='ГСЮра пил МСГРП'!$V37*AI$13 -> 0 | AJ37: ='ГСЮра пил МСГРП'!$W37*AI$13 -> 0 | AK37: ='ГСЮра керн ГИС'!$V37*AK$13 -> 0 | AL37: ='ГСЮра керн ГИС'!$W37*AK$13 -> 0 | AM37: =Посл.скв.!$V37*AM$13 -> 0 | AN37: =Посл.скв.!$W37*AM$13 -> 0 | AO37: =AM37+AK37+AI37+AG37+AE37+AC37+AA37+Y37++W37+U37+S37+Q37+M37+O37+K37+I37+G37 -> 0 | AP37: =AN37+AL37+AJ37+AH37+AF37+AD37+AB37+Z37++X37+V37+T37+R37+N37+P37+L37+J37+H37 -> 0
C38: ='Перв. скв '!C38 -> 0 | D38: ='Перв. скв '!D38 -> 0 | E38: ='Перв. скв '!E38 -> ООО "Буровая компания "Евразия" | F38: ='Перв. скв '!F38 -> операция | G38: ='Перв. скв '!$V38*G$13 -> 0 | H38: ='Перв. скв '!$W38*G$13 -> 0 | I38: ='2'!$V38*I$13 -> 0 | J38: ='2'!$W38*I$13 -> 0 | K38: ='3'!$V38*K$13 -> 0 | L38: ='3'!$W38*K$13 -> 0 | M38: ='4'!$V38*M$13 -> 0 | N38: ='4'!$W38*M$13 -> 0 | O38: ='5'!$V38*O$13 -> 0 | P38: ='5'!$W38*O$13 -> 0 | Q38: ='6'!$V38*Q$13 -> 0 | R38: ='6'!$W38*Q$13 -> 0 | S38: ='7'!$V38*S$13 -> 0 | T38: ='7'!$W38*S$13 -> 0 | U38: ='8'!$V38*U$13 -> 0 | V38: ='8'!$W38*U$13 -> 0 | W38: ='9'!$V38*W$13 -> 0 | X38: ='9'!$W38*W$13 -> 0 | Y38: =ВЗ!$V38*Y$13 -> 0 | Z38: =ВЗ!$W38*Y$13 -> 0 | AA38: ='ГС без пил 1000м гор'!$V38*AA$13 -> 0 | AB38: ='ГС без пил 1000м гор'!$W38*AA$13 -> 0 | AC38: ='ГС пил 1500м гор'!$V38*AC$13 -> 0 | AD38: ='ГС пил 1500м гор'!$W38*AC$13 -> 0 | AE38: ='ГС без пилот 1500м гор'!$V38*AE$13 -> 0 | AF38: ='ГС без пилот 1500м гор'!$W38*AE$13 -> 0 | AG38: ='ГСЮра без пил МГРП'!$V38*AG$13 -> 0 | AH38: ='ГСЮра без пил МГРП'!$W38*AG$13 -> 0 | AI38: ='ГСЮра пил МСГРП'!$V38*AI$13 -> 0 | AJ38: ='ГСЮра пил МСГРП'!$W38*AI$13 -> 0 | AK38: ='ГСЮра керн ГИС'!$V38*AK$13 -> 0 | AL38: ='ГСЮра керн ГИС'!$W38*AK$13 -> 0 | AM38: =Посл.скв.!$V38*AM$13 -> 0 | AN38: =Посл.скв.!$W38*AM$13 -> 0 | AO38: =AM38+AK38+AI38+AG38+AE38+AC38+AA38+Y38++W38+U38+S38+Q38+M38+O38+K38+I38+G38 -> 0 | AP38: =AN38+AL38+AJ38+AH38+AF38+AD38+AB38+Z38++X38+V38+T38+R38+N38+P38+L38+J38+H38 -> 0
C39: ='Перв. скв '!C39 -> Работы, свзянные с передвижкой БУ между скважинами на кустовой площадке | D39: ='Перв. скв '!D39 -> Передвижка 5 м. | E39: ='Перв. скв '!E39 -> ООО "Буровая компания "Евразия" | F39: ='Перв. скв '!F39 -> операция | G39: ='Перв. скв '!$V39*G$13 -> 0 | H39: ='Перв. скв '!$W39*G$13 -> 0 | I39: ='2'!$V39*I$13 -> 0 | J39: ='2'!$W39*I$13 -> 0 | K39: ='3'!$V39*K$13 -> 0 | L39: ='3'!$W39*K$13 -> 0 | M39: ='4'!$V39*M$13 -> 0 | N39: ='4'!$W39*M$13 -> 0 | O39: ='5'!$V39*O$13 -> 0 | P39: ='5'!$W39*O$13 -> 0 | Q39: ='6'!$V39*Q$13 -> 0 | R39: ='6'!$W39*Q$13 -> 0 | S39: ='7'!$V39*S$13 -> 0 | T39: ='7'!$W39*S$13 -> 0 | U39: ='8'!$V39*U$13 -> 0 | V39: ='8'!$W39*U$13 -> 0 | W39: ='9'!$V39*W$13 -> 0 | X39: ='9'!$W39*W$13 -> 0 | Y39: =ВЗ!$V39*Y$13 -> 0 | Z39: =ВЗ!$W39*Y$13 -> 0 | AA39: ='ГС без пил 1000м гор'!$V39*AA$13 -> 0 | AB39: ='ГС без пил 1000м гор'!$W39*AA$13 -> 0 | AC39: ='ГС пил 1500м гор'!$V39*AC$13 -> 0 | AD39: ='ГС пил 1500м гор'!$W39*AC$13 -> 0 | AE39: ='ГС без пилот 1500м гор'!$V39*AE$13 -> 0 | AF39: ='ГС без пилот 1500м гор'!$W39*AE$13 -> 0 | AG39: ='ГСЮра без пил МГРП'!$V39*AG$13 -> 0 | AH39: ='ГСЮра без пил МГРП'!$W39*AG$13 -> 0 | AI39: ='ГСЮра пил МСГРП'!$V39*AI$13 -> 0 | AJ39: ='ГСЮра пил МСГРП'!$W39*AI$13 -> 0 | AK39: ='ГСЮра керн ГИС'!$V39*AK$13 -> 0 | AL39: ='ГСЮра керн ГИС'!$W39*AK$13 -> 0 | AM39: =Посл.скв.!$V39*AM$13 -> 0 | AN39: =Посл.скв.!$W39*AM$13 -> 0 | AO39: =AM39+AK39+AI39+AG39+AE39+AC39+AA39+Y39++W39+U39+S39+Q39+M39+O39+K39+I39+G39 -> 0 | AP39: =AN39+AL39+AJ39+AH39+AF39+AD39+AB39+Z39++X39+V39+T39+R39+N39+P39+L39+J39+H39 -> 0
C40: ='Перв. скв '!C40 -> 0 | D40: ='Перв. скв '!D40 -> Передвижка 9 м. | E40: ='Перв. скв '!E40 -> ООО "Буровая компания "Евразия" | F40: ='Перв. скв '!F40 -> операция | G40: ='Перв. скв '!$V40*G$13 -> 0 | H40: ='Перв. скв '!$W40*G$13 -> 0 | I40: ='2'!$V40*I$13 -> 0 | J40: ='2'!$W40*I$13 -> 0 | K40: ='3'!$V40*K$13 -> 0 | L40: ='3'!$W40*K$13 -> 0 | M40: ='4'!$V40*M$13 -> 0 | N40: ='4'!$W40*M$13 -> 0 | O40: ='5'!$V40*O$13 -> 0 | P40: ='5'!$W40*O$13 -> 0 | Q40: ='6'!$V40*Q$13 -> 0 | R40: ='6'!$W40*Q$13 -> 0 | S40: ='7'!$V40*S$13 -> 0 | T40: ='7'!$W40*S$13 -> 0 | U40: ='8'!$V40*U$13 -> 0 | V40: ='8'!$W40*U$13 -> 0 | W40: ='9'!$V40*W$13 -> 0 | X40: ='9'!$W40*W$13 -> 0 | Y40: =ВЗ!$V40*Y$13 -> 0 | Z40: =ВЗ!$W40*Y$13 -> 0 | AA40: ='ГС без пил 1000м гор'!$V40*AA$13 -> 0 | AB40: ='ГС без пил 1000м гор'!$W40*AA$13 -> 0 | AC40: ='ГС пил 1500м гор'!$V40*AC$13 -> 0 | AD40: ='ГС пил 1500м гор'!$W40*AC$13 -> 0 | AE40: ='ГС без пилот 1500м гор'!$V40*AE$13 -> 0 | AF40: ='ГС без пилот 1500м гор'!$W40*AE$13 -> 0 | AG40: ='ГСЮра без пил МГРП'!$V40*AG$13 -> 0 | AH40: ='ГСЮра без пил МГРП'!$W40*AG$13 -> 0 | AI40: ='ГСЮра пил МСГРП'!$V40*AI$13 -> 0 | AJ40: ='ГСЮра пил МСГРП'!$W40*AI$13 -> 0 | AK40: ='ГСЮра керн ГИС'!$V40*AK$13 -> 0 | AL40: ='ГСЮра керн ГИС'!$W40*AK$13 -> 0 | AM40: =Посл.скв.!$V40*AM$13 -> 0 | AN40: =Посл.скв.!$W40*AM$13 -> 0 | AO40: =AM40+AK40+AI40+AG40+AE40+AC40+AA40+Y40++W40+U40+S40+Q40+M40+O40+K40+I40+G40 -> 0 | AP40: =AN40+AL40+AJ40+AH40+AF40+AD40+AB40+Z40++X40+V40+T40+R40+N40+P40+L40+J40+H40 -> 0
C41: ='Перв. скв '!C41 -> 0 | D41: ='Перв. скв '!D41 -> Передвижка 18 м. | E41: ='Перв. скв '!E41 -> ООО "Буровая компания "Евразия" | F41: ='Перв. скв '!F41 -> операция | G41: ='Перв. скв '!$V41*G$13 -> 0 | H41: ='Перв. скв '!$W41*G$13 -> 0 | I41: ='2'!$V41*I$13 -> 0 | J41: ='2'!$W41*I$13 -> 0 | K41: ='3'!$V41*K$13 -> 0 | L41: ='3'!$W41*K$13 -> 0 | M41: ='4'!$V41*M$13 -> 0 | N41: ='4'!$W41*M$13 -> 0 | O41: ='5'!$V41*O$13 -> 0 | P41: ='5'!$W41*O$13 -> 0 | Q41: ='6'!$V41*Q$13 -> 0 | R41: ='6'!$W41*Q$13 -> 0 | S41: ='7'!$V41*S$13 -> 0 | T41: ='7'!$W41*S$13 -> 0 | U41: ='8'!$V41*U$13 -> 0 | V41: ='8'!$W41*U$13 -> 0 | W41: ='9'!$V41*W$13 -> 0 | X41: ='9'!$W41*W$13 -> 0 | Y41: =ВЗ!$V41*Y$13 -> 2 | Z41: =ВЗ!$W41*Y$13 -> 2970233.4 | AA41: ='ГС без пил 1000м гор'!$V41*AA$13 -> 8 | AB41: ='ГС без пил 1000м гор'!$W41*AA$13 -> 15141530 | AC41: ='ГС пил 1500м гор'!$V41*AC$13 -> 0 | AD41: ='ГС пил 1500м гор'!$W41*AC$13 -> 0 | AE41: ='ГС без пилот 1500м гор'!$V41*AE$13 -> 6 | AF41: ='ГС без пилот 1500м гор'!$W41*AE$13 -> 9637869.5 | AG41: ='ГСЮра без пил МГРП'!$V41*AG$13 -> 9 | AH41: ='ГСЮра без пил МГРП'!$W41*AG$13 -> 14109099 | AI41: ='ГСЮра пил МСГРП'!$V41*AI$13 -> 4 | AJ41: ='ГСЮра пил МСГРП'!$W41*AI$13 -> 6243114.8 | AK41: ='ГСЮра керн ГИС'!$V41*AK$13 -> 1 | AL41: ='ГСЮра керн ГИС'!$W41*AK$13 -> 1540081.9 | AM41: =Посл.скв.!$V41*AM$13 -> 0 | AN41: =Посл.скв.!$W41*AM$13 -> 0 | AO41: =AM41+AK41+AI41+AG41+AE41+AC41+AA41+Y41++W41+U41+S41+Q41+M41+O41+K41+I41+G41 -> 30 | AP41: =AN41+AL41+AJ41+AH41+AF41+AD41+AB41+Z41++X41+V41+T41+R41+N41+P41+L41+J41+H41 -> 49641928
C42: ='Перв. скв '!C42 -> 0 | D42: ='Перв. скв '!D42 -> Передвижка 25 м. | E42: ='Перв. скв '!E42 -> ООО "Буровая компания "Евразия" | F42: ='Перв. скв '!F42 -> операция | G42: ='Перв. скв '!$V42*G$13 -> 0 | H42: ='Перв. скв '!$W42*G$13 -> 0 | I42: ='2'!$V42*I$13 -> 0 | J42: ='2'!$W42*I$13 -> 0 | K42: ='3'!$V42*K$13 -> 0 | L42: ='3'!$W42*K$13 -> 0 | M42: ='4'!$V42*M$13 -> 0 | N42: ='4'!$W42*M$13 -> 0 | O42: ='5'!$V42*O$13 -> 0 | P42: ='5'!$W42*O$13 -> 0 | Q42: ='6'!$V42*Q$13 -> 0 | R42: ='6'!$W42*Q$13 -> 0 | S42: ='7'!$V42*S$13 -> 0 | T42: ='7'!$W42*S$13 -> 0 | U42: ='8'!$V42*U$13 -> 0 | V42: ='8'!$W42*U$13 -> 0 | W42: ='9'!$V42*W$13 -> 0 | X42: ='9'!$W42*W$13 -> 0 | Y42: =ВЗ!$V42*Y$13 -> 0 | Z42: =ВЗ!$W42*Y$13 -> 0 | AA42: ='ГС без пил 1000м гор'!$V42*AA$13 -> 0 | AB42: ='ГС без пил 1000м гор'!$W42*AA$13 -> 0 | AC42: ='ГС пил 1500м гор'!$V42*AC$13 -> 0 | AD42: ='ГС пил 1500м гор'!$W42*AC$13 -> 0 | AE42: ='ГС без пилот 1500м гор'!$V42*AE$13 -> 0 | AF42: ='ГС без пилот 1500м гор'!$W42*AE$13 -> 0 | AG42: ='ГСЮра без пил МГРП'!$V42*AG$13 -> 0 | AH42: ='ГСЮра без пил МГРП'!$W42*AG$13 -> 0 | AI42: ='ГСЮра пил МСГРП'!$V42*AI$13 -> 0 | AJ42: ='ГСЮра пил МСГРП'!$W42*AI$13 -> 0 | AK42: ='ГСЮра керн ГИС'!$V42*AK$13 -> 0 | AL42: ='ГСЮра керн ГИС'!$W42*AK$13 -> 0 | AM42: =Посл.скв.!$V42*AM$13 -> 0 | AN42: =Посл.скв.!$W42*AM$13 -> 0 | AO42: =AM42+AK42+AI42+AG42+AE42+AC42+AA42+Y42++W42+U42+S42+Q42+M42+O42+K42+I42+G42 -> 0 | AP42: =AN42+AL42+AJ42+AH42+AF42+AD42+AB42+Z42++X42+V42+T42+R42+N42+P42+L42+J42+H42 -> 0
C43: ='Перв. скв '!C43 -> 0 | D43: ='Перв. скв '!D43 -> Передвижка 75 м. | E43: ='Перв. скв '!E43 -> ООО "Буровая компания "Евразия" | F43: ='Перв. скв '!F43 -> операция | G43: ='Перв. скв '!$V43*G$13 -> 0 | H43: ='Перв. скв '!$W43*G$13 -> 0 | I43: ='2'!$V43*I$13 -> 0 | J43: ='2'!$W43*I$13 -> 0 | K43: ='3'!$V43*K$13 -> 0 | L43: ='3'!$W43*K$13 -> 0 | M43: ='4'!$V43*M$13 -> 0 | N43: ='4'!$W43*M$13 -> 0 | O43: ='5'!$V43*O$13 -> 0 | P43: ='5'!$W43*O$13 -> 0 | Q43: ='6'!$V43*Q$13 -> 0 | R43: ='6'!$W43*Q$13 -> 0 | S43: ='7'!$V43*S$13 -> 0 | T43: ='7'!$W43*S$13 -> 0 | U43: ='8'!$V43*U$13 -> 0 | V43: ='8'!$W43*U$13 -> 0 | W43: ='9'!$V43*W$13 -> 0 | X43: ='9'!$W43*W$13 -> 0 | Y43: =ВЗ!$V43*Y$13 -> 0 | Z43: =ВЗ!$W43*Y$13 -> 0 | AA43: ='ГС без пил 1000м гор'!$V43*AA$13 -> 0 | AB43: ='ГС без пил 1000м гор'!$W43*AA$13 -> 0 | AC43: ='ГС пил 1500м гор'!$V43*AC$13 -> 0 | AD43: ='ГС пил 1500м гор'!$W43*AC$13 -> 0 | AE43: ='ГС без пилот 1500м гор'!$V43*AE$13 -> 0 | AF43: ='ГС без пилот 1500м гор'!$W43*AE$13 -> 0 | AG43: ='ГСЮра без пил МГРП'!$V43*AG$13 -> 0 | AH43: ='ГСЮра без пил МГРП'!$W43*AG$13 -> 0 | AI43: ='ГСЮра пил МСГРП'!$V43*AI$13 -> 0 | AJ43: ='ГСЮра пил МСГРП'!$W43*AI$13 -> 0 | AK43: ='ГСЮра керн ГИС'!$V43*AK$13 -> 0 | AL43: ='ГСЮра керн ГИС'!$W43*AK$13 -> 0 | AM43: =Посл.скв.!$V43*AM$13 -> 0 | AN43: =Посл.скв.!$W43*AM$13 -> 0 | AO43: =AM43+AK43+AI43+AG43+AE43+AC43+AA43+Y43++W43+U43+S43+Q43+M43+O43+K43+I43+G43 -> 0 | AP43: =AN43+AL43+AJ43+AH43+AF43+AD43+AB43+Z43++X43+V43+T43+R43+N43+P43+L43+J43+H43 -> 0
C44: ='Перв. скв '!C44 -> 0 | D44: ='Перв. скв '!D44 -> Передвижка нестандартная | E44: ='Перв. скв '!E44 -> ООО "Буровая компания "Евразия" | F44: ='Перв. скв '!F44 -> операция | G44: ='Перв. скв '!$V44*G$13 -> 0 | H44: ='Перв. скв '!$W44*G$13 -> 0 | I44: ='2'!$V44*I$13 -> 0 | J44: ='2'!$W44*I$13 -> 0 | K44: ='3'!$V44*K$13 -> 0 | L44: ='3'!$W44*K$13 -> 0 | M44: ='4'!$V44*M$13 -> 0 | N44: ='4'!$W44*M$13 -> 0 | O44: ='5'!$V44*O$13 -> 0 | P44: ='5'!$W44*O$13 -> 0 | Q44: ='6'!$V44*Q$13 -> 0 | R44: ='6'!$W44*Q$13 -> 0 | S44: ='7'!$V44*S$13 -> 0 | T44: ='7'!$W44*S$13 -> 0 | U44: ='8'!$V44*U$13 -> 0 | V44: ='8'!$W44*U$13 -> 0 | W44: ='9'!$V44*W$13 -> 0 | X44: ='9'!$W44*W$13 -> 0 | Y44: =ВЗ!$V44*Y$13 -> 0 | Z44: =ВЗ!$W44*Y$13 -> 0 | AA44: ='ГС без пил 1000м гор'!$V44*AA$13 -> 0 | AB44: ='ГС без пил 1000м гор'!$W44*AA$13 -> 0 | AC44: ='ГС пил 1500м гор'!$V44*AC$13 -> 0 | AD44: ='ГС пил 1500м гор'!$W44*AC$13 -> 0 | AE44: ='ГС без пилот 1500м гор'!$V44*AE$13 -> 0 | AF44: ='ГС без пилот 1500м гор'!$W44*AE$13 -> 0 | AG44: ='ГСЮра без пил МГРП'!$V44*AG$13 -> 0 | AH44: ='ГСЮра без пил МГРП'!$W44*AG$13 -> 0 | AI44: ='ГСЮра пил МСГРП'!$V44*AI$13 -> 0 | AJ44: ='ГСЮра пил МСГРП'!$W44*AI$13 -> 0 | AK44: ='ГСЮра керн ГИС'!$V44*AK$13 -> 0 | AL44: ='ГСЮра керн ГИС'!$W44*AK$13 -> 0 | AM44: =Посл.скв.!$V44*AM$13 -> 0 | AN44: =Посл.скв.!$W44*AM$13 -> 0 | AO44: =AM44+AK44+AI44+AG44+AE44+AC44+AA44+Y44++W44+U44+S44+Q44+M44+O44+K44+I44+G44 -> 0 | AP44: =AN44+AL44+AJ44+AH44+AF44+AD44+AB44+Z44++X44+V44+T44+R44+N44+P44+L44+J44+H44 -> 0
C45: ='Перв. скв '!C45 -> Работы связанные с демонтажем БУ, бурового и вспомогательного оборудования | D45: ='Перв. скв '!D45 -> Демонтаж БУ | E45: ='Перв. скв '!E45 -> ООО "Буровая компания "Евразия" | F45: ='Перв. скв '!F45 -> операция | G45: ='Перв. скв '!$V45*G$13 -> 0 | H45: ='Перв. скв '!$W45*G$13 -> 0 | I45: ='2'!$V45*I$13 -> 0 | J45: ='2'!$W45*I$13 -> 0 | K45: ='3'!$V45*K$13 -> 0 | L45: ='3'!$W45*K$13 -> 0 | M45: ='4'!$V45*M$13 -> 0 | N45: ='4'!$W45*M$13 -> 0 | O45: ='5'!$V45*O$13 -> 0 | P45: ='5'!$W45*O$13 -> 0 | Q45: ='6'!$V45*Q$13 -> 0 | R45: ='6'!$W45*Q$13 -> 0 | S45: ='7'!$V45*S$13 -> 0 | T45: ='7'!$W45*S$13 -> 0 | U45: ='8'!$V45*U$13 -> 0 | V45: ='8'!$W45*U$13 -> 0 | W45: ='9'!$V45*W$13 -> 0 | X45: ='9'!$W45*W$13 -> 0 | Y45: =ВЗ!$V45*Y$13 -> 0 | Z45: =ВЗ!$W45*Y$13 -> 0 | AA45: ='ГС без пил 1000м гор'!$V45*AA$13 -> 0 | AB45: ='ГС без пил 1000м гор'!$W45*AA$13 -> 0 | AC45: ='ГС пил 1500м гор'!$V45*AC$13 -> 0 | AD45: ='ГС пил 1500м гор'!$W45*AC$13 -> 0 | AE45: ='ГС без пилот 1500м гор'!$V45*AE$13 -> 0 | AF45: ='ГС без пилот 1500м гор'!$W45*AE$13 -> 0 | AG45: ='ГСЮра без пил МГРП'!$V45*AG$13 -> 0 | AH45: ='ГСЮра без пил МГРП'!$W45*AG$13 -> 0 | AI45: ='ГСЮра пил МСГРП'!$V45*AI$13 -> 0 | AJ45: ='ГСЮра пил МСГРП'!$W45*AI$13 -> 0 | AK45: ='ГСЮра керн ГИС'!$V45*AK$13 -> 0 | AL45: ='ГСЮра керн ГИС'!$W45*AK$13 -> 0 | AM45: =Посл.скв.!$V45*AM$13 -> 0 | AN45: =Посл.скв.!$W45*AM$13 -> 0 | AO45: =AM45+AK45+AI45+AG45+AE45+AC45+AA45+Y45++W45+U45+S45+Q45+M45+O45+K45+I45+G45 -> 0 | AP45: =AN45+AL45+AJ45+AH45+AF45+AD45+AB45+Z45++X45+V45+T45+R45+N45+P45+L45+J45+H45 -> 0
C46: ='Перв. скв '!C46 -> 0 | D46: ='Перв. скв '!D46 -> - демонтаж БУ | E46: ='Перв. скв '!E46 -> ООО "Буровая компания "Евразия" | F46: ='Перв. скв '!F46 -> операция | G46: ='Перв. скв '!$V46*G$13 -> 0 | H46: ='Перв. скв '!$W46*G$13 -> 0 | I46: ='2'!$V46*I$13 -> 0 | J46: ='2'!$W46*I$13 -> 0 | K46: ='3'!$V46*K$13 -> 0 | L46: ='3'!$W46*K$13 -> 0 | M46: ='4'!$V46*M$13 -> 0 | N46: ='4'!$W46*M$13 -> 0 | O46: ='5'!$V46*O$13 -> 0 | P46: ='5'!$W46*O$13 -> 0 | Q46: ='6'!$V46*Q$13 -> 0 | R46: ='6'!$W46*Q$13 -> 0 | S46: ='7'!$V46*S$13 -> 0 | T46: ='7'!$W46*S$13 -> 0 | U46: ='8'!$V46*U$13 -> 0 | V46: ='8'!$W46*U$13 -> 0 | W46: ='9'!$V46*W$13 -> 0 | X46: ='9'!$W46*W$13 -> 0 | Y46: =ВЗ!$V46*Y$13 -> 0 | Z46: =ВЗ!$W46*Y$13 -> 0 | AA46: ='ГС без пил 1000м гор'!$V46*AA$13 -> 0 | AB46: ='ГС без пил 1000м гор'!$W46*AA$13 -> 0 | AC46: ='ГС пил 1500м гор'!$V46*AC$13 -> 0 | AD46: ='ГС пил 1500м гор'!$W46*AC$13 -> 0 | AE46: ='ГС без пилот 1500м гор'!$V46*AE$13 -> 0 | AF46: ='ГС без пилот 1500м гор'!$W46*AE$13 -> 0 | AG46: ='ГСЮра без пил МГРП'!$V46*AG$13 -> 0 | AH46: ='ГСЮра без пил МГРП'!$W46*AG$13 -> 0 | AI46: ='ГСЮра пил МСГРП'!$V46*AI$13 -> 0 | AJ46: ='ГСЮра пил МСГРП'!$W46*AI$13 -> 0 | AK46: ='ГСЮра керн ГИС'!$V46*AK$13 -> 0 | AL46: ='ГСЮра керн ГИС'!$W46*AK$13 -> 0 | AM46: =Посл.скв.!$V46*AM$13 -> 0 | AN46: =Посл.скв.!$W46*AM$13 -> 0 | AO46: =AM46+AK46+AI46+AG46+AE46+AC46+AA46+Y46++W46+U46+S46+Q46+M46+O46+K46+I46+G46 -> 0 | AP46: =AN46+AL46+AJ46+AH46+AF46+AD46+AB46+Z46++X46+V46+T46+R46+N46+P46+L46+J46+H46 -> 0
C47: ='Перв. скв '!C47 -> 0 | D47: ='Перв. скв '!D47 -> - демонтаж АвИЭС | E47: ='Перв. скв '!E47 -> ООО "Буровая компания "Евразия" | F47: ='Перв. скв '!F47 -> операция | G47: ='Перв. скв '!$V47*G$13 -> 0 | H47: ='Перв. скв '!$W47*G$13 -> 0 | I47: ='2'!$V47*I$13 -> 0 | J47: ='2'!$W47*I$13 -> 0 | K47: ='3'!$V47*K$13 -> 0 | L47: ='3'!$W47*K$13 -> 0 | M47: ='4'!$V47*M$13 -> 0 | N47: ='4'!$W47*M$13 -> 0 | O47: ='5'!$V47*O$13 -> 0 | P47: ='5'!$W47*O$13 -> 0 | Q47: ='6'!$V47*Q$13 -> 0 | R47: ='6'!$W47*Q$13 -> 0 | S47: ='7'!$V47*S$13 -> 0 | T47: ='7'!$W47*S$13 -> 0 | U47: ='8'!$V47*U$13 -> 0 | V47: ='8'!$W47*U$13 -> 0 | W47: ='9'!$V47*W$13 -> 0 | X47: ='9'!$W47*W$13 -> 0 | Y47: =ВЗ!$V47*Y$13 -> 0 | Z47: =ВЗ!$W47*Y$13 -> 0 | AA47: ='ГС без пил 1000м гор'!$V47*AA$13 -> 0 | AB47: ='ГС без пил 1000м гор'!$W47*AA$13 -> 0 | AC47: ='ГС пил 1500м гор'!$V47*AC$13 -> 0 | AD47: ='ГС пил 1500м гор'!$W47*AC$13 -> 0 | AE47: ='ГС без пилот 1500м гор'!$V47*AE$13 -> 0 | AF47: ='ГС без пилот 1500м гор'!$W47*AE$13 -> 0 | AG47: ='ГСЮра без пил МГРП'!$V47*AG$13 -> 0 | AH47: ='ГСЮра без пил МГРП'!$W47*AG$13 -> 0 | AI47: ='ГСЮра пил МСГРП'!$V47*AI$13 -> 0 | AJ47: ='ГСЮра пил МСГРП'!$W47*AI$13 -> 0 | AK47: ='ГСЮра керн ГИС'!$V47*AK$13 -> 0 | AL47: ='ГСЮра керн ГИС'!$W47*AK$13 -> 0 | AM47: =Посл.скв.!$V47*AM$13 -> 0 | AN47: =Посл.скв.!$W47*AM$13 -> 0 | AO47: =AM47+AK47+AI47+AG47+AE47+AC47+AA47+Y47++W47+U47+S47+Q47+M47+O47+K47+I47+G47 -> 0 | AP47: =AN47+AL47+AJ47+AH47+AF47+AD47+AB47+Z47++X47+V47+T47+R47+N47+P47+L47+J47+H47 -> 0
...

Sheet Перв. скв 
A2: ПОДРОБНАЯ СМЕТНАЯ СТОИМОСТЬ СКВАЖИНЫ
B4: 3 | C4: Месторождение/ куст: | D4: ='Титул '!$K$5 -> 3 куст Новопортовского месторождения | E4: ВСЕГО СТ-ТЬ | F4: Исходные данные | H4: Перед забуркой | I4: Направление | J4: Кондуктор | K4: Техническая колонна | L4: Эксплуат-ая колонна | M4: Крепление колонн | N4: Хвостовик | O4: ВСЕГО БУРЕНИЕ | P4: Исходные данные | R4: ВСЕГО ОСВОЕНИЕ
C5: Подрядчик по бурению: | D5: ='Титул '!$K$11 -> ООО "Буровая компания "Евразия" | E5: =D369 -> 3.6218774e+08
C6: Тип буровой установки: | D6: ='Титул '!$K$12 -> ZJ-50 | E6: Всего ВМР | F6: Время бурения секции, сут: | H6: 0 | I6: 0.68 | J6: 2 | K6: 2.83 | L6: 10.79 | M6: 7.93 | N6: 9.77 | O6: =SUM(I6:N6) -> 34 | P6: Время освоения, сут:
C7: Тип скважины: | D7: =CONCATENATE('Титул '!$C$28," ",'Титул '!$D$28," ",'Титул '!$E$28," ",'Титул '!$F$28," ",'Титул '!$G$28," ",'Титул '!$H$28," ",'Титул '!$J$28," ",'Титул '!$I$28) -> ГС ЮРА без пилота МГРП 8ст | E7: =W69 -> 1.2893274e+08 | F7: Глубина (по стволу), м: | I7: 50 | J7: 460 | K7: 1200 | L7: 2700 | N7: 3700 | O7: ВСЕГО ПРОХОДКА | P7: В т.ч.время работы бригад КРС
C8: Проходка всего (м): | D8: 4728 | E8: Всего Бурение | F8: Диаметр долота, мм: | I8: 490 | J8: 393.7 | K8: 295.3 | L8: 220.7 | N8: 152.4 | P8: - ПЗР к ГРП/МСГРП, сут.
C9: Наличие СВП: | D9: ='Титул '!$K$13 -> 0 | E9: =W341 -> 1.3644058e+08 | F9: Диаметр колонны, мм: | I9: 630 | J9: 324 | K9: 245 | L9: 178 | N9: 114 | O9: =D8 -> 4728 | P9: - проведение ГРП/МСГРП, сут.
C10: Наличие АИЭС: | D10: ='Титул '!$K$14 -> да | E10: Всего Освоение | F10: Исходные данные | H10: Отход | I10: Пилот ГС | J10: Перебур | K10: Гориз.уч. 1 | L10: Гориз.уч. 2 | M10: Керн | O10: ГЛУБИНА ПО ВЕРТ-ЛИ | P10: - проведение ГНКТ, сут.
C11: Наличие автономности: | D11: ='Титул '!$K$15 -> да | E11: =W361 -> 96814424 | F11: Отдельные стволы, керн, м: | H11: 2000 | K11: 1500 | P11: - кол-во стадий МСГРП, шт.
B12: 1 | C12: Кол-во обсадных колонн (включая направл.): | D12: ='Титул '!I28 -> 0 | E12: Обор-ие устья | F12: Примечание: | P12: Примечание:
C13: Прочие существенные условия: | E13: =W367 -> 0
A15: ОПИСАНИЕ РАБОТ И УСЛУГ | H15: КОЛИЧЕСТВО | O15: СТОИМОСТЬ | V15: ВСЕГО
A16: КОД | B16: добавочный код | C16: СТАТЬЯ ЗАТРАТ | D16: ОПИСАНИЕ | E16: Подрядчик | F16: Единица измерения | G16: Руб. / Ед.изм. | H16: ПЗР (в т.ч. ВМР и осв.) | I16: =+I4 -> Направление | J16: =+J4 -> Кондуктор | K16: =+K4 -> Техническая колонна | L16: =+L4 -> Эксплуат-ая колонна | M16: Крепление колонн | N16: =+N4 -> Хвостовик | O16: ПЗР (в т.ч. ВМР и осв.) | P16: =+I16 -> Направление | Q16: =+J16 -> Кондуктор | R16: =+K16 -> Техническая колонна | S16: =+L16 -> Эксплуат-ая колонна | T16: Крепление колонн | U16: =+N16 -> Хвостовик | V16: Количество | W16: Стоимость (руб) | X16: ВСЕГО СТОИМОСТЬ
C18: 1. ЭТАП ВМР | X18: =SUM(W20:W68) -> 1.2893274e+08
C19: =D5 -> ООО "Буровая компания "Евразия" | D19: Описание работ/услуг
C20: Работы, связанные с мобилизацией БУ (переездом), а так же прочего бурового оборудования и бригадного хозяйства, автономного источника энергоснабжения, материалов подрядчика и прочее. | D20: Мобилизация БУ (переезд) | E20: =D$5 -> ООО "Буровая компания "Евразия" | F20: операция | G20: 1.2893274e+08 | H20: 1 | O20: =H20*G20 -> 1.2893274e+08 | V20: =SUM(H20:N20) -> 1 | W20: =SUM(O20:U20) -> 1.2893274e+08
D21: - мобилизация БУ (переезд) | E21: =D$5 -> ООО "Буровая компания "Евразия" | F21: операция | O21: =H21*G21 -> 0 | V21: =SUM(H21:N21) -> 0 | W21: =SUM(O21:U21) -> 0
D22: - мобилизация БХ и БИ (перевозка) | E22: =D$5 -> ООО "Буровая компания "Евразия" | F22: операция | O22: =H22*G22 -> 0 | V22: =SUM(H22:N22) -> 0 | W22: =SUM(O22:U22) -> 0
D23: - мобилизация АвИЭС (переезд) | E23: =D$5 -> ООО "Буровая компания "Евразия" | F23: операция | O23: =H23*G23 -> 0 | V23: =SUM(H23:N23) -> 0 | W23: =SUM(O23:U23) -> 0
E24: =D$5 -> ООО "Буровая компания "Евразия" | F24: операция | O24: =H24*G24 -> 0 | V24: =SUM(H24:N24) -> 0 | W24: =SUM(O24:U24) -> 0
E25: =D$5 -> ООО "Буровая компания "Евразия" | F25: операция | O25: =H25*G25 -> 0 | V25: =SUM(H25:N25) -> 0 | W25: =SUM(O25:U25) -> 0
E26: =D$5 -> ООО "Буровая компания "Евразия" | F26: операция | O26: =H26*G26 -> 0 | V26: =SUM(H26:N26) -> 0 | W26: =SUM(O26:U26) -> 0
E27: =D$5 -> ООО "Буровая компания "Евразия" | F27: операция | O27: =H27*G27 -> 0 | V27: =SUM(H27:N27) -> 0 | W27: =SUM(O27:U27) -> 0
E28: =D$5 -> ООО "Буровая компания "Евразия" | F28: операция | O28: =H28*G28 -> 0 | V28: =SUM(H28:N28) -> 0 | W28: =SUM(O28:U28) -> 0
C29: Работы связанные со сборкой (монтажем) и подключением БУ, бурового и вспомогательного оборудования | D29: Монтаж БУ | E29: =D$5 -> ООО "Буровая компания "Евразия" | F29: операция | O29: =H29*G29 -> 0 | V29: =SUM(H29:N29) -> 0 | W29: =SUM(O29:U29) -> 0
D30: - монтаж БУ | E30: =D$5 -> ООО "Буровая компания "Евразия" | F30: операция | O30: =H30*G30 -> 0 | V30: =SUM(H30:N30) -> 0 | W30: =SUM(O30:U30) -> 0
D31: - монтаж АвИЭС | E31: =D$5 -> ООО "Буровая компания "Евразия" | F31: операция | O31: =H31*G31 -> 0 | V31: =SUM(H31:N31) -> 0 | W31: =SUM(O31:U31) -> 0
D32: - монтаж БДЕ, ПВО | E32: =D$5 -> ООО "Буровая компания "Евразия" | F32: операция | O32: =H32*G32 -> 0 | V32: =SUM(H32:N32) -> 0 | W32: =SUM(O32:U32) -> 0
D33: - бурение водяного колодца | E33: =D$5 -> ООО "Буровая компания "Евразия" | F33: операция | O33: =H33*G33 -> 0 | V33: =SUM(H33:N33) -> 0 | W33: =SUM(O33:U33) -> 0
D34: - ПНР | E34: =D$5 -> ООО "Буровая компания "Евразия" | F34: операция | O34: =H34*G34 -> 0 | V34: =SUM(H34:N34) -> 0 | W34: =SUM(O34:U34) -> 0
E35: =D$5 -> ООО "Буровая компания "Евразия" | F35: операция | O35: =H35*G35 -> 0 | V35: =SUM(H35:N35) -> 0 | W35: =SUM(O35:U35) -> 0
